Workbook

Sheet Sheet1

Sheet Copy of Pre Workout 1
A9: PRE WORKOUT 1
A10: =HYPERLINK("https://goo.gl/forms/3ibooB993Hi7SS2d2","PRESS TO RECORD BODY WEIGHT") -> PRESS TO RECORD BODY WEIGHT
A12: Laying the Foundation
A13: This week we are going to get your body used to being in the gym. It is imperative that you keep the weight VERY light. No need to push yourself hard at all. Let's warm your body into the process of lifting again and pay close attention to how you recover.
A15: QUICK TIPS
A16: IF IT'S GREEN=NEEDS YOUR INPUT
A17: Click The Title of The workout to see an Instructional Video
A18: REMEMBER TO ROUND OUR SUGGESTED WEIGHTS TO YOUR GYM'S CLOSEST AVAILABLE WEIGHTS.
A21: BEGIN WORKOUT
A23: INSERT BODY WEIGHT | C23: 100
A25: Beginner | D25: Moderate
A26: (Over 1 month since I've worked out) | D26: Less than a month since weight training
A27: x
A29: DAY 1
A32: CHEST & BACK
A33: =HYPERLINK("https://youtu.be/ujVN-A0Z-ic","1. DUMBBELL INCLINE PRESS") -> 1. DUMBBELL INCLINE PRESS
A34: SUGGESTED WEIGHT | B34: =IF((AND(A27="",C23>=170)),25,IF((AND(A27="",C23<170)),20,IF((AND(D27="",C23>170)),15,12.5))) -> 12.5
A35: SET | B35: WEIGHT | C35: REPS | D35: REST | E35: PREVIOUS | F35: REP LOG
A36: 1 | B36: =B34 -> 12.5 | C36: 10 - 12 | D36: 1 MIN | F36: 10
A37: 2 | B37: =IF(F36<10,MROUND(B36*0.85,2.5),B36) -> 12.5 | C37: 10 - 12 | D37: 1 MIN | F37: 10
A38: 3 | B38: =IF(F37<10,MROUND(B37*0.8,2.5),B37) -> 12.5 | C38: 10 - 12 | D38: 1 MIN | F38: 10
A41: =HYPERLINK("https://www.youtube.com/watch?v=PnaDzYh2axA","2. LAT PULL DOWN") -> 2. LAT PULL DOWN
A42: SUGGESTED WEIGHT | B42: =IF((AND(A27="",C23>=170)),35,IF((AND(A27="",C23<170)),20,IF((AND(D27="",C23>170)),30,25))) -> 25
A43: SET | B43: WEIGHT | C43: REPS | D43: REST | E43: PREVIOUS | F43: REP LOG
A44: 1 | B44: =B42 -> 25 | C44: 10 - 12 | D44: 1 MIN | F44: 12
A45: 2 | B45: =IF(F44<10,MROUND(B44*0.8,5),B44) -> 25 | C45: 10 - 12 | D45: 1 MIN | F45: 12
A46: 3 | B46: =IF(F45<10,MROUND(B45*0.8,5),B45) -> 25 | C46: 10 - 12 | D46: 1 MIN | F46: 12
A49: =HYPERLINK("https://www.youtube.com/watch?v=Yke__29qVfo","3. TRICEPS PUSHDOWN (STRAIGHT BAR)") -> 3. TRICEPS PUSHDOWN (STRAIGHT BAR)
A50: SUGGESTED WEIGHT | B50: =IF((AND(A27="",C23>=170)),15,IF((AND(A27="",C23<170)),10,IF((AND(D27="",C23>170)),12.5,10))) -> 10
A51: SET | B51: WEIGHT | C51: REPS | D51: REST | E51: PREVIOUS | F51: REP LOG
A52: 1 | B52: =B50 -> 10 | C52: 10 - 12 | D52: 1 MIN | F52: 5
A53: 2 | B53: =IF(F52<10,MROUND(B52*0.8,2.5),B52) -> 7.5 | C53: 10 - 12 | D53: 1 MIN | F53: 12
A54: 3 | B54: =IF(F53<10,MROUND(B53*0.8,2.5),B53) -> 7.5 | C54: 10 - 12 | D54: 1 MIN
A57: =HYPERLINK("https://www.youtube.com/watch?v=9IqvmIhFxtY","4. BICEP CABLE CURL") -> 4. BICEP CABLE CURL
A58: SUGGESTED WEIGHT | B58: =IF((AND(A27="",C23>=170)),20,IF((AND(A27="",C23<170)),15,IF((AND(D27="",C23>170)),12.5,10))) -> 10
A59: SET | B59: WEIGHT | C59: REPS | D59: REST | E59: PREVIOUS | F59: REP LOG
A60: 1 | B60: =B58 -> 10 | C60: 10 - 12 | D60: 1MIN | E60: =IF('WEEK 1 '!B54=B60,'WEEK 1 '!F54,"") -> #REF! | F60: 10
A61: 2 | B61: =IF(F60<10,MROUND(B60*0.85,5),B60) -> 10 | C61: 10 - 12 | D61: 1MIN | E61: =IF('WEEK 1 '!B55=B61,'WEEK 1 '!F55,"") -> #REF! | F61: 10
A62: 3 | B62: =IF(F61<10,MROUND(B61*0.85,5),B61) -> 10 | C62: 10 - 12 | D62: 1MIN | E62: =IF('WEEK 1 '!B56=B62,'WEEK 1 '!F56,"") -> #REF! | F62: 10
A65: DAY 2
...

Sheet Copy of Pre Workout 2
A9: PRE WORKOUT 2
A10: =HYPERLINK("https://goo.gl/forms/3ibooB993Hi7SS2d2","PRESS TO RECORD BODY WEIGHT") -> PRESS TO RECORD BODY WEIGHT
A12: This Weeks Goals
A13: This week we are going to continue to get your body used to being back in the gym. There should be still be little to no strain since we are adding weight but we still want to keep it light. We'll be introducing a few new excersizes during this week as well. Push yourself, but not too hard.
A15: QUICK TIPS
A16: IF IT'S GREEN=NEEDS YOUR INPUT
A17: Click The Title of The workout to see an Instructional Video
A18: REMEMBER TO ROUND OUR SUGGESTED WEIGHTS TO YOUR GYM'S CLOSEST AVAILABLE WEIGHTS.
A21: BEGIN WORKOUT
A23: DAY 1
A26: CHEST & BACK
A27: =HYPERLINK("https://youtu.be/ujVN-A0Z-ic","1. DUMBBELL INCLINE PRESS") -> 1. DUMBBELL INCLINE PRESS
A28: SUGGESTED WEIGHT | B28: =IF('Pre Workout 1'!B142='Pre Workout 1'!B144,'Pre Workout 1'!B142+2.5,IF('Pre Workout 1'!F142<=9,MROUND('Pre Workout 1'!B142*0.95,5),MROUND('Pre Workout 1'!B142*0.85,2.5))) -> #REF!
A29: SET | B29: WEIGHT | C29: REPS | D29: REST | E29: PREVIOUS | F29: REP LOG
A30: 1 | B30: =B28 -> #REF! | C30: 10 - 15 | D30: 1 MIN
A31: 2 | B31: =IF(F30<10,MROUND(B30*0.85,2.5),B30) -> #REF! | C31: 10 - 15 | D31: 1 MIN
A32: 3 | B32: =IF(F31<10,MROUND(B31*0.8,2.5),B31) -> #REF! | C32: 10 - 15 | D32: 1 MIN
A35: =HYPERLINK("https://www.youtube.com/watch?v=PnaDzYh2axA","2. LAT PULL DOWN") -> 2. LAT PULL DOWN
A36: SUGGESTED WEIGHT | B36: =IF('Pre Workout 1'!B150='Pre Workout 1'!B152,'Pre Workout 1'!B150+15,IF('Pre Workout 1'!F150<=9,MROUND('Pre Workout 1'!B150*0.95,5),MROUND('Pre Workout 1'!B150*0.85,2.5))) -> #REF!
A37: SET | B37: WEIGHT | C37: REPS | D37: REST | E37: PREVIOUS | F37: REP LOG
A38: 1 | B38: =B36 -> #REF! | C38: 10 - 15 | D38: 1 MIN
A39: 2 | B39: =IF(F38<10,MROUND(B38*0.8,5),B38) -> #REF! | C39: 10 - 15 | D39: 1 MIN
A40: 3 | B40: =IF(F39<10,MROUND(B39*0.8,5),B39) -> #REF! | C40: 10 - 15 | D40: 1 MIN
A43: =HYPERLINK("https://www.youtube.com/watch?v=9YH1YvZbiY0","3. MACHINE LOW ROW") -> 3. MACHINE LOW ROW
A44: SUGGESTED WEIGHT | B44: =IF((AND(A27="",C23>=145)),40,IF((AND(A27="",C23<145)),35,IF((AND(D27="",C23>145)),35,30))) -> 30
A45: SET | B45: WEIGHT | C45: REPS | D45: REST | E45: PREVIOUS | F45: REP LOG
A46: 1 | B46: =B44 -> 30 | C46: 10 - 15 | D46: 1 MIN
A47: 2 | B47: =IF(F46<10,MROUND(B46*0.8,5),B46) -> 25 | C47: 10 - 15 | D47: 1 MIN
A48: 3 | B48: =IF(F47<10,MROUND(B47*0.8,5),B47) -> 20 | C48: 10 - 15 | D48: 1 MIN
A51: =HYPERLINK("https://www.youtube.com/watch?v=Yke__29qVfo","4. TRICEPS PUSHDOWN (STRAIGHT BAR)") -> 4. TRICEPS PUSHDOWN (STRAIGHT BAR)
A52: SUGGESTED WEIGHT | B52: ='Pre Workout 1'!B86 -> #REF!
A53: SET | B53: WEIGHT | C53: REPS | D53: REST | E53: PREVIOUS | F53: REP LOG
A54: 1 | B54: =B52 -> #REF! | C54: 10 - 12 | D54: 1 MIN
A55: 2 | B55: =IF(F54<10,MROUND(B54*0.8,2.5),B54) -> #REF! | C55: 10 - 12 | D55: 1 MIN
A56: 3 | B56: =IF(F55<10,MROUND(B55*0.8,2.5),B55) -> #REF! | C56: 10 - 12 | D56: 1 MIN
A59: =HYPERLINK("https://www.youtube.com/watch?v=9IqvmIhFxtY","5. BICEP CABLE CURL") -> 5. BICEP CABLE CURL
A60: SUGGESTED WEIGHT | B60: =IF('Pre Workout 1'!B96='Pre Workout 1'!B98,'Pre Workout 1'!B96+5,IF('Pre Workout 1'!F96<=9,MROUND('Pre Workout 1'!B96*0.95,5),MROUND('Pre Workout 1'!B96*0.85,2.5))) -> #REF!
A61: SET | B61: WEIGHT | C61: REPS | D61: REST | E61: PREVIOUS | F61: REP LOG
A62: 1 | B62: =B60 -> #REF! | C62: 10 - 12 | D62: 1MIN | E62: =IF('WEEK 1 '!B54=B62,'WEEK 1 '!F54,"") -> #REF!
A63: 2 | B63: =IF(F62<10,MROUND(B62*0.85,5),B62) -> #REF! | C63: 10 - 12 | D63: 1MIN | E63: =IF('WEEK 1 '!B55=B63,'WEEK 1 '!F55,"") -> #REF!
...

Sheet Copy of DETERMINING MAX WEEK
A8: WEEK 1 | I8: QUICK TIPS
A9: DAY 1 | I9: You only Log What's in GREEN
A10: CHEST & BACK | I10: Click The Title of The workout to see an Instructional Video
A11: This Weeks Goals
A12: swipe right for quick tips
A13: Today is all about setting the proper foundation for your future workouts. All we want to do is establish maximum strenght levels for some target muscle groups. It is important to keep great form as well as being honest in your logging.
A15: READ BEFORE WORKING OUT
A16: All of the workouts are meant to start off with a light weight to establish form and blood flow. If your 2nd set feels very light, you should jump to one of the recommended sets with a weight you feel will be moderate for you. Then from there work the consecutive sets toward your max then log it in the bright green box.
A17: =HYPERLINK("https://www.youtube.com/watch?v=qrv8cCA-WCY","WATCH- HOW TO MAX PROPERLY") -> WATCH- HOW TO MAX PROPERLY
A18: 1. BENCH PRESS | I18: =HYPERLINK("https://www.youtube.com/watch?v=ujVN-A0Z-ic","1. DUMBBELL INCLINE CHEST PRESS") -> 1. DUMBBELL INCLINE CHEST PRESS | O18: 1. MACHINE PRESS
A19: SET | B19: WEIGHT | C19: REPS | D19: REST | E19: REP LOG | I19: SET | J19: WEIGHT | K19: REPS | L19: REST | M19: REP LOG | O19: SET | P19: WEIGHT | Q19: REPS | R19: REST | S19: REP LOG
A20: 1 | B20: 85 | C20: 1 | D20: 2 MIN | I20: 1 | J20: 30 | K20: 4 | L20: 2 MIN | O20: 1 | P20: 85 | Q20: 4 | R20: 2 MIN
A21: 2 | B21: 135 | C21: 1 | D21: 2 MIN | I21: 2 | J21: 40 | K21: 4 | L21: 2 MIN | O21: 2 | P21: 135 | Q21: 4 | R21: 2 MIN
A22: 3 | B22: 155 | C22: 1 | D22: 2 MIN | I22: 3 | J22: 60 | K22: 4 | L22: 2 MIN | O22: 3 | P22: 155 | Q22: 4 | R22: 2 MIN
A23: 4 | B23: 170 | C23: 1 | D23: 2 MIN | I23: 4 | J23: 70 | K23: 4 | L23: 2 MIN | O23: 4 | P23: 170 | Q23: 4 | R23: 2 MIN
A24: 5 | B24: 185 | C24: 1 | D24: 2 MIN | I24: 5 | J24: 80 | K24: 4 | L24: 2 MIN | O24: 5 | P24: 185 | Q24: 4 | R24: 2 MIN
A25: 6 | B25: 205 | C25: 1 | D25: 2 MIN | I25: 6 | J25: 90 | K25: 4 | L25: 2 MIN | O25: 6 | P25: 205 | Q25: 4 | R25: 2 MIN
A26: 7 | B26: 225 | C26: 1 | D26: 2 MIN | I26: 7 | J26: 100 | K26: 4 | L26: 2 MIN | O26: 7 | P26: 225 | Q26: 4 | R26: 2 MIN
A27: 8 | B27: 240 | C27: 1 | D27: 2 MIN | I27: 8 | J27: 110 | K27: 4 | L27: 2 MIN | O27: 8 | P27: 240 | Q27: 4 | R27: 2 MIN
A28: 9 | B28: 260 | C28: 1 | D28: 2 MIN | I28: 9 | J28: 120 | K28: 4 | L28: 2 MIN | O28: 9 | P28: 260 | Q28: 4 | R28: 2 MIN
A29: 10 | B29: 280 | C29: 1 | D29: 2 MIN | I29: 10 | J29: 130 | K29: 4 | L29: 2 MIN | O29: 10 | P29: 280 | Q29: 4 | R29: 2 MIN
A30: 11 | B30: 305 | C30: 1 | D30: 2 MIN | I30: 11 | J30: 140 | K30: 4 | L30: 2 MIN | O30: 11 | P30: 305 | Q30: 4 | R30: 2 MIN
A31: INSERT FINAL MAX | E31: 245 | I31: INSERT FINAL MAX | O31: INSERT FINAL MAX
A33: =HYPERLINK("https://www.youtube.com/watch?v=PnaDzYh2axA","2. Lat Pull Down") -> 2. Lat Pull Down
A35: Set | B35: Weight | C35: Reps | D35: REST | E35: REP LOG
A36: Set1 | B36: 70 | C36: 4 | D36: 2 MIN
A37: Set 2 | B37: 90 | C37: 4 | D37: 2 MIN
A38: Set 3 | B38: 110 | C38: 4 | D38: 2 MIN
A39: Set 4 | B39: 130 | C39: 4 | D39: 2 MIN
A40: Set 5 | B40: 160 | C40: 4 | D40: 2 MIN
A41: Set 6 | B41: 180 | C41: 4 | D41: 2 MIN
A42: Set 7 | B42: 200 | C42: 4 | D42: 2 MIN
A43: Set 8 | B43: 210 | C43: 4 | D43: 2 MIN
A44: Set 9 | B44: 220 | C44: 4 | D44: 2 MIN
A45: Set 10 | B45: 230 | C45: 4 | D45: 2 MIN
A46: Set 11 | B46: 240 | C46: 4 | D46: 2 MIN
A47: INSERT FINAL MAX | E47: 250
A50: =HYPERLINK("https://www.youtube.com/watch?v=9YH1YvZbiY0","3. Machine Low Row") -> 3. Machine Low Row
A51: SET | B51: WEIGHT | C51: REPS | D51: REST | E51: REP LOG
A52: Set1 | B52: 70 | C52: 4 | D52: 2 MIN
...

Sheet Copy of Week 1 MASTER SHEET
A9: Week 1 | H9: QUICK TIPS
A10: =HYPERLINK("https://goo.gl/forms/3ibooB993Hi7SS2d2","PRESS TO RECORD BODY WEIGHT") -> PRESS TO RECORD BODY WEIGHT | H10: You only Log What's in GREEN
H11: Click The Title of The workout to see an Instructional Video
A12: This Weeks Goals
A13: This week we are going to jump you into a workout. As the weeks go on we will refine your workout more and it will become more targeted. Give it all you got and push to your limits everytime.
A15: DAY 1 | H15: ALTERNATE WORKOUTS | O15: ALTERNATE WORKOUTS
A18: CHEST & BACK | H18: CHEST & BACK | O18: CHEST & BACK
A19: =HYPERLINK("https://www.youtube.com/watch?v=iLgUDezDMbU","1. BENCH PRESS") -> 1. BENCH PRESS | H19: =HYPERLINK("https://www.youtube.com/watch?v=75e_H9Vq_Lw","1. MACHINE PRESS") -> 1. MACHINE PRESS | O19: =HYPERLINK("https://youtu.be/ujVN-A0Z-ic","1. DUMBBELL INCLINE PRESS") -> 1. DUMBBELL INCLINE PRESS
A20: CURRENT MAX | B20: ='Copy of DETERMINING MAX WEEK'!E31 -> 245 | H20: CURRENT MAX | I20: 120 | O20: CURRENT MAX | P20: 75
A21: SET | B21: WEIGHT | C21: REPS | D21: REST | E21: PREVIOUS | F21: REP LOG | H21: SET | I21: WEIGHT | J21: REPS | K21: REST | L21: PREVIOUS | M21: REP LOG | O21: SET | P21: WEIGHT | Q21: REPS | R21: REST | S21: PREVIOUS | T21: REP LOG
A22: 1 | B22: =IF( 'WEEK 1 '!B20<125,45,mround('WEEK 1 '!B20*0.35,5)) -> #REF! | C22: 6 | D22: 30s | H22: 1 | I22: =mround('WEEK 1 '!I20*0.35,5) -> #REF! | J22: 6 | K22: 30s | O22: 1 | P22: =mround('WEEK 1 '!P20*0.35,5) -> #REF! | Q22: 6 | R22: 1 MIN
A23: 2 | B23: =MROUND('WEEK 1 '!B20*0.8,5) -> #REF! | C23: 1 | D23: 1-2 MIN | H23: 2 | I23: =mround('WEEK 1 '!I20*0.65,5) -> #REF! | J23: 1 | K23: 1-2 MIN | O23: 2 | P23: =mround('WEEK 1 '!P20*0.65,5) -> #REF! | Q23: 1 | R23: 1 MIN
A24: 3 | B24: =mround('WEEK 1 '!B20*0.9,5) -> #REF! | C24: 1 | D24: 1-2 MIN | H24: 3 | I24: =mround('WEEK 1 '!I20*0.9,5) -> #REF! | J24: 1 | K24: 1-2 MIN | O24: 3 | P24: =mround('WEEK 1 '!P20*0.85,5) -> #REF! | Q24: 1 | R24: 1 MIN | V24: =90*0.93 -> 83.7
A25: 4 | B25: ='WEEK 1 '!B20 -> #REF! | C25: 1 | D25: 1-5 MIN | H25: 4 | I25: ='WEEK 1 '!I20 -> #REF! | J25: 1 | K25: 1-5 MIN | O25: 4 | P25: =mround('WEEK 1 '!P20*1,5) -> #REF! | Q25: REP OUT | R25: 1 MIN
A26: =IF('WEEK 1 '!F25<1,"PROCEED TO DOWN SETS","NEW 1 REP MAX ATTEMPT") -> #REF! | G26: ALTERNATE | H26: =IF('WEEK 1 '!M25<1,"PROCEED TO DOWN SETS","NEW 1 REP MAX ATTEMPT") -> #REF! | N26: ALTERNATE | O26: =IF(OR(ISBLANK('WEEK 1 '!T25),ISBLANK('WEEK 1 '!T24),ISBLANK('WEEK 1 '!T23)),"PROCEED TO DOWNSETS",if('WEEK 1 '!T25>=6,"NEW 4 REP MAX ATTEMPT","PROCEED TO DOWN SETS")) -> #REF!
A27: =if('WEEK 1 '!F25<1,"",5) -> #REF! | B27: =IF('WEEK 1 '!F25<1,"",B25+5) -> #REF! | C27: =if('WEEK 1 '!F25<1,"",1) -> #REF! | D27: =if('WEEK 1 '!F25<1,"","1-5 MIN") -> #REF! | H27: =if('WEEK 1 '!M25<1,"",5) -> #REF! | I27: =IF('WEEK 1 '!M25<1,"",I25+5) -> #REF! | J27: =if('WEEK 1 '!M25<1,"",1) -> #REF! | K27: =if('WEEK 1 '!M25<1,"","1-5 MIN") -> #REF! | O27: =IF(OR(ISBLANK('WEEK 1 '!T25),ISBLANK('WEEK 1 '!T24),ISBLANK('WEEK 1 '!T23)),"",IF('WEEK 1 '!T25>=6,5,"")) -> #REF! | P27: =IF(OR(ISBLANK('WEEK 1 '!T25),ISBLANK('WEEK 1 '!T24),ISBLANK('WEEK 1 '!T23)),"",IF('WEEK 1 '!T25>=6,'WEEK 1 '!P20+5,"")) -> #REF! | Q27: =IF(OR(ISBLANK('WEEK 1 '!T25),ISBLANK('WEEK 1 '!T24),ISBLANK('WEEK 1 '!T23)),"",IF('WEEK 1 '!T25>=6,"REP OUT","")) -> #REF! | R27: =IF(OR(ISBLANK('WEEK 1 '!T25),ISBLANK('WEEK 1 '!T24),ISBLANK('WEEK 1 '!T23)),"",IF('WEEK 1 '!T25>5,"1 MIN","")) -> #REF!
A28: =IF('WEEK 1 '!F27<1,"","6") -> #REF! | B28: =IF('WEEK 1 '!F27<1,"",B27+5) -> #REF! | C28: =IF('WEEK 1 '!F27<1,"","1") -> #REF! | D28: =IF('WEEK 1 '!F27<1,"","1-5 MIN") -> #REF! | H28: =IF('WEEK 1 '!M27<1,"","6") -> #REF! | I28: =IF('WEEK 1 '!M27<1,"",I27+5) -> #REF! | J28: =IF('WEEK 1 '!M27<1,"","1") -> #REF! | K28: =IF('WEEK 1 '!M27<1,"","1-5 MIN") -> #REF! | O28: =IF(OR(ISBLANK('WEEK 1 '!T25),ISBLANK('WEEK 1 '!T24),ISBLANK('WEEK 1 '!T23)),"FILL OUT REP LOG FIRST","DOWN SETS") -> DOWN SETS
A29: =IF(OR(ISBLANK('WEEK 1 '!F25),ISBLANK('WEEK 1 '!F24),ISBLANK('WEEK 1 '!F23)),"FILL OUT REP LOG FOR DOWN SETS","DOWN SETS") -> DOWN SETS | H29: =IF(OR(ISBLANK('WEEK 1 '!M25),ISBLANK('WEEK 1 '!M24),ISBLANK('WEEK 1 '!M23)),"FILL OUT REP LOG FOR DOWN SETS","DOWN SETS") -> DOWN SETS | O29: =IF('WEEK 1 '!T27>=4,"",IF(OR(ISBLANK('WEEK 1 '!T25),ISBLANK('WEEK 1 '!T24),ISBLANK('WEEK 1 '!T23)),"",IF('WEEK 1 '!T25>5,6,5))) -> #REF! | P29: =IF('WEEK 1 '!T27>=4,"",IF(OR(ISBLANK('WEEK 1 '!T25),ISBLANK('WEEK 1 '!T24),ISBLANK('WEEK 1 '!T23)),"",IF('WEEK 1 '!T25<6,mround('WEEK 1 '!P20*0.8,5),IF('WEEK 1 '!T25<10,mround('WEEK 1 '!P20*0.93,5),mround('WEEK 1 '!P20*0.7,5))))) -> #REF! | Q29: =IF('WEEK 1 '!T27>=4,"",IF(OR(ISBLANK('WEEK 1 '!T25),ISBLANK('WEEK 1 '!T24),ISBLANK('WEEK 1 '!T23)),"","REP OUT")) -> #REF! | R29: =IF('WEEK 1 '!T27>=4,"",IF(OR(ISBLANK('WEEK 1 '!T25),ISBLANK('WEEK 1 '!T24),ISBLANK('WEEK 1 '!T23)),"","1 MIN")) -> #REF! | V29: =0.7*85 -> 59.5
A30: =IF(OR(ISBLANK('WEEK 1 '!F25),ISBLANK('WEEK 1 '!F24),ISBLANK('WEEK 1 '!F23)),"",IF((AND(A27="",A28="")),5,IF((AND(A27>1,A28="")),6,7))) -> #REF! | B30: =IF(OR(ISBLANK('WEEK 1 '!F25),ISBLANK('WEEK 1 '!F24),ISBLANK('WEEK 1 '!F23)),"",MROUND('WEEK 1 '!B32*0.9,5)) -> #REF! | C30: =IF(OR(ISBLANK('WEEK 1 '!F25),ISBLANK('WEEK 1 '!F24),ISBLANK('WEEK 1 '!F23)),"","REP OUT") -> REP OUT | D30: =IF(OR(ISBLANK('WEEK 1 '!F25),ISBLANK('WEEK 1 '!F24),ISBLANK('WEEK 1 '!F23)),"","1-3 MIN") -> 1-3 MIN | H30: =IF(OR(ISBLANK('WEEK 1 '!M25),ISBLANK('WEEK 1 '!M24),ISBLANK('WEEK 1 '!M23)),"",IF((AND(H27="",H28="")),5,IF((AND(H27>1,H28="")),6,7))) -> #REF! | I30: =IF(OR(ISBLANK('WEEK 1 '!M25),ISBLANK('WEEK 1 '!M24),ISBLANK('WEEK 1 '!M23)),"",MROUND('WEEK 1 '!I32*0.9,5)) -> #REF! | J30: =IF(OR(ISBLANK('WEEK 1 '!M25),ISBLANK('WEEK 1 '!M24),ISBLANK('WEEK 1 '!M23)),"","REP OUT") -> REP OUT | K30: =IF(OR(ISBLANK('WEEK 1 '!M25),ISBLANK('WEEK 1 '!M24),ISBLANK('WEEK 1 '!M23)),"","1-3 MIN") -> 1-3 MIN | O30: =IF('WEEK 1 '!T27>=4,"",IF(OR(ISBLANK('WEEK 1 '!T25),ISBLANK('WEEK 1 '!T24),ISBLANK('WEEK 1 '!T23)),"",IF('WEEK 1 '!T25>5,7,6))) -> #REF! | P30: =IF('WEEK 1 '!T27>=4,"",IF(OR(ISBLANK('WEEK 1 '!T25),ISBLANK('WEEK 1 '!T24),ISBLANK('WEEK 1 '!T23)),"",IF('WEEK 1 '!T25<6,mround('WEEK 1 '!P20*0.65,5),IF('WEEK 1 '!T25<10,mround('WEEK 1 '!P20*0.7,5),mround('WEEK 1 '!P20*0.65,5))))) -> #REF! | Q30: =IF('WEEK 1 '!T27>=4,"",IF(OR(ISBLANK('WEEK 1 '!T25),ISBLANK('WEEK 1 '!T24),ISBLANK('WEEK 1 '!T23)),"","REP OUT")) -> #REF! | R30: =IF('WEEK 1 '!T27>=4,"",IF(OR(ISBLANK('WEEK 1 '!T25),ISBLANK('WEEK 1 '!T24),ISBLANK('WEEK 1 '!T23)),"","1 MIN")) -> #REF!
A31: =IF(OR(ISBLANK('WEEK 1 '!F25),ISBLANK('WEEK 1 '!F24),ISBLANK('WEEK 1 '!F23)),"",IF((AND(A27="",A28="")),6,IF((AND(A27>1,A28="")),7,8))) -> #REF! | B31: =IF(OR(ISBLANK('WEEK 1 '!F25),ISBLANK('WEEK 1 '!F24),ISBLANK('WEEK 1 '!F23)),"",mround('WEEK 1 '!B32*0.78,5)) -> #REF! | C31: =IF(OR(ISBLANK('WEEK 1 '!F25),ISBLANK('WEEK 1 '!F24),ISBLANK('WEEK 1 '!F23)),"","REP OUT") -> REP OUT | D31: =IF(OR(ISBLANK('WEEK 1 '!F25),ISBLANK('WEEK 1 '!F24),ISBLANK('WEEK 1 '!F23)),"","1-3 MIN") -> 1-3 MIN | H31: =IF(OR(ISBLANK('WEEK 1 '!M25),ISBLANK('WEEK 1 '!M24),ISBLANK('WEEK 1 '!M23)),"",IF((AND(H27="",H28="")),6,IF((AND(H27>1,H28="")),7,8))) -> #REF! | I31: =IF(OR(ISBLANK('WEEK 1 '!M25),ISBLANK('WEEK 1 '!M24),ISBLANK('WEEK 1 '!M23)),"",mround('WEEK 1 '!I32*0.78,5)) -> #REF! | J31: =IF(OR(ISBLANK('WEEK 1 '!M25),ISBLANK('WEEK 1 '!M24),ISBLANK('WEEK 1 '!M23)),"","REP OUT") -> REP OUT | K31: =IF(OR(ISBLANK('WEEK 1 '!M25),ISBLANK('WEEK 1 '!M24),ISBLANK('WEEK 1 '!M23)),"","1-3 MIN") -> 1-3 MIN | O31: =IF('WEEK 1 '!T27<4,"",IF(OR(ISBLANK('WEEK 1 '!T25),ISBLANK('WEEK 1 '!T24),ISBLANK('WEEK 1 '!T23)),"",IF('WEEK 1 '!T27>3,6,5))) -> #REF! | P31: =IF('WEEK 1 '!T27<4,"",IF(OR(ISBLANK('WEEK 1 '!T25),ISBLANK('WEEK 1 '!T24),ISBLANK('WEEK 1 '!T23)),"",IF('WEEK 1 '!T27<6,mround('WEEK 1 '!P33*0.8,5),IF('WEEK 1 '!T27<10,mround('WEEK 1 '!P33*0.93,5),mround('WEEK 1 '!P33*0.7,5))))) -> #REF! | Q31: =IF('WEEK 1 '!T27<4,"",IF(OR(ISBLANK('WEEK 1 '!T25),ISBLANK('WEEK 1 '!T24),ISBLANK('WEEK 1 '!T23)),"","REP OUT")) -> #REF! | R31: =IF('WEEK 1 '!T27<4,"",IF(OR(ISBLANK('WEEK 1 '!T25),ISBLANK('WEEK 1 '!T24),ISBLANK('WEEK 1 '!T23)),"","1 MIN")) -> #REF!
A32: FINAL MAX | B32: =IF(OR(ISBLANK('WEEK 1 '!F25),ISBLANK('WEEK 1 '!F24),ISBLANK('WEEK 1 '!F23)),"",IF('WEEK 1 '!F28>=1,'WEEK 1 '!B28,IF('WEEK 1 '!F27>=1,'WEEK 1 '!B27,IF('WEEK 1 '!F25<1,'WEEK 1 '!B25-5,'WEEK 1 '!B25)))) -> #REF! | H32: FINAL MAX | I32: =IF(OR(ISBLANK('WEEK 1 '!M25),ISBLANK('WEEK 1 '!M24),ISBLANK('WEEK 1 '!M23)),"",IF('WEEK 1 '!M28>=1,'WEEK 1 '!I28,IF('WEEK 1 '!M27>=1,'WEEK 1 '!I27,IF('WEEK 1 '!M25<1,'WEEK 1 '!I25-5,'WEEK 1 '!I25)))) -> #REF! | O32: =IF('WEEK 1 '!T27<4,"",IF(OR(ISBLANK('WEEK 1 '!T25),ISBLANK('WEEK 1 '!T24),ISBLANK('WEEK 1 '!T23)),"",IF('WEEK 1 '!T27>3,7,""))) -> #REF! | P32: =IF('WEEK 1 '!T27<4,"",IF(OR(ISBLANK('WEEK 1 '!T25),ISBLANK('WEEK 1 '!T24),ISBLANK('WEEK 1 '!T23)),"",IF('WEEK 1 '!T27<6,mround('WEEK 1 '!P33*0.65,5),IF('WEEK 1 '!T27<10,mround('WEEK 1 '!P33*0.7,5),mround('WEEK 1 '!P33*0.65,5))))) -> #REF! | Q32: =IF('WEEK 1 '!T27<4,"",IF(OR(ISBLANK('WEEK 1 '!T25),ISBLANK('WEEK 1 '!T24),ISBLANK('WEEK 1 '!T23)),"","REP OUT")) -> #REF! | R32: =IF('WEEK 1 '!T27<4,"",IF(OR(ISBLANK('WEEK 1 '!T25),ISBLANK('WEEK 1 '!T24),ISBLANK('WEEK 1 '!T23)),"","1 MIN")) -> #REF!
O33: FINAL MAX | P33: =IF(OR(ISBLANK('WEEK 1 '!T23),ISBLANK('WEEK 1 '!T24),ISBLANK('WEEK 1 '!T25)),"",IF('WEEK 1 '!T27>=4,'WEEK 1 '!P27,IF('WEEK 1 '!T25<=3,'WEEK 1 '!P25-5,'WEEK 1 '!P25))) -> #REF!
A34: =IF(B35<5,"SKIP TO NEXT WORKOUT",HYPERLINK("https://www.youtube.com/watch?v=mGv8D2DGyNQ","2.DB CHEST FLY")) -> 2.DB CHEST FLY | H34: =HYPERLINK("https://www.youtube.com/watch?v=THb0dhfIu1k","2. MACHINE CHEST FLY") -> 2. MACHINE CHEST FLY
A35: DBL INC MAX | B35: 30 | G35: ALTERNATE | H35: DBL INC MAX | I35: ='WEEK 1 '!B35 -> #REF!
A36: SET | B36: WEIGHT | C36: REPS | D36: REST | E36: PREVIOUS | F36: REP LOG | H36: SET | I36: WEIGHT | J36: REPS | K36: REST | L36: PREVIOUS | M36: REP LOG
A37: 1 | B37: =mround(B35*0.29,2.5) -> 7.5 | C37: 15 | D37: 1 - 2 MIN | H37: 1 | I37: =mround('WEEK 1 '!I35*2*0.75,10) -> #REF! | J37: 15 | K37: 1 - 2 MIN
A38: 2 | B38: =mround(B35*0.29,2.5) -> 7.5 | C38: 15 | D38: 1 - 2 MIN | H38: 2 | I38: =mround('WEEK 1 '!I35*2*0.75,10) -> #REF! | J38: 15 | K38: 1 - 2 MIN
A41: =HYPERLINK("https://www.youtube.com/watch?v=PnaDzYh2axA","3. LAT PULL DOWN") -> 3. LAT PULL DOWN
A42: CURRENT MAX | B42: 100
A43: SET | B43: WEIGHT | C43: REPS | D43: REST | E43: PREVIOUS | F43: REP LOG
A44: 1 | B44: =mround('WEEK 1 '!B42*0.35,5) -> #REF! | C44: 6 | D44: 30s
A45: 2 | B45: =mround('WEEK 1 '!B42*0.65,5) -> #REF! | C45: 3 | D45: 1-2 MIN
A46: 3 | B46: =mround('WEEK 1 '!B42*0.9,5) -> #REF! | C46: 2 | D46: 1-2 MIN
A47: 4 | B47: ='WEEK 1 '!B42 -> #REF! | C47: 3 | D47: 1-5 MIN
A48: =IF('WEEK 1 '!F47<3,"PROCEED TO DOWN SETS","NEW 4 REP MAX ATTEMPT") -> #REF!
A49: =if('WEEK 1 '!F47<=2,"",5) -> #REF! | B49: =IF('WEEK 1 '!F47<=2,"",B47+5) -> #REF! | C49: =if('WEEK 1 '!F47<=2,"",4) -> #REF! | D49: =if('WEEK 1 '!F47<=2,"","1-5 MIN") -> #REF!
A50: =IF('WEEK 1 '!F49<4,"","6") -> #REF! | B50: =IF('WEEK 1 '!F49<4,"",B49+5) -> #REF! | C50: =IF('WEEK 1 '!F49<4,"","4") -> #REF! | D50: =IF('WEEK 1 '!F49<4,"","1-5 MIN") -> #REF!
A51: =IF(OR(ISBLANK('WEEK 1 '!F47),ISBLANK('WEEK 1 '!F46),ISBLANK('WEEK 1 '!F45)),"FILL OUT REP LOG FOR DOWN SETS","DOWN SETS") -> DOWN SETS
A52: =IF(OR(ISBLANK('WEEK 1 '!F47),ISBLANK('WEEK 1 '!F46),ISBLANK('WEEK 1 '!F45)),"",IF((AND(A49="",A50="")),5,IF((AND(A49>1,A50="")),6,7))) -> #REF! | B52: =MROUND('WEEK 1 '!B54*0.8,5) -> #REF! | C52: REP OUT | D52: 1-3 MIN
A53: =IF(OR(ISBLANK('WEEK 1 '!F47),ISBLANK('WEEK 1 '!F46),ISBLANK('WEEK 1 '!F45)),"",IF((AND(A49="",A50="")),6,IF((AND(A49>1,A50="")),7,8))) -> #REF! | B53: =mround('WEEK 1 '!B54*0.7,5) -> #REF! | C53: REP OUT | D53: 1-3 MIN
...

Sheet Copy of DETERMINING MAX WEEK 1
A8: WEEK 1 | I8: QUICK TIPS
A9: DAY 1 | I9: You only Log What's in GREEN
A10: CHEST & BACK | I10: Click The Title of The workout to see an Instructional Video
A11: This Weeks Goals
A12: swipe right for quick tips
A13: Today is all about setting the proper foundation for your future workouts. All we want to do is establish maximum strenght levels for some target muscle groups. It is important to keep great form as well as being honest in your logging.
A15: READ BEFORE WORKING OUT
A16: All of the workouts are meant to start off with a light weight to establish form and blood flow. If your 2nd set feels very light, you should jump to one of the recommended sets with a weight you feel will be moderate for you. Then from there work the consecutive sets toward your max then log it in the bright green box.
A17: =HYPERLINK("https://www.youtube.com/watch?v=qrv8cCA-WCY","WATCH- HOW TO MAX PROPERLY") -> WATCH- HOW TO MAX PROPERLY
A18: 1. BENCH PRESS | I18: =HYPERLINK("https://www.youtube.com/watch?v=ujVN-A0Z-ic","1. DUMBBELL INCLINE CHEST PRESS") -> 1. DUMBBELL INCLINE CHEST PRESS | O18: 1. MACHINE PRESS
A19: SET | B19: WEIGHT | C19: REPS | D19: REST | E19: REP LOG | I19: SET | J19: WEIGHT | K19: REPS | L19: REST | M19: REP LOG | O19: SET | P19: WEIGHT | Q19: REPS | R19: REST | S19: REP LOG
A20: 1 | B20: 85 | C20: 1 | D20: 2 MIN | I20: 1 | J20: 30 | K20: 4 | L20: 2 MIN | O20: 1 | P20: 85 | Q20: 4 | R20: 2 MIN
A21: 2 | B21: 135 | C21: 1 | D21: 2 MIN | I21: 2 | J21: 40 | K21: 4 | L21: 2 MIN | O21: 2 | P21: 135 | Q21: 4 | R21: 2 MIN
A22: 3 | B22: 155 | C22: 1 | D22: 2 MIN | I22: 3 | J22: 60 | K22: 4 | L22: 2 MIN | O22: 3 | P22: 155 | Q22: 4 | R22: 2 MIN
A23: 4 | B23: 170 | C23: 1 | D23: 2 MIN | I23: 4 | J23: 70 | K23: 4 | L23: 2 MIN | O23: 4 | P23: 170 | Q23: 4 | R23: 2 MIN
A24: 5 | B24: 185 | C24: 1 | D24: 2 MIN | I24: 5 | J24: 80 | K24: 4 | L24: 2 MIN | O24: 5 | P24: 185 | Q24: 4 | R24: 2 MIN
A25: 6 | B25: 205 | C25: 1 | D25: 2 MIN | I25: 6 | J25: 90 | K25: 4 | L25: 2 MIN | O25: 6 | P25: 205 | Q25: 4 | R25: 2 MIN
A26: 7 | B26: 225 | C26: 1 | D26: 2 MIN | I26: 7 | J26: 100 | K26: 4 | L26: 2 MIN | O26: 7 | P26: 225 | Q26: 4 | R26: 2 MIN
A27: 8 | B27: 240 | C27: 1 | D27: 2 MIN | I27: 8 | J27: 110 | K27: 4 | L27: 2 MIN | O27: 8 | P27: 240 | Q27: 4 | R27: 2 MIN
A28: 9 | B28: 260 | C28: 1 | D28: 2 MIN | I28: 9 | J28: 120 | K28: 4 | L28: 2 MIN | O28: 9 | P28: 260 | Q28: 4 | R28: 2 MIN
A29: 10 | B29: 280 | C29: 1 | D29: 2 MIN | I29: 10 | J29: 130 | K29: 4 | L29: 2 MIN | O29: 10 | P29: 280 | Q29: 4 | R29: 2 MIN
A30: 11 | B30: 305 | C30: 1 | D30: 2 MIN | I30: 11 | J30: 140 | K30: 4 | L30: 2 MIN | O30: 11 | P30: 305 | Q30: 4 | R30: 2 MIN
A31: INSERT FINAL MAX | E31: 245 | I31: INSERT FINAL MAX | O31: INSERT FINAL MAX
A33: =HYPERLINK("https://www.youtube.com/watch?v=PnaDzYh2axA","2. Lat Pull Down") -> 2. Lat Pull Down
A35: Set | B35: Weight | C35: Reps | D35: REST | E35: REP LOG
A36: Set1 | B36: 70 | C36: 4 | D36: 2 MIN
A37: Set 2 | B37: 90 | C37: 4 | D37: 2 MIN
A38: Set 3 | B38: 110 | C38: 4 | D38: 2 MIN
A39: Set 4 | B39: 130 | C39: 4 | D39: 2 MIN
A40: Set 5 | B40: 160 | C40: 4 | D40: 2 MIN
A41: Set 6 | B41: 180 | C41: 4 | D41: 2 MIN
A42: Set 7 | B42: 200 | C42: 4 | D42: 2 MIN
A43: Set 8 | B43: 210 | C43: 4 | D43: 2 MIN
A44: Set 9 | B44: 220 | C44: 4 | D44: 2 MIN
A45: Set 10 | B45: 230 | C45: 4 | D45: 2 MIN
A46: Set 11 | B46: 240 | C46: 4 | D46: 2 MIN
A47: INSERT FINAL MAX | E47: 250
A50: =HYPERLINK("https://www.youtube.com/watch?v=9YH1YvZbiY0","3. Machine Low Row") -> 3. Machine Low Row
A51: SET | B51: WEIGHT | C51: REPS | D51: REST | E51: REP LOG
A52: Set1 | B52: 70 | C52: 4 | D52: 2 MIN
...

Sheet Copy of Week 1 MASTER SHEET 1
A9: Week 1 | H9: QUICK TIPS
A10: =HYPERLINK("https://goo.gl/forms/3ibooB993Hi7SS2d2","PRESS TO RECORD BODY WEIGHT") -> PRESS TO RECORD BODY WEIGHT | H10: You only Log What's in GREEN
H11: Click The Title of The workout to see an Instructional Video
A12: This Weeks Goals
A13: This week we are going to jump you into a workout. As the weeks go on we will refine your workout more and it will become more targeted. Give it all you got and push to your limits everytime.
A15: DAY 1 | H15: ALTERNATE WORKOUTS | O15: ALTERNATE WORKOUTS
A18: CHEST & BACK | H18: CHEST & BACK | O18: CHEST & BACK
A19: =HYPERLINK("https://www.youtube.com/watch?v=iLgUDezDMbU","1. BENCH PRESS") -> 1. BENCH PRESS | H19: =HYPERLINK("https://www.youtube.com/watch?v=75e_H9Vq_Lw","1. MACHINE PRESS") -> 1. MACHINE PRESS | O19: =HYPERLINK("https://youtu.be/ujVN-A0Z-ic","1. DUMBBELL INCLINE PRESS") -> 1. DUMBBELL INCLINE PRESS
A20: CURRENT MAX | B20: ='Copy of DETERMINING MAX WEEK 1'!E31 -> 245 | H20: CURRENT MAX | I20: 120 | O20: CURRENT MAX | P20: 75
A21: SET | B21: WEIGHT | C21: REPS | D21: REST | E21: PREVIOUS | F21: REP LOG | H21: SET | I21: WEIGHT | J21: REPS | K21: REST | L21: PREVIOUS | M21: REP LOG | O21: SET | P21: WEIGHT | Q21: REPS | R21: REST | S21: PREVIOUS | T21: REP LOG
A22: 1 | B22: =IF( 'WEEK 1 '!B20<125,45,mround('WEEK 1 '!B20*0.35,5)) -> #REF! | C22: 6 | D22: 30s | H22: 1 | I22: =mround('WEEK 1 '!I20*0.35,5) -> #REF! | J22: 6 | K22: 30s | O22: 1 | P22: =mround('WEEK 1 '!P20*0.35,5) -> #REF! | Q22: 6 | R22: 1 MIN
A23: 2 | B23: =MROUND('WEEK 1 '!B20*0.8,5) -> #REF! | C23: 1 | D23: 1-2 MIN | H23: 2 | I23: =mround('WEEK 1 '!I20*0.65,5) -> #REF! | J23: 1 | K23: 1-2 MIN | O23: 2 | P23: =mround('WEEK 1 '!P20*0.65,5) -> #REF! | Q23: 1 | R23: 1 MIN
A24: 3 | B24: =mround('WEEK 1 '!B20*0.9,5) -> #REF! | C24: 1 | D24: 1-2 MIN | H24: 3 | I24: =mround('WEEK 1 '!I20*0.9,5) -> #REF! | J24: 1 | K24: 1-2 MIN | O24: 3 | P24: =mround('WEEK 1 '!P20*0.85,5) -> #REF! | Q24: 1 | R24: 1 MIN | V24: =90*0.93 -> 83.7
A25: 4 | B25: ='WEEK 1 '!B20 -> #REF! | C25: 1 | D25: 1-5 MIN | H25: 4 | I25: ='WEEK 1 '!I20 -> #REF! | J25: 1 | K25: 1-5 MIN | O25: 4 | P25: =mround('WEEK 1 '!P20*1,5) -> #REF! | Q25: REP OUT | R25: 1 MIN
A26: =IF('WEEK 1 '!F25<1,"PROCEED TO DOWN SETS","NEW 1 REP MAX ATTEMPT") -> #REF! | G26: ALTERNATE | H26: =IF('WEEK 1 '!M25<1,"PROCEED TO DOWN SETS","NEW 1 REP MAX ATTEMPT") -> #REF! | N26: ALTERNATE | O26: =IF(OR(ISBLANK('WEEK 1 '!T25),ISBLANK('WEEK 1 '!T24),ISBLANK('WEEK 1 '!T23)),"PROCEED TO DOWNSETS",if('WEEK 1 '!T25>=6,"NEW 4 REP MAX ATTEMPT","PROCEED TO DOWN SETS")) -> #REF!
A27: =if('WEEK 1 '!F25<1,"",5) -> #REF! | B27: =IF('WEEK 1 '!F25<1,"",B25+5) -> #REF! | C27: =if('WEEK 1 '!F25<1,"",1) -> #REF! | D27: =if('WEEK 1 '!F25<1,"","1-5 MIN") -> #REF! | H27: =if('WEEK 1 '!M25<1,"",5) -> #REF! | I27: =IF('WEEK 1 '!M25<1,"",I25+5) -> #REF! | J27: =if('WEEK 1 '!M25<1,"",1) -> #REF! | K27: =if('WEEK 1 '!M25<1,"","1-5 MIN") -> #REF! | O27: =IF(OR(ISBLANK('WEEK 1 '!T25),ISBLANK('WEEK 1 '!T24),ISBLANK('WEEK 1 '!T23)),"",IF('WEEK 1 '!T25>=6,5,"")) -> #REF! | P27: =IF(OR(ISBLANK('WEEK 1 '!T25),ISBLANK('WEEK 1 '!T24),ISBLANK('WEEK 1 '!T23)),"",IF('WEEK 1 '!T25>=6,'WEEK 1 '!P20+5,"")) -> #REF! | Q27: =IF(OR(ISBLANK('WEEK 1 '!T25),ISBLANK('WEEK 1 '!T24),ISBLANK('WEEK 1 '!T23)),"",IF('WEEK 1 '!T25>=6,"REP OUT","")) -> #REF! | R27: =IF(OR(ISBLANK('WEEK 1 '!T25),ISBLANK('WEEK 1 '!T24),ISBLANK('WEEK 1 '!T23)),"",IF('WEEK 1 '!T25>5,"1 MIN","")) -> #REF!
A28: =IF('WEEK 1 '!F27<1,"","6") -> #REF! | B28: =IF('WEEK 1 '!F27<1,"",B27+5) -> #REF! | C28: =IF('WEEK 1 '!F27<1,"","1") -> #REF! | D28: =IF('WEEK 1 '!F27<1,"","1-5 MIN") -> #REF! | H28: =IF('WEEK 1 '!M27<1,"","6") -> #REF! | I28: =IF('WEEK 1 '!M27<1,"",I27+5) -> #REF! | J28: =IF('WEEK 1 '!M27<1,"","1") -> #REF! | K28: =IF('WEEK 1 '!M27<1,"","1-5 MIN") -> #REF! | O28: =IF(OR(ISBLANK('WEEK 1 '!T25),ISBLANK('WEEK 1 '!T24),ISBLANK('WEEK 1 '!T23)),"FILL OUT REP LOG FIRST","DOWN SETS") -> DOWN SETS
A29: =IF(OR(ISBLANK('WEEK 1 '!F25),ISBLANK('WEEK 1 '!F24),ISBLANK('WEEK 1 '!F23)),"FILL OUT REP LOG FOR DOWN SETS","DOWN SETS") -> DOWN SETS | H29: =IF(OR(ISBLANK('WEEK 1 '!M25),ISBLANK('WEEK 1 '!M24),ISBLANK('WEEK 1 '!M23)),"FILL OUT REP LOG FOR DOWN SETS","DOWN SETS") -> DOWN SETS | O29: =IF('WEEK 1 '!T27>=4,"",IF(OR(ISBLANK('WEEK 1 '!T25),ISBLANK('WEEK 1 '!T24),ISBLANK('WEEK 1 '!T23)),"",IF('WEEK 1 '!T25>5,6,5))) -> #REF! | P29: =IF('WEEK 1 '!T27>=4,"",IF(OR(ISBLANK('WEEK 1 '!T25),ISBLANK('WEEK 1 '!T24),ISBLANK('WEEK 1 '!T23)),"",IF('WEEK 1 '!T25<6,mround('WEEK 1 '!P20*0.8,5),IF('WEEK 1 '!T25<10,mround('WEEK 1 '!P20*0.93,5),mround('WEEK 1 '!P20*0.7,5))))) -> #REF! | Q29: =IF('WEEK 1 '!T27>=4,"",IF(OR(ISBLANK('WEEK 1 '!T25),ISBLANK('WEEK 1 '!T24),ISBLANK('WEEK 1 '!T23)),"","REP OUT")) -> #REF! | R29: =IF('WEEK 1 '!T27>=4,"",IF(OR(ISBLANK('WEEK 1 '!T25),ISBLANK('WEEK 1 '!T24),ISBLANK('WEEK 1 '!T23)),"","1 MIN")) -> #REF! | V29: =0.7*85 -> 59.5
A30: =IF(OR(ISBLANK('WEEK 1 '!F25),ISBLANK('WEEK 1 '!F24),ISBLANK('WEEK 1 '!F23)),"",IF((AND(A27="",A28="")),5,IF((AND(A27>1,A28="")),6,7))) -> #REF! | B30: =IF(OR(ISBLANK('WEEK 1 '!F25),ISBLANK('WEEK 1 '!F24),ISBLANK('WEEK 1 '!F23)),"",MROUND('WEEK 1 '!B32*0.9,5)) -> #REF! | C30: =IF(OR(ISBLANK('WEEK 1 '!F25),ISBLANK('WEEK 1 '!F24),ISBLANK('WEEK 1 '!F23)),"","REP OUT") -> REP OUT | D30: =IF(OR(ISBLANK('WEEK 1 '!F25),ISBLANK('WEEK 1 '!F24),ISBLANK('WEEK 1 '!F23)),"","1-3 MIN") -> 1-3 MIN | H30: =IF(OR(ISBLANK('WEEK 1 '!M25),ISBLANK('WEEK 1 '!M24),ISBLANK('WEEK 1 '!M23)),"",IF((AND(H27="",H28="")),5,IF((AND(H27>1,H28="")),6,7))) -> #REF! | I30: =IF(OR(ISBLANK('WEEK 1 '!M25),ISBLANK('WEEK 1 '!M24),ISBLANK('WEEK 1 '!M23)),"",MROUND('WEEK 1 '!I32*0.9,5)) -> #REF! | J30: =IF(OR(ISBLANK('WEEK 1 '!M25),ISBLANK('WEEK 1 '!M24),ISBLANK('WEEK 1 '!M23)),"","REP OUT") -> REP OUT | K30: =IF(OR(ISBLANK('WEEK 1 '!M25),ISBLANK('WEEK 1 '!M24),ISBLANK('WEEK 1 '!M23)),"","1-3 MIN") -> 1-3 MIN | O30: =IF('WEEK 1 '!T27>=4,"",IF(OR(ISBLANK('WEEK 1 '!T25),ISBLANK('WEEK 1 '!T24),ISBLANK('WEEK 1 '!T23)),"",IF('WEEK 1 '!T25>5,7,6))) -> #REF! | P30: =IF('WEEK 1 '!T27>=4,"",IF(OR(ISBLANK('WEEK 1 '!T25),ISBLANK('WEEK 1 '!T24),ISBLANK('WEEK 1 '!T23)),"",IF('WEEK 1 '!T25<6,mround('WEEK 1 '!P20*0.65,5),IF('WEEK 1 '!T25<10,mround('WEEK 1 '!P20*0.7,5),mround('WEEK 1 '!P20*0.65,5))))) -> #REF! | Q30: =IF('WEEK 1 '!T27>=4,"",IF(OR(ISBLANK('WEEK 1 '!T25),ISBLANK('WEEK 1 '!T24),ISBLANK('WEEK 1 '!T23)),"","REP OUT")) -> #REF! | R30: =IF('WEEK 1 '!T27>=4,"",IF(OR(ISBLANK('WEEK 1 '!T25),ISBLANK('WEEK 1 '!T24),ISBLANK('WEEK 1 '!T23)),"","1 MIN")) -> #REF!
A31: =IF(OR(ISBLANK('WEEK 1 '!F25),ISBLANK('WEEK 1 '!F24),ISBLANK('WEEK 1 '!F23)),"",IF((AND(A27="",A28="")),6,IF((AND(A27>1,A28="")),7,8))) -> #REF! | B31: =IF(OR(ISBLANK('WEEK 1 '!F25),ISBLANK('WEEK 1 '!F24),ISBLANK('WEEK 1 '!F23)),"",mround('WEEK 1 '!B32*0.78,5)) -> #REF! | C31: =IF(OR(ISBLANK('WEEK 1 '!F25),ISBLANK('WEEK 1 '!F24),ISBLANK('WEEK 1 '!F23)),"","REP OUT") -> REP OUT | D31: =IF(OR(ISBLANK('WEEK 1 '!F25),ISBLANK('WEEK 1 '!F24),ISBLANK('WEEK 1 '!F23)),"","1-3 MIN") -> 1-3 MIN | H31: =IF(OR(ISBLANK('WEEK 1 '!M25),ISBLANK('WEEK 1 '!M24),ISBLANK('WEEK 1 '!M23)),"",IF((AND(H27="",H28="")),6,IF((AND(H27>1,H28="")),7,8))) -> #REF! | I31: =IF(OR(ISBLANK('WEEK 1 '!M25),ISBLANK('WEEK 1 '!M24),ISBLANK('WEEK 1 '!M23)),"",mround('WEEK 1 '!I32*0.78,5)) -> #REF! | J31: =IF(OR(ISBLANK('WEEK 1 '!M25),ISBLANK('WEEK 1 '!M24),ISBLANK('WEEK 1 '!M23)),"","REP OUT") -> REP OUT | K31: =IF(OR(ISBLANK('WEEK 1 '!M25),ISBLANK('WEEK 1 '!M24),ISBLANK('WEEK 1 '!M23)),"","1-3 MIN") -> 1-3 MIN | O31: =IF('WEEK 1 '!T27<4,"",IF(OR(ISBLANK('WEEK 1 '!T25),ISBLANK('WEEK 1 '!T24),ISBLANK('WEEK 1 '!T23)),"",IF('WEEK 1 '!T27>3,6,5))) -> #REF! | P31: =IF('WEEK 1 '!T27<4,"",IF(OR(ISBLANK('WEEK 1 '!T25),ISBLANK('WEEK 1 '!T24),ISBLANK('WEEK 1 '!T23)),"",IF('WEEK 1 '!T27<6,mround('WEEK 1 '!P33*0.8,5),IF('WEEK 1 '!T27<10,mround('WEEK 1 '!P33*0.93,5),mround('WEEK 1 '!P33*0.7,5))))) -> #REF! | Q31: =IF('WEEK 1 '!T27<4,"",IF(OR(ISBLANK('WEEK 1 '!T25),ISBLANK('WEEK 1 '!T24),ISBLANK('WEEK 1 '!T23)),"","REP OUT")) -> #REF! | R31: =IF('WEEK 1 '!T27<4,"",IF(OR(ISBLANK('WEEK 1 '!T25),ISBLANK('WEEK 1 '!T24),ISBLANK('WEEK 1 '!T23)),"","1 MIN")) -> #REF!
A32: FINAL MAX | B32: =IF(OR(ISBLANK('WEEK 1 '!F25),ISBLANK('WEEK 1 '!F24),ISBLANK('WEEK 1 '!F23)),"",IF('WEEK 1 '!F28>=1,'WEEK 1 '!B28,IF('WEEK 1 '!F27>=1,'WEEK 1 '!B27,IF('WEEK 1 '!F25<1,'WEEK 1 '!B25-5,'WEEK 1 '!B25)))) -> #REF! | H32: FINAL MAX | I32: =IF(OR(ISBLANK('WEEK 1 '!M25),ISBLANK('WEEK 1 '!M24),ISBLANK('WEEK 1 '!M23)),"",IF('WEEK 1 '!M28>=1,'WEEK 1 '!I28,IF('WEEK 1 '!M27>=1,'WEEK 1 '!I27,IF('WEEK 1 '!M25<1,'WEEK 1 '!I25-5,'WEEK 1 '!I25)))) -> #REF! | O32: =IF('WEEK 1 '!T27<4,"",IF(OR(ISBLANK('WEEK 1 '!T25),ISBLANK('WEEK 1 '!T24),ISBLANK('WEEK 1 '!T23)),"",IF('WEEK 1 '!T27>3,7,""))) -> #REF! | P32: =IF('WEEK 1 '!T27<4,"",IF(OR(ISBLANK('WEEK 1 '!T25),ISBLANK('WEEK 1 '!T24),ISBLANK('WEEK 1 '!T23)),"",IF('WEEK 1 '!T27<6,mround('WEEK 1 '!P33*0.65,5),IF('WEEK 1 '!T27<10,mround('WEEK 1 '!P33*0.7,5),mround('WEEK 1 '!P33*0.65,5))))) -> #REF! | Q32: =IF('WEEK 1 '!T27<4,"",IF(OR(ISBLANK('WEEK 1 '!T25),ISBLANK('WEEK 1 '!T24),ISBLANK('WEEK 1 '!T23)),"","REP OUT")) -> #REF! | R32: =IF('WEEK 1 '!T27<4,"",IF(OR(ISBLANK('WEEK 1 '!T25),ISBLANK('WEEK 1 '!T24),ISBLANK('WEEK 1 '!T23)),"","1 MIN")) -> #REF!
O33: FINAL MAX | P33: =IF(OR(ISBLANK('WEEK 1 '!T23),ISBLANK('WEEK 1 '!T24),ISBLANK('WEEK 1 '!T25)),"",IF('WEEK 1 '!T27>=4,'WEEK 1 '!P27,IF('WEEK 1 '!T25<=3,'WEEK 1 '!P25-5,'WEEK 1 '!P25))) -> #REF!
A34: =IF(B35<5,"SKIP TO NEXT WORKOUT",HYPERLINK("https://www.youtube.com/watch?v=mGv8D2DGyNQ","2.DB CHEST FLY")) -> 2.DB CHEST FLY | H34: =HYPERLINK("https://www.youtube.com/watch?v=THb0dhfIu1k","2. MACHINE CHEST FLY") -> 2. MACHINE CHEST FLY
A35: DBL INC MAX | B35: 30 | G35: ALTERNATE | H35: DBL INC MAX | I35: ='WEEK 1 '!B35 -> #REF!
A36: SET | B36: WEIGHT | C36: REPS | D36: REST | E36: PREVIOUS | F36: REP LOG | H36: SET | I36: WEIGHT | J36: REPS | K36: REST | L36: PREVIOUS | M36: REP LOG
A37: 1 | B37: =mround(B35*0.29,2.5) -> 7.5 | C37: 15 | D37: 1 - 2 MIN | H37: 1 | I37: =mround('WEEK 1 '!I35*2*0.75,10) -> #REF! | J37: 15 | K37: 1 - 2 MIN
A38: 2 | B38: =mround(B35*0.29,2.5) -> 7.5 | C38: 15 | D38: 1 - 2 MIN | H38: 2 | I38: =mround('WEEK 1 '!I35*2*0.75,10) -> #REF! | J38: 15 | K38: 1 - 2 MIN
A41: =HYPERLINK("https://www.youtube.com/watch?v=PnaDzYh2axA","3. LAT PULL DOWN") -> 3. LAT PULL DOWN
A42: CURRENT MAX | B42: 100
A43: SET | B43: WEIGHT | C43: REPS | D43: REST | E43: PREVIOUS | F43: REP LOG
A44: 1 | B44: =mround('WEEK 1 '!B42*0.35,5) -> #REF! | C44: 6 | D44: 30s
A45: 2 | B45: =mround('WEEK 1 '!B42*0.65,5) -> #REF! | C45: 3 | D45: 1-2 MIN
A46: 3 | B46: =mround('WEEK 1 '!B42*0.9,5) -> #REF! | C46: 2 | D46: 1-2 MIN
A47: 4 | B47: ='WEEK 1 '!B42 -> #REF! | C47: 3 | D47: 1-5 MIN
A48: =IF('WEEK 1 '!F47<3,"PROCEED TO DOWN SETS","NEW 4 REP MAX ATTEMPT") -> #REF!
A49: =if('WEEK 1 '!F47<=2,"",5) -> #REF! | B49: =IF('WEEK 1 '!F47<=2,"",B47+5) -> #REF! | C49: =if('WEEK 1 '!F47<=2,"",4) -> #REF! | D49: =if('WEEK 1 '!F47<=2,"","1-5 MIN") -> #REF!
A50: =IF('WEEK 1 '!F49<4,"","6") -> #REF! | B50: =IF('WEEK 1 '!F49<4,"",B49+5) -> #REF! | C50: =IF('WEEK 1 '!F49<4,"","4") -> #REF! | D50: =IF('WEEK 1 '!F49<4,"","1-5 MIN") -> #REF!
A51: =IF(OR(ISBLANK('WEEK 1 '!F47),ISBLANK('WEEK 1 '!F46),ISBLANK('WEEK 1 '!F45)),"FILL OUT REP LOG FOR DOWN SETS","DOWN SETS") -> DOWN SETS
A52: =IF(OR(ISBLANK('WEEK 1 '!F47),ISBLANK('WEEK 1 '!F46),ISBLANK('WEEK 1 '!F45)),"",IF((AND(A49="",A50="")),5,IF((AND(A49>1,A50="")),6,7))) -> #REF! | B52: =MROUND('WEEK 1 '!B54*0.8,5) -> #REF! | C52: REP OUT | D52: 1-3 MIN
A53: =IF(OR(ISBLANK('WEEK 1 '!F47),ISBLANK('WEEK 1 '!F46),ISBLANK('WEEK 1 '!F45)),"",IF((AND(A49="",A50="")),6,IF((AND(A49>1,A50="")),7,8))) -> #REF! | B53: =mround('WEEK 1 '!B54*0.7,5) -> #REF! | C53: REP OUT | D53: 1-3 MIN
...

Sheet Copy of WEEK 1 
A9: Week 1 | H9: QUICK TIPS
A10: ='Week 1 MASTER SHEET'!A10 -> #REF! | H10: IF IT'S GREEN=NEEDS YOUR INPUT
H11: Click The Title of The workout to see an Instructional Video
A12: This Weeks Goals | G12: ='Week 1 MASTER SHEET'!H12 -> #REF!
A13: This week we are going to jump you into a workout. As the weeks go on we will refine your workout more and it will become more targeted. Give it all you got and push to your limits everytime.
A14: SWIPE RIGHT FOR QUICK TIPS
A15: DAY 1 | H15: ALTERNATE WORKOUTS | O15: ='Week 1 MASTER SHEET'!O15 -> #REF!
A18: CHEST & BACK | H18: ='Week 1 MASTER SHEET'!H18 -> #REF! | O18: ='Week 1 MASTER SHEET'!O18 -> #REF!
A19: =HYPERLINK("https://www.youtube.com/watch?v=iLgUDezDMbU","1. BENCH PRESS") -> 1. BENCH PRESS | G19: ALTERNATE | H19: ='Week 1 MASTER SHEET'!H19 -> #REF! | O19: ='Week 1 MASTER SHEET'!O19 -> #REF!
A20: CURRENT MAX | B20: 100 | H20: ='Week 1 MASTER SHEET'!H20 -> #REF! | I20: ='DETERMINING MAX WEEK'!S31 -> #REF! | O20: ='Week 1 MASTER SHEET'!O20 -> #REF! | P20: 75
A21: SET | B21: WEIGHT | C21: REPS | D21: REST | E21: PREVIOUS | F21: REP LOG | H21: ='Week 1 MASTER SHEET'!H21 -> #REF! | I21: ='Week 1 MASTER SHEET'!I21 -> #REF! | J21: ='Week 1 MASTER SHEET'!J21 -> #REF! | K21: ='Week 1 MASTER SHEET'!K21 -> #REF! | L21: ='Week 1 MASTER SHEET'!L21 -> #REF! | M21: REP LOG | O21: ='Week 1 MASTER SHEET'!O21 -> #REF! | P21: ='Week 1 MASTER SHEET'!P21 -> #REF! | Q21: ='Week 1 MASTER SHEET'!Q21 -> #REF! | R21: ='Week 1 MASTER SHEET'!R21 -> #REF! | S21: ='Week 1 MASTER SHEET'!S21 -> #REF! | T21: REP LOG
A22: ='Week 1 MASTER SHEET'!A22 -> #REF! | B22: ='Week 1 MASTER SHEET'!B22 -> #REF! | C22: ='Week 1 MASTER SHEET'!C22 -> #REF! | D22: ='Week 1 MASTER SHEET'!D22 -> #REF! | F22: 6 | H22: ='Week 1 MASTER SHEET'!H22 -> #REF! | I22: ='Week 1 MASTER SHEET'!I22 -> #REF! | J22: ='Week 1 MASTER SHEET'!J22 -> #REF! | K22: ='Week 1 MASTER SHEET'!K22 -> #REF! | L22: ='Week 1 MASTER SHEET'!L22 -> #REF! | O22: ='Week 1 MASTER SHEET'!O22 -> #REF! | P22: ='Week 1 MASTER SHEET'!P22 -> #REF! | Q22: ='Week 1 MASTER SHEET'!Q22 -> #REF! | R22: ='Week 1 MASTER SHEET'!R22 -> #REF! | S22: ='Week 1 MASTER SHEET'!S22 -> #REF! | T22: 6
A23: ='Week 1 MASTER SHEET'!A23 -> #REF! | B23: ='Week 1 MASTER SHEET'!B23 -> #REF! | C23: ='Week 1 MASTER SHEET'!C23 -> #REF! | D23: ='Week 1 MASTER SHEET'!D23 -> #REF! | E23: ='Week 1 MASTER SHEET'!E23 -> #REF! | F23: 1 | H23: ='Week 1 MASTER SHEET'!H23 -> #REF! | I23: ='Week 1 MASTER SHEET'!I23 -> #REF! | J23: ='Week 1 MASTER SHEET'!J23 -> #REF! | K23: ='Week 1 MASTER SHEET'!K23 -> #REF! | L23: ='Week 1 MASTER SHEET'!L23 -> #REF! | O23: ='Week 1 MASTER SHEET'!O23 -> #REF! | P23: ='Week 1 MASTER SHEET'!P23 -> #REF! | Q23: ='Week 1 MASTER SHEET'!Q23 -> #REF! | R23: ='Week 1 MASTER SHEET'!R23 -> #REF! | S23: ='Week 1 MASTER SHEET'!S23 -> #REF! | T23: 1
A24: ='Week 1 MASTER SHEET'!A24 -> #REF! | B24: ='Week 1 MASTER SHEET'!B24 -> #REF! | C24: ='Week 1 MASTER SHEET'!C24 -> #REF! | D24: ='Week 1 MASTER SHEET'!D24 -> #REF! | E24: ='Week 1 MASTER SHEET'!E24 -> #REF! | F24: 1 | H24: ='Week 1 MASTER SHEET'!H24 -> #REF! | I24: ='Week 1 MASTER SHEET'!I24 -> #REF! | J24: ='Week 1 MASTER SHEET'!J24 -> #REF! | K24: ='Week 1 MASTER SHEET'!K24 -> #REF! | L24: ='Week 1 MASTER SHEET'!L24 -> #REF! | O24: ='Week 1 MASTER SHEET'!O24 -> #REF! | P24: ='Week 1 MASTER SHEET'!P24 -> #REF! | Q24: ='Week 1 MASTER SHEET'!Q24 -> #REF! | R24: ='Week 1 MASTER SHEET'!R24 -> #REF! | S24: ='Week 1 MASTER SHEET'!S24 -> #REF! | T24: 1
A25: ='Week 1 MASTER SHEET'!A25 -> #REF! | B25: ='Week 1 MASTER SHEET'!B25 -> #REF! | C25: ='Week 1 MASTER SHEET'!C25 -> #REF! | D25: ='Week 1 MASTER SHEET'!D25 -> #REF! | E25: ='Week 1 MASTER SHEET'!E25 -> #REF! | F25: 1 | H25: ='Week 1 MASTER SHEET'!H25 -> #REF! | I25: ='Week 1 MASTER SHEET'!I25 -> #REF! | J25: ='Week 1 MASTER SHEET'!J25 -> #REF! | K25: ='Week 1 MASTER SHEET'!K25 -> #REF! | L25: ='Week 1 MASTER SHEET'!L25 -> #REF! | O25: ='Week 1 MASTER SHEET'!O25 -> #REF! | P25: ='Week 1 MASTER SHEET'!P25 -> #REF! | Q25: ='Week 1 MASTER SHEET'!Q25 -> #REF! | R25: ='Week 1 MASTER SHEET'!R25 -> #REF! | S25: ='Week 1 MASTER SHEET'!S25 -> #REF! | T25: 6
A26: ='Week 1 MASTER SHEET'!A26 -> #REF! | H26: ='Week 1 MASTER SHEET'!H26 -> #REF! | O26: ='Week 1 MASTER SHEET'!O26 -> #REF!
A27: ='Week 1 MASTER SHEET'!A27 -> #REF! | B27: ='Week 1 MASTER SHEET'!B27 -> #REF! | C27: ='Week 1 MASTER SHEET'!C27 -> #REF! | D27: ='Week 1 MASTER SHEET'!D27 -> #REF! | E27: ='Week 1 MASTER SHEET'!E27 -> #REF! | H27: ='Week 1 MASTER SHEET'!H27 -> #REF! | I27: ='Week 1 MASTER SHEET'!I27 -> #REF! | J27: ='Week 1 MASTER SHEET'!J27 -> #REF! | K27: ='Week 1 MASTER SHEET'!K27 -> #REF! | L27: ='Week 1 MASTER SHEET'!L27 -> #REF! | O27: ='Week 1 MASTER SHEET'!O27 -> #REF! | P27: ='Week 1 MASTER SHEET'!P27 -> #REF! | Q27: ='Week 1 MASTER SHEET'!Q27 -> #REF! | R27: ='Week 1 MASTER SHEET'!R27 -> #REF! | S27: ='Week 1 MASTER SHEET'!S27 -> #REF! | T27: 3
A28: ='Week 1 MASTER SHEET'!A28 -> #REF! | B28: ='Week 1 MASTER SHEET'!B28 -> #REF! | C28: ='Week 1 MASTER SHEET'!C28 -> #REF! | D28: ='Week 1 MASTER SHEET'!D28 -> #REF! | E28: ='Week 1 MASTER SHEET'!E28 -> #REF! | H28: ='Week 1 MASTER SHEET'!H28 -> #REF! | I28: ='Week 1 MASTER SHEET'!I28 -> #REF! | J28: ='Week 1 MASTER SHEET'!J28 -> #REF! | K28: ='Week 1 MASTER SHEET'!K28 -> #REF! | O28: ='Week 1 MASTER SHEET'!O28 -> #REF!
A29: ='Week 1 MASTER SHEET'!A29 -> #REF! | H29: ='Week 1 MASTER SHEET'!H29 -> #REF! | O29: ='Week 1 MASTER SHEET'!O29 -> #REF! | P29: ='Week 1 MASTER SHEET'!P29 -> #REF! | Q29: ='Week 1 MASTER SHEET'!Q29 -> #REF! | R29: ='Week 1 MASTER SHEET'!R29 -> #REF! | S29: ='Week 1 MASTER SHEET'!S29 -> #REF! | T29: 6
A30: ='Week 1 MASTER SHEET'!A30 -> #REF! | C30: ='Week 1 MASTER SHEET'!C30 -> #REF! | D30: ='Week 1 MASTER SHEET'!D30 -> #REF! | E30: ='Week 1 MASTER SHEET'!E30 -> #REF! | H30: ='Week 1 MASTER SHEET'!H30 -> #REF! | I30: ='Week 1 MASTER SHEET'!I30 -> #REF! | J30: ='Week 1 MASTER SHEET'!J30 -> #REF! | K30: ='Week 1 MASTER SHEET'!K30 -> #REF! | L30: ='Week 1 MASTER SHEET'!L30 -> #REF! | O30: ='Week 1 MASTER SHEET'!O30 -> #REF! | P30: ='Week 1 MASTER SHEET'!P30 -> #REF! | Q30: ='Week 1 MASTER SHEET'!Q30 -> #REF! | R30: ='Week 1 MASTER SHEET'!R30 -> #REF! | S30: ='Week 1 MASTER SHEET'!S30 -> #REF! | T30: 10
A31: ='Week 1 MASTER SHEET'!A31 -> #REF! | B31: 185 | C31: ='Week 1 MASTER SHEET'!C31 -> #REF! | D31: ='Week 1 MASTER SHEET'!D31 -> #REF! | E31: ='Week 1 MASTER SHEET'!E31 -> #REF! | H31: ='Week 1 MASTER SHEET'!H31 -> #REF! | I31: ='Week 1 MASTER SHEET'!I31 -> #REF! | J31: ='Week 1 MASTER SHEET'!J31 -> #REF! | K31: ='Week 1 MASTER SHEET'!K31 -> #REF! | L31: ='Week 1 MASTER SHEET'!L31 -> #REF! | O31: ='Week 1 MASTER SHEET'!O31 -> #REF! | P31: ='Week 1 MASTER SHEET'!P31 -> #REF! | Q31: ='Week 1 MASTER SHEET'!Q31 -> #REF! | R31: ='Week 1 MASTER SHEET'!R31 -> #REF! | S31: ='Week 1 MASTER SHEET'!S31 -> #REF!
A32: ='Week 1 MASTER SHEET'!A32 -> #REF! | B32: ='Week 1 MASTER SHEET'!B32 -> #REF! | H32: ='Week 1 MASTER SHEET'!H32 -> #REF! | I32: ='Week 1 MASTER SHEET'!I32 -> #REF! | O32: ='Week 1 MASTER SHEET'!O32 -> #REF! | P32: ='Week 1 MASTER SHEET'!P32 -> #REF! | Q32: ='Week 1 MASTER SHEET'!Q32 -> #REF! | R32: ='Week 1 MASTER SHEET'!R32 -> #REF! | S32: ='Week 1 MASTER SHEET'!S32 -> #REF!
O33: ='Week 1 MASTER SHEET'!O33 -> #REF! | P33: ='Week 1 MASTER SHEET'!P33 -> #REF!
A34: ='Week 1 MASTER SHEET'!A34 -> #REF! | G34: ALTERNATE | H34: ='Week 1 MASTER SHEET'!H34 -> #REF!
A35: ='Week 1 MASTER SHEET'!A35 -> #REF! | B35: 30 | H35: ='Week 1 MASTER SHEET'!H35 -> #REF! | I35: 75
A36: ='Week 1 MASTER SHEET'!A36 -> #REF! | B36: ='Week 1 MASTER SHEET'!B36 -> #REF! | C36: ='Week 1 MASTER SHEET'!C36 -> #REF! | D36: ='Week 1 MASTER SHEET'!D36 -> #REF! | E36: ='Week 1 MASTER SHEET'!E36 -> #REF! | F36: REP LOG | H36: ='Week 1 MASTER SHEET'!H36 -> #REF! | I36: ='Week 1 MASTER SHEET'!I36 -> #REF! | J36: ='Week 1 MASTER SHEET'!J36 -> #REF! | K36: ='Week 1 MASTER SHEET'!K36 -> #REF! | L36: ='Week 1 MASTER SHEET'!L36 -> #REF! | M36: REP LOG
A37: ='Week 1 MASTER SHEET'!A37 -> #REF! | B37: ='Week 1 MASTER SHEET'!B37 -> #REF! | C37: ='Week 1 MASTER SHEET'!C37 -> #REF! | D37: ='Week 1 MASTER SHEET'!D37 -> #REF! | E37: ='Week 1 MASTER SHEET'!E37 -> #REF! | F37: 15 | H37: ='Week 1 MASTER SHEET'!H37 -> #REF! | I37: ='Week 1 MASTER SHEET'!I37 -> #REF! | J37: ='Week 1 MASTER SHEET'!J37 -> #REF! | K37: ='Week 1 MASTER SHEET'!K37 -> #REF! | L37: ='Week 1 MASTER SHEET'!L37 -> #REF!
A38: ='Week 1 MASTER SHEET'!A38 -> #REF! | B38: ='Week 1 MASTER SHEET'!B38 -> #REF! | C38: ='Week 1 MASTER SHEET'!C38 -> #REF! | D38: ='Week 1 MASTER SHEET'!D38 -> #REF! | E38: ='Week 1 MASTER SHEET'!E38 -> #REF! | F38: 15 | H38: ='Week 1 MASTER SHEET'!H38 -> #REF! | I38: ='Week 1 MASTER SHEET'!I38 -> #REF! | J38: ='Week 1 MASTER SHEET'!J38 -> #REF! | K38: ='Week 1 MASTER SHEET'!K38 -> #REF! | L38: ='Week 1 MASTER SHEET'!L38 -> #REF!
A41: ='Week 1 MASTER SHEET'!A41 -> #REF!
A42: ='Week 1 MASTER SHEET'!A42 -> #REF! | B42: 255
A43: ='Week 1 MASTER SHEET'!A43 -> #REF! | B43: ='Week 1 MASTER SHEET'!B43 -> #REF! | C43: ='Week 1 MASTER SHEET'!C43 -> #REF! | D43: ='Week 1 MASTER SHEET'!D43 -> #REF! | E43: ='Week 1 MASTER SHEET'!E43 -> #REF! | F43: REP LOG
A44: ='Week 1 MASTER SHEET'!A44 -> #REF! | B44: ='Week 1 MASTER SHEET'!B44 -> #REF! | C44: ='Week 1 MASTER SHEET'!C44 -> #REF! | D44: ='Week 1 MASTER SHEET'!D44 -> #REF! | E44: ='Week 1 MASTER SHEET'!E44 -> #REF! | F44: 6
A45: ='Week 1 MASTER SHEET'!A45 -> #REF! | B45: ='Week 1 MASTER SHEET'!B45 -> #REF! | C45: ='Week 1 MASTER SHEET'!C45 -> #REF! | D45: ='Week 1 MASTER SHEET'!D45 -> #REF! | E45: ='Week 1 MASTER SHEET'!E45 -> #REF! | F45: 3
A46: ='Week 1 MASTER SHEET'!A46 -> #REF! | B46: ='Week 1 MASTER SHEET'!B46 -> #REF! | C46: ='Week 1 MASTER SHEET'!C46 -> #REF! | D46: ='Week 1 MASTER SHEET'!D46 -> #REF! | E46: ='Week 1 MASTER SHEET'!E46 -> #REF! | F46: 2
A47: ='Week 1 MASTER SHEET'!A47 -> #REF! | B47: ='Week 1 MASTER SHEET'!B47 -> #REF! | C47: ='Week 1 MASTER SHEET'!C47 -> #REF! | D47: ='Week 1 MASTER SHEET'!D47 -> #REF! | E47: ='Week 1 MASTER SHEET'!E47 -> #REF! | F47: 3
A48: ='Week 1 MASTER SHEET'!A48 -> #REF!
A49: ='Week 1 MASTER SHEET'!A49 -> #REF! | B49: ='Week 1 MASTER SHEET'!B49 -> #REF! | C49: ='Week 1 MASTER SHEET'!C49 -> #REF! | D49: ='Week 1 MASTER SHEET'!D49 -> #REF! | E49: ='Week 1 MASTER SHEET'!E49 -> #REF! | F49: 4
A50: ='Week 1 MASTER SHEET'!A50 -> #REF! | B50: ='Week 1 MASTER SHEET'!B50 -> #REF! | C50: ='Week 1 MASTER SHEET'!C50 -> #REF! | D50: ='Week 1 MASTER SHEET'!D50 -> #REF! | E50: ='Week 1 MASTER SHEET'!E50 -> #REF! | F50: 3
A51: ='Week 1 MASTER SHEET'!A51 -> #REF!
A52: ='Week 1 MASTER SHEET'!A52 -> #REF! | B52: ='Week 1 MASTER SHEET'!B52 -> #REF! | C52: ='Week 1 MASTER SHEET'!C52 -> #REF! | D52: ='Week 1 MASTER SHEET'!D52 -> #REF! | E52: ='Week 1 MASTER SHEET'!E52 -> #REF! | F52: 6
...

Sheet Copy of WEEK 2
A9: ='Week 2 (MASTER SHEET)'!A9 -> #REF! | H9: QUICK TIPS
A10: ='Week 2 (MASTER SHEET)'!A10 -> #REF! | H10: IF IT'S GREEN=NEEDS YOUR INPUT
H11: Click The Title of The workout to see an Instructional Video
A12: This Weeks Goals
A13: ='Week 2 (MASTER SHEET)'!A13 -> #REF!
A14: SWIPE RIGHT FOR QUICK TIPS
A16: DAY 1 | H16: ='Week 2 (MASTER SHEET)'!H16 -> #REF!
A19: ='Week 2 (MASTER SHEET)'!A19 -> #REF! | H19: ='Week 2 (MASTER SHEET)'!H19 -> #REF!
A20: ='Week 2 (MASTER SHEET)'!A20 -> #REF! | G20: ALTERNATE | H20: ='Week 2 (MASTER SHEET)'!H20 -> #REF!
A21: ='Week 2 (MASTER SHEET)'!A21 -> #REF! | B21: 75 | H21: ='Week 2 (MASTER SHEET)'!H21 -> #REF! | I21: ='Week 2 (MASTER SHEET)'!I21 -> #REF!
A22: ='Week 2 (MASTER SHEET)'!A22 -> #REF! | B22: ='Week 2 (MASTER SHEET)'!B22 -> #REF! | C22: ='Week 2 (MASTER SHEET)'!C22 -> #REF! | D22: ='Week 2 (MASTER SHEET)'!D22 -> #REF! | E22: ='Week 2 (MASTER SHEET)'!E22 -> #REF! | F22: ='Week 2 (MASTER SHEET)'!F22 -> #REF! | H22: ='Week 2 (MASTER SHEET)'!H22 -> #REF! | I22: ='Week 2 (MASTER SHEET)'!I22 -> #REF! | J22: ='Week 2 (MASTER SHEET)'!J22 -> #REF! | K22: ='Week 2 (MASTER SHEET)'!K22 -> #REF! | L22: ='Week 2 (MASTER SHEET)'!L22 -> #REF! | M22: ='Week 2 (MASTER SHEET)'!M22 -> #REF!
A23: ='Week 2 (MASTER SHEET)'!A23 -> #REF! | B23: ='Week 2 (MASTER SHEET)'!B23 -> #REF! | C23: ='Week 2 (MASTER SHEET)'!C23 -> #REF! | D23: ='Week 2 (MASTER SHEET)'!D23 -> #REF! | E23: ='Week 2 (MASTER SHEET)'!E23 -> #REF! | F23: 6 | H23: ='Week 2 (MASTER SHEET)'!H23 -> #REF! | I23: ='Week 2 (MASTER SHEET)'!I23 -> #REF! | J23: ='Week 2 (MASTER SHEET)'!J23 -> #REF! | K23: ='Week 2 (MASTER SHEET)'!K23 -> #REF! | L23: ='Week 2 (MASTER SHEET)'!L23 -> #REF!
A24: ='Week 2 (MASTER SHEET)'!A24 -> #REF! | B24: ='Week 2 (MASTER SHEET)'!B24 -> #REF! | C24: ='Week 2 (MASTER SHEET)'!C24 -> #REF! | D24: ='Week 2 (MASTER SHEET)'!D24 -> #REF! | E24: ='Week 2 (MASTER SHEET)'!E24 -> #REF! | F24: 1 | H24: ='Week 2 (MASTER SHEET)'!H24 -> #REF! | I24: ='Week 2 (MASTER SHEET)'!I24 -> #REF! | J24: ='Week 2 (MASTER SHEET)'!J24 -> #REF! | K24: ='Week 2 (MASTER SHEET)'!K24 -> #REF! | L24: ='Week 2 (MASTER SHEET)'!L24 -> #REF!
A25: ='Week 2 (MASTER SHEET)'!A25 -> #REF! | B25: ='Week 2 (MASTER SHEET)'!B25 -> #REF! | C25: ='Week 2 (MASTER SHEET)'!C25 -> #REF! | D25: ='Week 2 (MASTER SHEET)'!D25 -> #REF! | E25: ='Week 2 (MASTER SHEET)'!E25 -> #REF! | F25: 1 | H25: ='Week 2 (MASTER SHEET)'!H25 -> #REF! | I25: ='Week 2 (MASTER SHEET)'!I25 -> #REF! | J25: ='Week 2 (MASTER SHEET)'!J25 -> #REF! | K25: ='Week 2 (MASTER SHEET)'!K25 -> #REF! | L25: ='Week 2 (MASTER SHEET)'!L25 -> #REF!
A26: ='Week 2 (MASTER SHEET)'!A26 -> #REF! | B26: ='Week 2 (MASTER SHEET)'!B26 -> #REF! | C26: ='Week 2 (MASTER SHEET)'!C26 -> #REF! | D26: ='Week 2 (MASTER SHEET)'!D26 -> #REF! | E26: ='Week 2 (MASTER SHEET)'!E26 -> #REF! | F26: 6 | H26: ='Week 2 (MASTER SHEET)'!H26 -> #REF! | I26: ='Week 2 (MASTER SHEET)'!I26 -> #REF! | J26: ='Week 2 (MASTER SHEET)'!J26 -> #REF! | K26: ='Week 2 (MASTER SHEET)'!K26 -> #REF! | L26: ='Week 2 (MASTER SHEET)'!L26 -> #REF!
A27: ='Week 2 (MASTER SHEET)'!A27 -> #REF! | H27: ='Week 2 (MASTER SHEET)'!H27 -> #REF!
A28: ='Week 2 (MASTER SHEET)'!A28 -> #REF! | B28: ='Week 2 (MASTER SHEET)'!B28 -> #REF! | C28: ='Week 2 (MASTER SHEET)'!C28 -> #REF! | D28: ='Week 2 (MASTER SHEET)'!D28 -> #REF! | E28: ='Week 2 (MASTER SHEET)'!E28 -> #REF! | F28: 2 | H28: ='Week 2 (MASTER SHEET)'!H28 -> #REF! | I28: ='Week 2 (MASTER SHEET)'!I28 -> #REF! | J28: ='Week 2 (MASTER SHEET)'!J28 -> #REF! | K28: ='Week 2 (MASTER SHEET)'!K28 -> #REF! | L28: ='Week 2 (MASTER SHEET)'!L28 -> #REF!
A29: ='Week 2 (MASTER SHEET)'!A29 -> #REF! | H29: ='Week 2 (MASTER SHEET)'!H29 -> #REF!
A30: ='Week 2 (MASTER SHEET)'!A30 -> #REF! | B30: ='Week 2 (MASTER SHEET)'!B30 -> #REF! | C30: ='Week 2 (MASTER SHEET)'!C30 -> #REF! | D30: ='Week 2 (MASTER SHEET)'!D30 -> #REF! | E30: ='Week 2 (MASTER SHEET)'!E30 -> #REF! | H30: ='Week 2 (MASTER SHEET)'!H30 -> #REF! | I30: ='Week 2 (MASTER SHEET)'!I30 -> #REF! | J30: ='Week 2 (MASTER SHEET)'!J30 -> #REF! | K30: ='Week 2 (MASTER SHEET)'!K30 -> #REF! | L30: ='Week 2 (MASTER SHEET)'!L30 -> #REF!
A31: ='Week 2 (MASTER SHEET)'!A31 -> #REF! | B31: ='Week 2 (MASTER SHEET)'!B31 -> #REF! | C31: ='Week 2 (MASTER SHEET)'!C31 -> #REF! | D31: ='Week 2 (MASTER SHEET)'!D31 -> #REF! | E31: ='Week 2 (MASTER SHEET)'!E31 -> #REF! | H31: ='Week 2 (MASTER SHEET)'!H31 -> #REF! | I31: ='Week 2 (MASTER SHEET)'!I31 -> #REF! | J31: ='Week 2 (MASTER SHEET)'!J31 -> #REF! | K31: ='Week 2 (MASTER SHEET)'!K31 -> #REF!
A32: ='Week 2 (MASTER SHEET)'!A32 -> #REF! | B32: ='Week 2 (MASTER SHEET)'!B32 -> #REF! | C32: ='Week 2 (MASTER SHEET)'!C32 -> #REF! | D32: ='Week 2 (MASTER SHEET)'!D32 -> #REF! | E32: ='Week 2 (MASTER SHEET)'!E32 -> #REF! | H32: ='Week 2 (MASTER SHEET)'!H32 -> #REF! | I32: ='Week 2 (MASTER SHEET)'!I32 -> #REF! | J32: ='Week 2 (MASTER SHEET)'!J32 -> #REF! | K32: ='Week 2 (MASTER SHEET)'!K32 -> #REF!
A33: ='Week 2 (MASTER SHEET)'!A33 -> #REF! | B33: ='Week 2 (MASTER SHEET)'!B33 -> #REF! | C33: ='Week 2 (MASTER SHEET)'!C33 -> #REF! | D33: ='Week 2 (MASTER SHEET)'!D33 -> #REF! | E33: ='Week 2 (MASTER SHEET)'!E33 -> #REF! | H33: ='Week 2 (MASTER SHEET)'!H33 -> #REF! | I33: ='Week 2 (MASTER SHEET)'!I33 -> #REF! | J33: ='Week 2 (MASTER SHEET)'!J33 -> #REF! | K33: ='Week 2 (MASTER SHEET)'!K33 -> #REF!
A34: ='Week 2 (MASTER SHEET)'!A34 -> #REF! | B34: ='Week 2 (MASTER SHEET)'!B34 -> #REF! | H34: ='Week 2 (MASTER SHEET)'!H34 -> #REF! | I34: ='Week 2 (MASTER SHEET)'!I34 -> #REF!
A37: ='Week 2 (MASTER SHEET)'!A37 -> #REF! | G37: ALTERNATE | H37: ='Week 2 (MASTER SHEET)'!H37 -> #REF!
A38: ='Week 2 (MASTER SHEET)'!A38 -> #REF! | B38: ='Week 2 (MASTER SHEET)'!B38 -> #REF! | H38: ='Week 2 (MASTER SHEET)'!H38 -> #REF! | I38: ='Week 2 (MASTER SHEET)'!I38 -> #REF!
A39: ='Week 2 (MASTER SHEET)'!A39 -> #REF! | B39: ='Week 2 (MASTER SHEET)'!B39 -> #REF! | C39: ='Week 2 (MASTER SHEET)'!C39 -> #REF! | D39: ='Week 2 (MASTER SHEET)'!D39 -> #REF! | E39: ='Week 2 (MASTER SHEET)'!E39 -> #REF! | F39: ='Week 2 (MASTER SHEET)'!F39 -> #REF! | H39: ='Week 2 (MASTER SHEET)'!H39 -> #REF! | I39: ='Week 2 (MASTER SHEET)'!I39 -> #REF! | J39: ='Week 2 (MASTER SHEET)'!J39 -> #REF! | K39: ='Week 2 (MASTER SHEET)'!K39 -> #REF! | L39: ='Week 2 (MASTER SHEET)'!L39 -> #REF! | M39: ='Week 2 (MASTER SHEET)'!M39 -> #REF!
A40: ='Week 2 (MASTER SHEET)'!A40 -> #REF! | B40: ='Week 2 (MASTER SHEET)'!B40 -> #REF! | C40: ='Week 2 (MASTER SHEET)'!C40 -> #REF! | D40: ='Week 2 (MASTER SHEET)'!D40 -> #REF! | E40: ='Week 2 (MASTER SHEET)'!E40 -> #REF! | F40: 15 | H40: ='Week 2 (MASTER SHEET)'!H40 -> #REF! | I40: ='Week 2 (MASTER SHEET)'!I40 -> #REF! | J40: ='Week 2 (MASTER SHEET)'!J40 -> #REF! | K40: ='Week 2 (MASTER SHEET)'!K40 -> #REF! | L40: ='Week 2 (MASTER SHEET)'!L40 -> #REF!
A41: ='Week 2 (MASTER SHEET)'!A41 -> #REF! | B41: ='Week 2 (MASTER SHEET)'!B41 -> #REF! | C41: ='Week 2 (MASTER SHEET)'!C41 -> #REF! | D41: ='Week 2 (MASTER SHEET)'!D41 -> #REF! | E41: ='Week 2 (MASTER SHEET)'!E41 -> #REF! | F41: 15 | H41: ='Week 2 (MASTER SHEET)'!H41 -> #REF! | I41: ='Week 2 (MASTER SHEET)'!I41 -> #REF! | J41: ='Week 2 (MASTER SHEET)'!J41 -> #REF! | K41: ='Week 2 (MASTER SHEET)'!K41 -> #REF! | L41: ='Week 2 (MASTER SHEET)'!L41 -> #REF!
A44: ='Week 2 (MASTER SHEET)'!A44 -> #REF!
A45: ='Week 2 (MASTER SHEET)'!A45 -> #REF! | B45: ='Week 2 (MASTER SHEET)'!B45 -> #REF!
A46: ='Week 2 (MASTER SHEET)'!A46 -> #REF! | B46: ='Week 2 (MASTER SHEET)'!B46 -> #REF! | C46: ='Week 2 (MASTER SHEET)'!C46 -> #REF! | D46: ='Week 2 (MASTER SHEET)'!D46 -> #REF! | E46: ='Week 2 (MASTER SHEET)'!E46 -> #REF! | F46: ='Week 2 (MASTER SHEET)'!F46 -> #REF!
A47: ='Week 2 (MASTER SHEET)'!A47 -> #REF! | B47: ='Week 2 (MASTER SHEET)'!B47 -> #REF! | C47: ='Week 2 (MASTER SHEET)'!C47 -> #REF! | D47: ='Week 2 (MASTER SHEET)'!D47 -> #REF! | E47: ='Week 2 (MASTER SHEET)'!E47 -> #REF!
A48: ='Week 2 (MASTER SHEET)'!A48 -> #REF! | B48: ='Week 2 (MASTER SHEET)'!B48 -> #REF! | C48: ='Week 2 (MASTER SHEET)'!C48 -> #REF! | D48: ='Week 2 (MASTER SHEET)'!D48 -> #REF! | E48: ='Week 2 (MASTER SHEET)'!E48 -> #REF!
A49: ='Week 2 (MASTER SHEET)'!A49 -> #REF! | B49: ='Week 2 (MASTER SHEET)'!B49 -> #REF! | C49: ='Week 2 (MASTER SHEET)'!C49 -> #REF! | D49: ='Week 2 (MASTER SHEET)'!D49 -> #REF! | E49: ='Week 2 (MASTER SHEET)'!E49 -> #REF!
A50: ='Week 2 (MASTER SHEET)'!A50 -> #REF! | B50: ='Week 2 (MASTER SHEET)'!B50 -> #REF! | C50: ='Week 2 (MASTER SHEET)'!C50 -> #REF! | D50: ='Week 2 (MASTER SHEET)'!D50 -> #REF!
A51: ='Week 2 (MASTER SHEET)'!A51 -> #REF!
A52: ='Week 2 (MASTER SHEET)'!A52 -> #REF! | B52: ='Week 2 (MASTER SHEET)'!B52 -> #REF! | C52: ='Week 2 (MASTER SHEET)'!C52 -> #REF! | D52: ='Week 2 (MASTER SHEET)'!D52 -> #REF!
A53: ='Week 2 (MASTER SHEET)'!A53 -> #REF! | B53: ='Week 2 (MASTER SHEET)'!B53 -> #REF! | C53: ='Week 2 (MASTER SHEET)'!C53 -> #REF! | D53: ='Week 2 (MASTER SHEET)'!D53 -> #REF! | E53: ='Week 2 (MASTER SHEET)'!E53 -> #REF!
A54: ='Week 2 (MASTER SHEET)'!A54 -> #REF!
A55: ='Week 2 (MASTER SHEET)'!A55 -> #REF! | B55: ='Week 2 (MASTER SHEET)'!B55 -> #REF! | C55: ='Week 2 (MASTER SHEET)'!C55 -> #REF! | D55: ='Week 2 (MASTER SHEET)'!D55 -> #REF! | E55: ='Week 2 (MASTER SHEET)'!E55 -> #REF!
...

Sheet Copy of Week 2 (MASTER SHEET)
A9: Week 2
A10: ='Week 1 MASTER SHEET'!A10 -> #REF!
A12: This Weeks Goals
A13: This week we are going to continue to attemp new maxes in some areas as well as go for max repititions in others. Be sure to push your hardest and keep good form.
A16: DAY 1 | H16: ALTERNATE WORKOUTS
A19: CHEST & BACK | H19: CHEST & BACK
A20: =HYPERLINK("https://youtu.be/ujVN-A0Z-ic","1. DUMBBELL INCLINE PRESS") -> 1. DUMBBELL INCLINE PRESS | H20: =HYPERLINK("https://youtu.be/75e_H9Vq_Lw","1. MACHINE PRESS") -> 1. MACHINE PRESS
A21: CURRENT MAX | B21: 20 | H21: CURRENT MAX | I21: ='WEEK 1 '!I32 -> #REF!
A22: SET | B22: WEIGHT | C22: REPS | D22: REST | E22: PREVIOUS | F22: REP LOG | H22: SET | I22: WEIGHT | J22: REPS | K22: REST | L22: PREVIOUS | M22: REP LOG
A23: 1 | B23: =mround('WEEK 2'!B21*0.35,5) -> #REF! | C23: 6 | D23: 1 MIN | E23: =IF('WEEK 1 '!P22='WEEK 2'!B23,'WEEK 1 '!T22,"") -> #REF! | H23: 1 | I23: =mround('WEEK 2'!I21*0.35,5) -> #REF! | J23: 6 | K23: 1 MIN | L23: =IF('WEEK 1 '!I22='WEEK 2'!I23,'WEEK 1 '!M22,"") -> #REF!
A24: 2 | B24: =mround('WEEK 2'!B21*0.65,5) -> #REF! | C24: 1 | D24: 1 MIN | E24: =IF('WEEK 1 '!P23='WEEK 2'!B24,'WEEK 1 '!T23,"") -> #REF! | H24: 2 | I24: =mround('WEEK 2'!I21*0.65,5) -> #REF! | J24: 1 | K24: 1 MIN | L24: =IF('WEEK 1 '!I23='WEEK 2'!I24,'WEEK 1 '!M23,"") -> #REF!
A25: 3 | B25: =mround('WEEK 2'!B21*0.85,5) -> #REF! | C25: 1 | D25: 1 MIN | E25: =IF('WEEK 1 '!P24='WEEK 2'!B25,'WEEK 1 '!T24,"") -> #REF! | H25: 3 | I25: =mround('WEEK 2'!I21*0.85,5) -> #REF! | J25: 1 | K25: 1 MIN | L25: =IF('WEEK 1 '!I24='WEEK 2'!I25,'WEEK 1 '!M24,"") -> #REF!
