Workbook

Sheet Weight Log
A1: Timestamp | B1: TIME | C1: Weight

Sheet NVScriptsProperties
A1: autocratn | B1: autocratp
A2: dataSheetName | B2: "Sheet74"
A3: v | B3: "5.1"
A4: dataSheetId | B4: "1.93398831E8"
A5: updateTime | B5: "1.754241016814E12"
A6: vp | B6: "5.1"
A7: ssId | B7: "1p7n7VGnhBnHBgXaegcBc4PNjDHs8ya7wb5iAtHQE3QU"

Sheet WORK ANALYTICS
B1: =IF(B2>0,"MAX WEEK",IF(B3>0,"MAX WEEK",if(B4>0,"MAX WEEK",""))) -> MAX WEEK | C1: =IF(C2>0,"WEEK 1",IF(C3>0,"WEEK 1",if(C4>0,"WEEK 1",""))) -> WEEK 1 | D1: =IF(D2>0,"WEEK 2",IF(D3>0,"WEEK 2",if(D4>0,"WEEK 2",""))) -> WEEK 2 | E1: =IF(E2>0,"WEEK 4",IF(E3>0,"WEEK 4",if(E4>0,"WEEK 4",""))) -> WEEK 4 | F1: =IF(F2>0,"WEEK 5",IF(F3>0,"WEEK 5",if(F4>0,"WEEK 5",""))) | G1: =IF(G2>0,"WEEK 6",IF(G3>0,"WEEK 6",if(G4>0,"WEEK 6",""))) | H1: =IF(H2>0,"WEEK 7",IF(H3>0,"WEEK 7",if(H4>0,"WEEK 7",""))) | I1: =IF(I2>0,"WEEK 8",IF(I3>0,"WEEK 8",if(I4>0,"WEEK 8",""))) | J1: =IF(J2>0,"WEEK 9",IF(J3>0,"WEEK 9",if(J4>0,"WEEK 9",""))) | K1: =IF(K2>0,"WEEK 10",IF(K3>0,"WEEK 10",if(K4>0,"WEEK 10",""))) | L1: =IF(L2>0,"WEEK 11",IF(L3>0,"WEEK 11",if(L4>0,"WEEK 11",""))) | M1: =IF(M2>0,"WEEK 12",IF(M3>0,"WEEK 12",if(M4>0,"WEEK 12",""))) | N1: =IF(N2>0,"WEEK 12","") | O1: =IF(O2>0,"WEEK 13","") | P1: =IF(P2>0,"WEEK 14","") | Q1: =IF(Q2>0,"WEEK 15","") | R1: =IF(R2>0,"WEEK 16","") | S1: =IF(S2>0,"WEEK 17","") | T1: =IF(T2>0,"WEEK 18","") | U1: =IF(U2>0,"WEEK 19","") | V1: =IF(V2>0,"WEEK 20","") | W1: =IF(W2>0,"WEEK 21","") | X1: =IF(X2>0,"WEEK 22","") | Y1: =IF(Y2>0,"WEEK 23","") | Z1: =IF(Z2>0,"WEEK 24","") | AA1: =IF(AA2>0,"WEEK 25","") | AB1: =IF(AB2>0,"WEEK 26","") | AC1: =IF(AC2>0,"WEEK 27","") | AD1: =IF(AD2>0,"WEEK 28","") | AE1: =IF(AE2>0,"WEEK 29","") | AF1: =IF(AF2>0,"WEEK 30","") | AG1: =IF(AG2>0,"WEEK 31","") | AH1: =IF(AH2>0,"WEEK 32","") | AI1: =IF(AI2>0,"WEEK 33","") | AJ1: =IF(AJ2>0,"WEEK 34","") | AK1: =IF(AK2>0,"WEEK 35","") | AL1: =IF(AL2>0,"WEEK 36","") | AM1: =IF(AM2>0,"WEEK 37","") | AN1: =IF(AN2>0,"WEEK 38","") | AO1: =IF(AO2>0,"WEEK 39","") | AP1: =IF(AP2>0,"WEEK 40","") | AQ1: =IF(AQ2>0,"WEEK 41","") | AR1: =IF(AR2>0,"WEEK 42","") | AS1: =IF(AS2>0,"WEEK 43","") | AT1: =IF(AT2>0,"WEEK 44","") | AU1: =IF(AU2>0,"WEEK 45","") | AV1: =IF(AV2>0,"WEEK 46","") | AW1: =IF(AW2>0,"WEEK 47","") | AX1: =IF(AX2>0,"WEEK 48","") | AY1: =IF(AY2>0,"WEEK 49","") | AZ1: =IF(AZ2>0,"WEEK 50","") | BA1: =IF(BA2>0,"WEEK 51","") | BB1: =IF(BB2>0,"WEEK 52","")
A2: DB INCLINE PRESS | B2: ='WEEK 1 '!P20 -> 75 | C2: ='WEEK 1 '!P30 -> 55 | D2: ='WEEK 2'!B31 -> 55 | E2: ='WEEK 4 Master Sheet '!P31 -> 75
A3: Machine Press | B3: ='WEEK 1 '!I20 | C3: ='WEEK 1 '!I31 | D3: ='WEEK 2'!I31 | E3: ='WEEK 4 Master Sheet '!I31
A4: Bench Press | B4: ='WEEK 1 '!B20 -> 100 | C4: ='WEEK 1 '!B31 -> 185 | E4: ='WEEK 4 Master Sheet '!B31 -> 80
B10: =IF(B11>0,"MAX WEEK",IF(B12>0,"MAX WEEK",if(B13>0,"MAX WEEK",""))) -> MAX WEEK | C10: =IF(C11>0,"WEEK 1",IF(C12>0,"WEEK 1",if(C13>0,"WEEK 1",""))) -> WEEK 1 | D10: =IF(D11>0,"WEEK 2",IF(D12>0,"WEEK 2",if(D13>0,"WEEK 2",""))) | E10: =IF(E11>0,"WEEK 3",IF(E12>0,"WEEK 3",if(E13>0,"WEEK 3",""))) -> WEEK 3 | F10: =IF(F11>0,"WEEK 5",IF(F12>0,"WEEK 5",if(F13>0,"WEEK 5",""))) | G10: =IF(G11>0,"WEEK 6",IF(G12>0,"WEEK 6",if(G13>0,"WEEK 6",""))) | H10: =IF(H11>0,"WEEK 7",IF(H12>0,"WEEK 7",if(H13>0,"WEEK 7",""))) | I10: =IF(J11>0,"WEEK 9",IF(J12>0,"WEEK 9",if(J13>0,"WEEK 9",""))) | J10: =IF(K11>0,"WEEK 10",IF(K12>0,"WEEK 10",if(K13>0,"WEEK 10",""))) | K10: =IF(M11>0,"WEEK 11",IF(M12>0,"WEEK 11",if(M13>0,"WEEK 11","")))
A11: LAT PULL DOWN | B11: ='WEEK 1 '!B42 -> 255 | C11: ='WEEK 1 '!B54 -> 260
A12: HIGH ROW | B12: ='WEEK 1 '!B66 -> 60 | C12: ='WEEK 1 '!B66 -> 60 | E12: ='WEEK 3 '!B50 -> 55
A13: LOW ROW | B13: ='WEEK 1 '!B58 -> 205 | D13: ='WEEK 2'!B56 -> 0
B20: =IF(B21>0,"MAX WEEK",IF(B22>0,"MAX WEEK",if(B23>0,"MAX WEEK",""))) -> MAX WEEK | C20: =IF(C21>0,"WEEK 1",IF(C22>0,"WEEK 1",if(C23>0,"WEEK 1",""))) -> WEEK 1 | D20: =IF(D21>0,"WEEK 2",IF(D22>0,"WEEK 2",if(D23>0,"WEEK 2",""))) -> WEEK 2 | E20: =IF(E21>0,"WEEK 3",IF(E22>0,"WEEK 3",if(E23>0,"WEEK 3",""))) | F20: =IF(F21>0,"WEEK 5",IF(F22>0,"WEEK 5",if(F23>0,"WEEK 5",""))) | G20: =IF(G21>0,"WEEK 6",IF(G22>0,"WEEK 6",if(G23>0,"WEEK 6",""))) | H20: =IF(H21>0,"WEEK 7",IF(H22>0,"WEEK 7",if(H23>0,"WEEK 7",""))) | I20: =IF(I21>0,"WEEK 8",IF(I22>0,"WEEK 8",if(I23>0,"WEEK 8",""))) | J20: =IF(J21>0,"WEEK 9",IF(J22>0,"WEEK 9",if(J23>0,"WEEK 9",""))) | K20: =IF(K21>0,"WEEK 10",IF(K22>0,"WEEK 10",if(K23>0,"WEEK 10",""))) | L20: =IF(L21>0,"WEEK 11",IF(L22>0,"WEEK 11",if(L23>0,"WEEK 11",""))) | M20: =IF(M21>0,"WEEK 12",IF(M22>0,"WEEK 12",if(M23>0,"WEEK 12","")))
A21: LEG PRESS | B21: ='WEEK 2'!B87 -> 240 | C21: 10 | D21: 14
A22: MACHINE SQUAT | B22: ='WEEK 3 '!B86 | E22: ='WEEK 3 '!B86
A23: BAR SQUAT
B30: =IF(B31>0,"MAX WEEK",IF(B32>0,"MAX WEEK",if(B33>0,"MAX WEEK",""))) -> MAX WEEK | C30: =IF(C31>0,"WEEK 1",IF(C32>0,"WEEK 1",if(C33>0,"WEEK 1",""))) -> WEEK 1 | D30: =IF(D31>0,"WEEK 2",IF(D32>0,"WEEK 2",if(D33>0,"WEEK 2",""))) -> WEEK 2 | E30: =IF(E31>0,"WEEK 4",IF(E32>0,"WEEK 4",if(E33>0,"WEEK 4",""))) -> WEEK 4 | F30: =IF(F31>0,"WEEK 5",IF(F32>0,"WEEK 5",if(F33>0,"WEEK 5",""))) | G30: =IF(G31>0,"WEEK 6",IF(G32>0,"WEEK 6",if(G33>0,"WEEK 6",""))) | H30: =IF(H31>0,"WEEK 7",IF(H32>0,"WEEK 7",if(H33>0,"WEEK 7",""))) | I30: =IF(I31>0,"WEEK 8",IF(I32>0,"WEEK 8",if(I33>0,"WEEK 8",""))) | J30: =IF(J31>0,"WEEK 9",IF(J32>0,"WEEK 9",if(J33>0,"WEEK 9",""))) | K30: =IF(K31>0,"WEEK 10",IF(K32>0,"WEEK 10",if(K33>0,"WEEK 10",""))) | L30: =IF(L31>0,"WEEK 11",IF(L32>0,"WEEK 11",if(L33>0,"WEEK 11",""))) | M30: =IF(M31>0,"WEEK 12",IF(M32>0,"WEEK 12",if(M33>0,"WEEK 12","")))
A31: DB SHOULDER PRESS | B31: ='WEEK 1 '!B114 -> 70 | C31: 10 | D31: 14
A32: MACHINE SHOULDER PRESS | C32: 5 | D32: 8 | E32: 13
B35: =IF(B36>0,"MAX WEEK",IF(B37>0,"MAX WEEK",if(B38>0,"MAX WEEK",""))) -> MAX WEEK | C35: =IF(C36>0,"WEEK 1",IF(C37>0,"WEEK 1",if(C38>0,"WEEK 1",""))) | D35: =IF(D36>0,"WEEK 2",IF(D37>0,"WEEK 2",if(D38>0,"WEEK 2",""))) | E35: =IF(E36>0,"WEEK 4",IF(E37>0,"WEEK 4",if(E38>0,"WEEK 4",""))) -> #REF! | F35: =IF(F36>0,"WEEK 5",IF(F37>0,"WEEK 5",if(F38>0,"WEEK 5",""))) | G35: =IF(G36>0,"WEEK 6",IF(G37>0,"WEEK 6",if(G38>0,"WEEK 6",""))) | H35: =IF(H36>0,"WEEK 7",IF(H37>0,"WEEK 7",if(H38>0,"WEEK 7",""))) | I35: =IF(I36>0,"WEEK 8",IF(I37>0,"WEEK 8",if(I38>0,"WEEK 8",""))) | J35: =IF(J36>0,"WEEK 9",IF(J37>0,"WEEK 9",if(J38>0,"WEEK 9",""))) | K35: =IF(K36>0,"WEEK 10",IF(K37>0,"WEEK 10",if(K38>0,"WEEK 10",""))) | L35: =IF(L36>0,"WEEK 11",IF(L37>0,"WEEK 11",if(L38>0,"WEEK 11",""))) | M35: =IF(M36>0,"WEEK 12",IF(M37>0,"WEEK 12",if(M38>0,"WEEK 12","")))
A36: ALTERNATING CURLS | B36: ='DETERMINING MAX WEEK'!E193 -> 40 | E36: =#REF! -> #REF!
A37: BAR CURLS | D37: ='WEEK 2'!I153
A38: MACHINE CURLS | C38: ='WEEK 1 '!B166 | D38: ='WEEK 2'!B158
B42: =IF(B43>0,"MAX WEEK",IF(B44>0,"MAX WEEK",if(B45>0,"MAX WEEK",""))) -> MAX WEEK | C42: =IF(C43>0,"WEEK 1",IF(C44>0,"WEEK 1",if(C45>0,"WEEK 1",""))) -> #REF! | D42: =IF(D43>0,"WEEK 2",IF(D44>0,"WEEK 2",if(D45>0,"WEEK 2",""))) | E42: =IF(E43>0,"WEEK 3",IF(E44>0,"WEEK 3",if(E45>0,"WEEK 3",""))) -> #REF! | F42: =IF(F43>0,"WEEK 5",IF(F44>0,"WEEK 5",if(F45>0,"WEEK 5",""))) | G42: =IF(G43>0,"WEEK 6",IF(G44>0,"WEEK 6",if(G45>0,"WEEK 6",""))) | H42: =IF(H43>0,"WEEK 7",IF(H44>0,"WEEK 7",if(H45>0,"WEEK 7",""))) | I42: =IF(I43>0,"WEEK 8",IF(I44>0,"WEEK 8",if(I45>0,"WEEK 8",""))) | J42: =IF(J43>0,"WEEK 9",IF(J44>0,"WEEK 9",if(J45>0,"WEEK 9",""))) | K42: =IF(K43>0,"WEEK 10",IF(K44>0,"WEEK 10",if(K45>0,"WEEK 10",""))) | L42: =IF(L43>0,"WEEK 11",IF(L44>0,"WEEK 11",if(L45>0,"WEEK 11",""))) | M42: =IF(M43>0,"WEEK 12",IF(M44>0,"WEEK 12",if(M45>0,"WEEK 12","")))
A43: MACHINE PRESS | B43: ='WEEK 1 '!B145 -> 100 | C43: =#REF! -> #REF!
A44: OVERHEAD EXTENSION | E44: =#REF! -> #REF!

Sheet Sheet74

Sheet Pre Workout 1
A9: PRE WORKOUT 1
A10: =HYPERLINK("https://goo.gl/forms/3ibooB993Hi7SS2d2","PRESS TO RECORD BODY WEIGHT") -> PRESS TO RECORD BODY WEIGHT
A12: Laying the Foundation
A13: This week we are going to get your body used to being in the gym. It is imperative that you keep the weight VERY light. No need to push yourself hard at all. Let's warm your body into the process of lifting again and pay close attention to how you recover.
A15: QUICK TIPS
A16: IF IT'S GREEN=NEEDS YOUR INPUT
A17: Click The Title of The workout to see an Instructional Video
A18: REMEMBER TO ROUND OUR SUGGESTED WEIGHTS TO YOUR GYM'S CLOSEST AVAILABLE WEIGHTS.
A21: BEGIN WORKOUT
A23: INSERT BODY WEIGHT | C23: 100
A25: Beginner | D25: Moderate
A26: (Over 1 month since I've worked out) | D26: Less than a month since weight training
A27: x
A29: DAY 1
A32: CHEST & BACK
A33: =HYPERLINK("https://youtu.be/ujVN-A0Z-ic","1. DUMBBELL INCLINE PRESS") -> 1. DUMBBELL INCLINE PRESS
A34: SUGGESTED WEIGHT | B34: =IF((AND(A27="",C23>=170)),25,IF((AND(A27="",C23<170)),20,IF((AND(D27="",C23>170)),15,12.5))) -> 12.5
A35: SET | B35: WEIGHT | C35: REPS | D35: REST | E35: PREVIOUS | F35: REP LOG
A36: 1 | B36: =B34 -> 12.5 | C36: 10 - 12 | D36: 1 MIN | F36: 10
A37: 2 | B37: =IF(F36<10,MROUND(B36*0.85,2.5),B36) -> 12.5 | C37: 10 - 12 | D37: 1 MIN | F37: 10
A38: 3 | B38: =IF(F37<10,MROUND(B37*0.8,2.5),B37) -> 12.5 | C38: 10 - 12 | D38: 1 MIN | F38: 10
A41: =HYPERLINK("https://www.youtube.com/watch?v=PnaDzYh2axA","2. LAT PULL DOWN") -> 2. LAT PULL DOWN
A42: SUGGESTED WEIGHT | B42: =IF((AND(A27="",C23>=170)),35,IF((AND(A27="",C23<170)),20,IF((AND(D27="",C23>170)),30,25))) -> 25
A43: SET | B43: WEIGHT | C43: REPS | D43: REST | E43: PREVIOUS | F43: REP LOG
A44: 1 | B44: =B42 -> 25 | C44: 10 - 12 | D44: 1 MIN | F44: 12
A45: 2 | B45: =IF(F44<10,MROUND(B44*0.8,5),B44) -> 25 | C45: 10 - 12 | D45: 1 MIN | F45: 12
A46: 3 | B46: =IF(F45<10,MROUND(B45*0.8,5),B45) -> 25 | C46: 10 - 12 | D46: 1 MIN | F46: 12
A49: =HYPERLINK("https://www.youtube.com/watch?v=Yke__29qVfo","3. TRICEPS PUSHDOWN (STRAIGHT BAR)") -> 3. TRICEPS PUSHDOWN (STRAIGHT BAR)
A50: SUGGESTED WEIGHT | B50: =IF((AND(A27="",C23>=170)),15,IF((AND(A27="",C23<170)),10,IF((AND(D27="",C23>170)),12.5,10))) -> 10
A51: SET | B51: WEIGHT | C51: REPS | D51: REST | E51: PREVIOUS | F51: REP LOG
A52: 1 | B52: =B50 -> 10 | C52: 10 - 12 | D52: 1 MIN | F52: 5
A53: 2 | B53: =IF(F52<10,MROUND(B52*0.8,2.5),B52) -> 7.5 | C53: 10 - 12 | D53: 1 MIN | F53: 12
A54: 3 | B54: =IF(F53<10,MROUND(B53*0.8,2.5),B53) -> 7.5 | C54: 10 - 12 | D54: 1 MIN
A57: =HYPERLINK("https://www.youtube.com/watch?v=9IqvmIhFxtY","4. BICEP CABLE CURL") -> 4. BICEP CABLE CURL
A58: SUGGESTED WEIGHT | B58: =IF((AND(A27="",C23>=170)),20,IF((AND(A27="",C23<170)),15,IF((AND(D27="",C23>170)),12.5,10))) -> 10
A59: SET | B59: WEIGHT | C59: REPS | D59: REST | E59: PREVIOUS | F59: REP LOG
A60: 1 | B60: =B58 -> 10 | C60: 10 - 12 | D60: 1MIN | E60: =IF('WEEK 1 '!B54=B60,'WEEK 1 '!F54,"") | F60: 10
A61: 2 | B61: =IF(F60<10,MROUND(B60*0.85,5),B60) -> 10 | C61: 10 - 12 | D61: 1MIN | E61: =IF('WEEK 1 '!B55=B61,'WEEK 1 '!F55,"") | F61: 10
A62: 3 | B62: =IF(F61<10,MROUND(B61*0.85,5),B61) -> 10 | C62: 10 - 12 | D62: 1MIN | E62: =IF('WEEK 1 '!B56=B62,'WEEK 1 '!F56,"") | F62: 10
A65: DAY 2
...

Sheet Pre Workout 2
A9: PRE WORKOUT 2
A10: =HYPERLINK("https://goo.gl/forms/3ibooB993Hi7SS2d2","PRESS TO RECORD BODY WEIGHT") -> PRESS TO RECORD BODY WEIGHT
A12: This Weeks Goals
A13: This week we are going to continue to get your body used to being back in the gym. There should be still be little to no strain since we are adding weight but we still want to keep it light. We'll be introducing a few new excersizes during this week as well. Push yourself, but not too hard.
A15: QUICK TIPS
A16: IF IT'S GREEN=NEEDS YOUR INPUT
A17: Click The Title of The workout to see an Instructional Video
A18: REMEMBER TO ROUND OUR SUGGESTED WEIGHTS TO YOUR GYM'S CLOSEST AVAILABLE WEIGHTS.
A21: BEGIN WORKOUT
A23: DAY 1
A26: CHEST & BACK
A27: =HYPERLINK("https://youtu.be/ujVN-A0Z-ic","1. DUMBBELL INCLINE PRESS") -> 1. DUMBBELL INCLINE PRESS
A28: SUGGESTED WEIGHT | B28: =IF('Pre Workout 1'!B142='Pre Workout 1'!B144,'Pre Workout 1'!B142+2.5,IF('Pre Workout 1'!F142<=9,MROUND('Pre Workout 1'!B142*0.95,5),MROUND('Pre Workout 1'!B142*0.85,2.5))) -> 20
A29: SET | B29: WEIGHT | C29: REPS | D29: REST | E29: PREVIOUS | F29: REP LOG
A30: 1 | B30: =B28 -> 20 | C30: 10 - 15 | D30: 1 MIN
A31: 2 | B31: =IF(F30<10,MROUND(B30*0.85,2.5),B30) -> 17.5 | C31: 10 - 15 | D31: 1 MIN
A32: 3 | B32: =IF(F31<10,MROUND(B31*0.8,2.5),B31) -> 15 | C32: 10 - 15 | D32: 1 MIN
A35: =HYPERLINK("https://www.youtube.com/watch?v=PnaDzYh2axA","2. LAT PULL DOWN") -> 2. LAT PULL DOWN
A36: SUGGESTED WEIGHT | B36: =IF('Pre Workout 1'!B150='Pre Workout 1'!B152,'Pre Workout 1'!B150+15,IF('Pre Workout 1'!F150<=9,MROUND('Pre Workout 1'!B150*0.95,5),MROUND('Pre Workout 1'!B150*0.85,2.5))) -> 60
A37: SET | B37: WEIGHT | C37: REPS | D37: REST | E37: PREVIOUS | F37: REP LOG
A38: 1 | B38: =B36 -> 60 | C38: 10 - 15 | D38: 1 MIN
A39: 2 | B39: =IF(F38<10,MROUND(B38*0.8,5),B38) -> 50 | C39: 10 - 15 | D39: 1 MIN
A40: 3 | B40: =IF(F39<10,MROUND(B39*0.8,5),B39) -> 40 | C40: 10 - 15 | D40: 1 MIN
A43: =HYPERLINK("https://www.youtube.com/watch?v=9YH1YvZbiY0","3. MACHINE LOW ROW") -> 3. MACHINE LOW ROW
A44: SUGGESTED WEIGHT | B44: =IF((AND(A27="",C23>=145)),40,IF((AND(A27="",C23<145)),35,IF((AND(D27="",C23>145)),35,30))) -> 30
A45: SET | B45: WEIGHT | C45: REPS | D45: REST | E45: PREVIOUS | F45: REP LOG
A46: 1 | B46: =B44 -> 30 | C46: 10 - 15 | D46: 1 MIN
A47: 2 | B47: =IF(F46<10,MROUND(B46*0.8,5),B46) -> 25 | C47: 10 - 15 | D47: 1 MIN
A48: 3 | B48: =IF(F47<10,MROUND(B47*0.8,5),B47) -> 20 | C48: 10 - 15 | D48: 1 MIN
A51: =HYPERLINK("https://www.youtube.com/watch?v=Yke__29qVfo","4. TRICEPS PUSHDOWN (STRAIGHT BAR)") -> 4. TRICEPS PUSHDOWN (STRAIGHT BAR)
A52: SUGGESTED WEIGHT | B52: ='Pre Workout 1'!B86 -> 7.5
A53: SET | B53: WEIGHT | C53: REPS | D53: REST | E53: PREVIOUS | F53: REP LOG
A54: 1 | B54: =B52 -> 7.5 | C54: 10 - 12 | D54: 1 MIN
A55: 2 | B55: =IF(F54<10,MROUND(B54*0.8,2.5),B54) -> 5 | C55: 10 - 12 | D55: 1 MIN
A56: 3 | B56: =IF(F55<10,MROUND(B55*0.8,2.5),B55) -> 5 | C56: 10 - 12 | D56: 1 MIN
A59: =HYPERLINK("https://www.youtube.com/watch?v=9IqvmIhFxtY","5. BICEP CABLE CURL") -> 5. BICEP CABLE CURL
A60: SUGGESTED WEIGHT | B60: =IF('Pre Workout 1'!B96='Pre Workout 1'!B98,'Pre Workout 1'!B96+5,IF('Pre Workout 1'!F96<=9,MROUND('Pre Workout 1'!B96*0.95,5),MROUND('Pre Workout 1'!B96*0.85,2.5))) -> 20
A61: SET | B61: WEIGHT | C61: REPS | D61: REST | E61: PREVIOUS | F61: REP LOG
A62: 1 | B62: =B60 -> 20 | C62: 10 - 12 | D62: 1MIN | E62: =IF('WEEK 1 '!B54=B62,'WEEK 1 '!F54,"")
A63: 2 | B63: =IF(F62<10,MROUND(B62*0.85,5),B62) -> 15 | C63: 10 - 12 | D63: 1MIN | E63: =IF('WEEK 1 '!B55=B63,'WEEK 1 '!F55,"")
...

Sheet 90 DAY PROGRESS
H17: YOU'VE LOST | I17: =MAX('Weight Log'!C2:C19)-MIN('Weight Log'!C2:C19) -> 0 | J17: LBS
A39: ='WORK ANALYTICS'!A2 -> DB INCLINE PRESS | D39: ='WORK ANALYTICS'!A3 -> Machine Press | G39: ='WORK ANALYTICS'!A4 -> Bench Press
A40: =IF(B40>0,"INCREASE OF",IF(B40=0,"NO PROGRESS","DECREASE OF")) -> INCREASE OF | B40: =MAX('WORK ANALYTICS'!C2:M2)-MIN('WORK ANALYTICS'!C2:M2) -> 20 | C40: LBS | D40: =IF(E40>0,"INCREASE OF",IF(E40=0,"NO PROGRESS","DECREASE OF")) -> NO PROGRESS | E40: =MAX('WORK ANALYTICS'!C3:M3)-MIN('WORK ANALYTICS'!C3:M3) -> 0 | F40: LBS | G40: =IF(H40>0,"INCREASE OF",IF(H40=0,"NO PROGRESS","DECREASE OF")) -> INCREASE OF | H40: =MAX('WORK ANALYTICS'!C4:M4)-MIN('WORK ANALYTICS'!C4:M4) -> 105 | I40: LBS
A61: ='WORK ANALYTICS'!A11 -> LAT PULL DOWN | D61: ='WORK ANALYTICS'!A12 -> HIGH ROW | G61: ='WORK ANALYTICS'!A13 -> LOW ROW
A62: =IF(B62>0,"INCREASE OF",IF(B62=0,"NO PROGRESS","DECREASE OF")) -> INCREASE OF | B62: =MAX('WORK ANALYTICS'!B11:M11)-MIN('WORK ANALYTICS'!B11:M11) -> 5 | C62: LBS | D62: =IF(E62>0,"INCREASE OF",IF(E62=0,"NO PROGRESS","DECREASE OF")) -> NO PROGRESS | E62: =MAX('WORK ANALYTICS'!B12)-MIN('WORK ANALYTICS'!B12) -> 0 | F62: LBS | G62: =IF(H62>0,"INCREASE OF",IF(H62=0,"NO PROGRESS","DECREASE OF")) -> NO PROGRESS | H62: =MAX('WORK ANALYTICS'!B13)-MIN('WORK ANALYTICS'!B13) -> 0 | I62: LBS
A82: LEG PRESS | D82: MACHINE SQUAT | G82: BAR SQUAT
A83: =IF(B83>0,"INCREASE OF",IF(B83=0,"NO PROGRESS","DECREASE OF")) -> INCREASE OF | B83: =MAX('WORK ANALYTICS'!C21:M21)-MIN('WORK ANALYTICS'!C21:M21) -> 4 | C83: LBS | D83: =IF(E83>0,"INCREASE OF",IF(E83=0,"NO PROGRESS","DECREASE OF")) -> NO PROGRESS | E83: =MAX('WORK ANALYTICS'!C22:M22)-MIN('WORK ANALYTICS'!C22:M22) -> 0 | F83: LBS | G83: =IF(H83>0,"INCREASE OF",IF(H83=0,"NO PROGRESS","DECREASE OF")) -> NO PROGRESS | H83: =MAX('WORK ANALYTICS'!C23:M23)-MIN('WORK ANALYTICS'!C23:M23) -> 0 | I83: LBS
B103: ='WORK ANALYTICS'!A31 -> DB SHOULDER PRESS | F103: ='WORK ANALYTICS'!A32 -> MACHINE SHOULDER PRESS
B104: =IF(D104>0,"INCREASE OF",IF(D104=0,"NO PROGRESS","DECREASE OF")) -> INCREASE OF | D104: =MAX('WORK ANALYTICS'!C31:M31)-MIN('WORK ANALYTICS'!C31:M31) -> 4 | E104: LBS | F104: =IF(G104>0,"INCREASE OF",IF(G104=0,"NO PROGRESS","DECREASE OF")) -> INCREASE OF | G104: =MAX('WORK ANALYTICS'!C32:M32)-MIN('WORK ANALYTICS'!C32:M32) -> 8 | H104: LBS
A124: ='WORK ANALYTICS'!A36 -> ALTERNATING CURLS | D124: ='WORK ANALYTICS'!A37 -> BAR CURLS | G124: ='WORK ANALYTICS'!A38 -> MACHINE CURLS
A125: =IF(B125>0,"INCREASE OF",IF(B125=0,"NO PROGRESS","DECREASE OF")) -> #REF! | B125: =MAX('WORK ANALYTICS'!C36:M36)-MIN('WORK ANALYTICS'!C36:M36) -> #REF! | C125: LBS | D125: =IF(E125>0,"INCREASE OF",IF(E125=0,"NO PROGRESS","DECREASE OF")) -> NO PROGRESS | E125: =MAX('WORK ANALYTICS'!C37:M37)-MIN('WORK ANALYTICS'!C37:M37) -> 0 | F125: LBS | G125: =IF(H125>0,"INCREASE OF",IF(H125=0,"NO PROGRESS","DECREASE OF")) -> NO PROGRESS | H125: =MAX('WORK ANALYTICS'!C38:M38)-MIN('WORK ANALYTICS'!C38:M38) -> 0 | I125: LBS
C145: ='WORK ANALYTICS'!A43 -> MACHINE PRESS | F145: ='WORK ANALYTICS'!A44 -> OVERHEAD EXTENSION
C146: =IF(D146>0,"INCREASE OF",IF(D146=0,"NO PROGRESS","DECREASE OF")) -> #REF! | D146: =MAX('WORK ANALYTICS'!C43:M43)-MIN('WORK ANALYTICS'!C43:M43) -> #REF! | E146: LBS | F146: =IF(G146>0,"INCREASE OF",IF(G146=0,"NO PROGRESS","DECREASE OF")) -> #REF! | G146: =MAX('WORK ANALYTICS'!C44:M44)-MIN('WORK ANALYTICS'!C44:M44) -> #REF! | H146: LBS

Sheet DETERMINING MAX WEEK
A8: WEEK 1 | I8: QUICK TIPS
A9: DAY 1 | I9: You only Log What's in GREEN
A10: CHEST & BACK | I10: Click The Title of The workout to see an Instructional Video
A11: This Weeks Goals
A12: swipe right for quick tips
A13: Today is all about setting the proper foundation for your future workouts. All we want to do is establish maximum strenght levels for some target muscle groups. It is important to keep great form as well as being honest in your logging.
A15: READ BEFORE WORKING OUT
A16: All of the workouts are meant to start off with a light weight to establish form and blood flow. If your 2nd set feels very light, you should jump to one of the recommended sets with a weight you feel will be moderate for you. Then from there work the consecutive sets toward your max then log it in the bright green box.
A17: =HYPERLINK("https://www.youtube.com/watch?v=qrv8cCA-WCY","WATCH- HOW TO MAX PROPERLY") -> WATCH- HOW TO MAX PROPERLY
A18: 1. BENCH PRESS | I18: =HYPERLINK("https://www.youtube.com/watch?v=ujVN-A0Z-ic","1. DUMBBELL INCLINE CHEST PRESS") -> 1. DUMBBELL INCLINE CHEST PRESS | O18: 1. MACHINE PRESS
A19: SET | B19: WEIGHT | C19: REPS | D19: REST | E19: REP LOG | I19: SET | J19: WEIGHT | K19: REPS | L19: REST | M19: REP LOG | O19: SET | P19: WEIGHT | Q19: REPS | R19: REST | S19: REP LOG
A20: 1 | B20: 85 | C20: 1 | D20: 2 MIN | I20: 1 | J20: 30 | K20: 4 | L20: 2 MIN | O20: 1 | P20: 85 | Q20: 4 | R20: 2 MIN
A21: 2 | B21: 135 | C21: 1 | D21: 2 MIN | I21: 2 | J21: 40 | K21: 4 | L21: 2 MIN | O21: 2 | P21: 135 | Q21: 4 | R21: 2 MIN
A22: 3 | B22: 155 | C22: 1 | D22: 2 MIN | I22: 3 | J22: 60 | K22: 4 | L22: 2 MIN | O22: 3 | P22: 155 | Q22: 4 | R22: 2 MIN
A23: 4 | B23: 170 | C23: 1 | D23: 2 MIN | I23: 4 | J23: 70 | K23: 4 | L23: 2 MIN | O23: 4 | P23: 170 | Q23: 4 | R23: 2 MIN
A24: 5 | B24: 185 | C24: 1 | D24: 2 MIN | I24: 5 | J24: 80 | K24: 4 | L24: 2 MIN | O24: 5 | P24: 185 | Q24: 4 | R24: 2 MIN
A25: 6 | B25: 205 | C25: 1 | D25: 2 MIN | I25: 6 | J25: 90 | K25: 4 | L25: 2 MIN | O25: 6 | P25: 205 | Q25: 4 | R25: 2 MIN
A26: 7 | B26: 225 | C26: 1 | D26: 2 MIN | I26: 7 | J26: 100 | K26: 4 | L26: 2 MIN | O26: 7 | P26: 225 | Q26: 4 | R26: 2 MIN
A27: 8 | B27: 240 | C27: 1 | D27: 2 MIN | I27: 8 | J27: 110 | K27: 4 | L27: 2 MIN | O27: 8 | P27: 240 | Q27: 4 | R27: 2 MIN
A28: 9 | B28: 260 | C28: 1 | D28: 2 MIN | I28: 9 | J28: 120 | K28: 4 | L28: 2 MIN | O28: 9 | P28: 260 | Q28: 4 | R28: 2 MIN
A29: 10 | B29: 280 | C29: 1 | D29: 2 MIN | I29: 10 | J29: 130 | K29: 4 | L29: 2 MIN | O29: 10 | P29: 280 | Q29: 4 | R29: 2 MIN
A30: 11 | B30: 305 | C30: 1 | D30: 2 MIN | I30: 11 | J30: 140 | K30: 4 | L30: 2 MIN | O30: 11 | P30: 305 | Q30: 4 | R30: 2 MIN
A31: INSERT FINAL MAX | E31: 245 | I31: INSERT FINAL MAX | O31: INSERT FINAL MAX
A33: =HYPERLINK("https://www.youtube.com/watch?v=PnaDzYh2axA","2. Lat Pull Down") -> 2. Lat Pull Down
A35: Set | B35: Weight | C35: Reps | D35: REST | E35: REP LOG
A36: Set1 | B36: 70 | C36: 4 | D36: 2 MIN
A37: Set 2 | B37: 90 | C37: 4 | D37: 2 MIN
A38: Set 3 | B38: 110 | C38: 4 | D38: 2 MIN
A39: Set 4 | B39: 130 | C39: 4 | D39: 2 MIN
A40: Set 5 | B40: 160 | C40: 4 | D40: 2 MIN
A41: Set 6 | B41: 180 | C41: 4 | D41: 2 MIN
A42: Set 7 | B42: 200 | C42: 4 | D42: 2 MIN
A43: Set 8 | B43: 210 | C43: 4 | D43: 2 MIN
A44: Set 9 | B44: 220 | C44: 4 | D44: 2 MIN
A45: Set 10 | B45: 230 | C45: 4 | D45: 2 MIN
A46: Set 11 | B46: 240 | C46: 4 | D46: 2 MIN
A47: INSERT FINAL MAX | E47: 250
A50: =HYPERLINK("https://www.youtube.com/watch?v=9YH1YvZbiY0","3. Machine Low Row") -> 3. Machine Low Row
A51: SET | B51: WEIGHT | C51: REPS | D51: REST | E51: REP LOG
A52: Set1 | B52: 70 | C52: 4 | D52: 2 MIN
...

Sheet Week 1 MASTER SHEET
A9: Week 1 | H9: QUICK TIPS
A10: =HYPERLINK("https://goo.gl/forms/3ibooB993Hi7SS2d2","PRESS TO RECORD BODY WEIGHT") -> PRESS TO RECORD BODY WEIGHT | H10: You only Log What's in GREEN
H11: Click The Title of The workout to see an Instructional Video
A12: This Weeks Goals
A13: This week we are going to jump you into a workout. As the weeks go on we will refine your workout more and it will become more targeted. Give it all you got and push to your limits everytime.
A15: DAY 1 | H15: ALTERNATE WORKOUTS | O15: ALTERNATE WORKOUTS
A18: CHEST & BACK | H18: CHEST & BACK | O18: CHEST & BACK
A19: =HYPERLINK("https://www.youtube.com/watch?v=iLgUDezDMbU","1. BENCH PRESS") -> 1. BENCH PRESS | H19: =HYPERLINK("https://www.youtube.com/watch?v=75e_H9Vq_Lw","1. MACHINE PRESS") -> 1. MACHINE PRESS | O19: =HYPERLINK("https://youtu.be/ujVN-A0Z-ic","1. DUMBBELL INCLINE PRESS") -> 1. DUMBBELL INCLINE PRESS
A20: CURRENT MAX | B20: ='DETERMINING MAX WEEK'!E31 -> 245 | H20: CURRENT MAX | I20: 120 | O20: CURRENT MAX | P20: 75
A21: SET | B21: WEIGHT | C21: REPS | D21: REST | E21: PREVIOUS | F21: REP LOG | H21: SET | I21: WEIGHT | J21: REPS | K21: REST | L21: PREVIOUS | M21: REP LOG | O21: SET | P21: WEIGHT | Q21: REPS | R21: REST | S21: PREVIOUS | T21: REP LOG
A22: 1 | B22: =IF( 'WEEK 1 '!B20<125,45,mround('WEEK 1 '!B20*0.35,5)) -> 45 | C22: 6 | D22: 30s | H22: 1 | I22: =mround('WEEK 1 '!I20*0.35,5) -> 0 | J22: 6 | K22: 30s | O22: 1 | P22: =mround('WEEK 1 '!P20*0.35,5) -> 25 | Q22: 6 | R22: 1 MIN
A23: 2 | B23: =MROUND('WEEK 1 '!B20*0.8,5) -> 80 | C23: 1 | D23: 1-2 MIN | H23: 2 | I23: =mround('WEEK 1 '!I20*0.65,5) -> 0 | J23: 1 | K23: 1-2 MIN | O23: 2 | P23: =mround('WEEK 1 '!P20*0.65,5) -> 50 | Q23: 1 | R23: 1 MIN
A24: 3 | B24: =mround('WEEK 1 '!B20*0.9,5) -> 90 | C24: 1 | D24: 1-2 MIN | H24: 3 | I24: =mround('WEEK 1 '!I20*0.9,5) -> 0 | J24: 1 | K24: 1-2 MIN | O24: 3 | P24: =mround('WEEK 1 '!P20*0.85,5) -> 65 | Q24: 1 | R24: 1 MIN | V24: =90*0.93 -> 83.7
A25: 4 | B25: ='WEEK 1 '!B20 -> 100 | C25: 1 | D25: 1-5 MIN | H25: 4 | I25: ='WEEK 1 '!I20 | J25: 1 | K25: 1-5 MIN | O25: 4 | P25: =mround('WEEK 1 '!P20*1,5) -> 75 | Q25: REP OUT | R25: 1 MIN
A26: =IF('WEEK 1 '!F25<1,"PROCEED TO DOWN SETS","NEW 1 REP MAX ATTEMPT") -> NEW 1 REP MAX ATTEMPT | G26: ALTERNATE | H26: =IF('WEEK 1 '!M25<1,"PROCEED TO DOWN SETS","NEW 1 REP MAX ATTEMPT") -> PROCEED TO DOWN SETS | N26: ALTERNATE | O26: =IF(OR(ISBLANK('WEEK 1 '!T25),ISBLANK('WEEK 1 '!T24),ISBLANK('WEEK 1 '!T23)),"PROCEED TO DOWNSETS",if('WEEK 1 '!T25>=6,"NEW 4 REP MAX ATTEMPT","PROCEED TO DOWN SETS")) -> NEW 4 REP MAX ATTEMPT
A27: =if('WEEK 1 '!F25<1,"",5) -> 5 | B27: =IF('WEEK 1 '!F25<1,"",B25+5) -> 105 | C27: =if('WEEK 1 '!F25<1,"",1) -> 1 | D27: =if('WEEK 1 '!F25<1,"","1-5 MIN") -> 1-5 MIN | H27: =if('WEEK 1 '!M25<1,"",5) | I27: =IF('WEEK 1 '!M25<1,"",I25+5) | J27: =if('WEEK 1 '!M25<1,"",1) | K27: =if('WEEK 1 '!M25<1,"","1-5 MIN") | O27: =IF(OR(ISBLANK('WEEK 1 '!T25),ISBLANK('WEEK 1 '!T24),ISBLANK('WEEK 1 '!T23)),"",IF('WEEK 1 '!T25>=6,5,"")) -> 5 | P27: =IF(OR(ISBLANK('WEEK 1 '!T25),ISBLANK('WEEK 1 '!T24),ISBLANK('WEEK 1 '!T23)),"",IF('WEEK 1 '!T25>=6,'WEEK 1 '!P20+5,"")) -> 80 | Q27: =IF(OR(ISBLANK('WEEK 1 '!T25),ISBLANK('WEEK 1 '!T24),ISBLANK('WEEK 1 '!T23)),"",IF('WEEK 1 '!T25>=6,"REP OUT","")) -> REP OUT | R27: =IF(OR(ISBLANK('WEEK 1 '!T25),ISBLANK('WEEK 1 '!T24),ISBLANK('WEEK 1 '!T23)),"",IF('WEEK 1 '!T25>5,"1 MIN","")) -> 1 MIN
A28: =IF('WEEK 1 '!F27<1,"","6") | B28: =IF('WEEK 1 '!F27<1,"",B27+5) | C28: =IF('WEEK 1 '!F27<1,"","1") | D28: =IF('WEEK 1 '!F27<1,"","1-5 MIN") | H28: =IF('WEEK 1 '!M27<1,"","6") | I28: =IF('WEEK 1 '!M27<1,"",I27+5) | J28: =IF('WEEK 1 '!M27<1,"","1") | K28: =IF('WEEK 1 '!M27<1,"","1-5 MIN") | O28: =IF(OR(ISBLANK('WEEK 1 '!T25),ISBLANK('WEEK 1 '!T24),ISBLANK('WEEK 1 '!T23)),"FILL OUT REP LOG FIRST","DOWN SETS") -> DOWN SETS
A29: =IF(OR(ISBLANK('WEEK 1 '!F25),ISBLANK('WEEK 1 '!F24),ISBLANK('WEEK 1 '!F23)),"FILL OUT REP LOG FOR DOWN SETS","DOWN SETS") -> DOWN SETS | H29: =IF(OR(ISBLANK('WEEK 1 '!M25),ISBLANK('WEEK 1 '!M24),ISBLANK('WEEK 1 '!M23)),"FILL OUT REP LOG FOR DOWN SETS","DOWN SETS") -> FILL OUT REP LOG FOR DOWN SETS | O29: =IF('WEEK 1 '!T27>=4,"",IF(OR(ISBLANK('WEEK 1 '!T25),ISBLANK('WEEK 1 '!T24),ISBLANK('WEEK 1 '!T23)),"",IF('WEEK 1 '!T25>5,6,5))) -> 6 | P29: =IF('WEEK 1 '!T27>=4,"",IF(OR(ISBLANK('WEEK 1 '!T25),ISBLANK('WEEK 1 '!T24),ISBLANK('WEEK 1 '!T23)),"",IF('WEEK 1 '!T25<6,mround('WEEK 1 '!P20*0.8,5),IF('WEEK 1 '!T25<10,mround('WEEK 1 '!P20*0.93,5),mround('WEEK 1 '!P20*0.7,5))))) -> 70 | Q29: =IF('WEEK 1 '!T27>=4,"",IF(OR(ISBLANK('WEEK 1 '!T25),ISBLANK('WEEK 1 '!T24),ISBLANK('WEEK 1 '!T23)),"","REP OUT")) -> REP OUT | R29: =IF('WEEK 1 '!T27>=4,"",IF(OR(ISBLANK('WEEK 1 '!T25),ISBLANK('WEEK 1 '!T24),ISBLANK('WEEK 1 '!T23)),"","1 MIN")) -> 1 MIN | V29: =0.7*85 -> 59.5
A30: =IF(OR(ISBLANK('WEEK 1 '!F25),ISBLANK('WEEK 1 '!F24),ISBLANK('WEEK 1 '!F23)),"",IF((AND(A27="",A28="")),5,IF((AND(A27>1,A28="")),6,7))) -> 6 | B30: =IF(OR(ISBLANK('WEEK 1 '!F25),ISBLANK('WEEK 1 '!F24),ISBLANK('WEEK 1 '!F23)),"",MROUND('WEEK 1 '!B32*0.9,5)) -> 90 | C30: =IF(OR(ISBLANK('WEEK 1 '!F25),ISBLANK('WEEK 1 '!F24),ISBLANK('WEEK 1 '!F23)),"","REP OUT") -> REP OUT | D30: =IF(OR(ISBLANK('WEEK 1 '!F25),ISBLANK('WEEK 1 '!F24),ISBLANK('WEEK 1 '!F23)),"","1-3 MIN") -> 1-3 MIN | H30: =IF(OR(ISBLANK('WEEK 1 '!M25),ISBLANK('WEEK 1 '!M24),ISBLANK('WEEK 1 '!M23)),"",IF((AND(H27="",H28="")),5,IF((AND(H27>1,H28="")),6,7))) | I30: =IF(OR(ISBLANK('WEEK 1 '!M25),ISBLANK('WEEK 1 '!M24),ISBLANK('WEEK 1 '!M23)),"",MROUND('WEEK 1 '!I32*0.9,5)) | J30: =IF(OR(ISBLANK('WEEK 1 '!M25),ISBLANK('WEEK 1 '!M24),ISBLANK('WEEK 1 '!M23)),"","REP OUT") | K30: =IF(OR(ISBLANK('WEEK 1 '!M25),ISBLANK('WEEK 1 '!M24),ISBLANK('WEEK 1 '!M23)),"","1-3 MIN") | O30: =IF('WEEK 1 '!T27>=4,"",IF(OR(ISBLANK('WEEK 1 '!T25),ISBLANK('WEEK 1 '!T24),ISBLANK('WEEK 1 '!T23)),"",IF('WEEK 1 '!T25>5,7,6))) -> 7 | P30: =IF('WEEK 1 '!T27>=4,"",IF(OR(ISBLANK('WEEK 1 '!T25),ISBLANK('WEEK 1 '!T24),ISBLANK('WEEK 1 '!T23)),"",IF('WEEK 1 '!T25<6,mround('WEEK 1 '!P20*0.65,5),IF('WEEK 1 '!T25<10,mround('WEEK 1 '!P20*0.7,5),mround('WEEK 1 '!P20*0.65,5))))) -> 55 | Q30: =IF('WEEK 1 '!T27>=4,"",IF(OR(ISBLANK('WEEK 1 '!T25),ISBLANK('WEEK 1 '!T24),ISBLANK('WEEK 1 '!T23)),"","REP OUT")) -> REP OUT | R30: =IF('WEEK 1 '!T27>=4,"",IF(OR(ISBLANK('WEEK 1 '!T25),ISBLANK('WEEK 1 '!T24),ISBLANK('WEEK 1 '!T23)),"","1 MIN")) -> 1 MIN
A31: =IF(OR(ISBLANK('WEEK 1 '!F25),ISBLANK('WEEK 1 '!F24),ISBLANK('WEEK 1 '!F23)),"",IF((AND(A27="",A28="")),6,IF((AND(A27>1,A28="")),7,8))) -> 7 | B31: =IF(OR(ISBLANK('WEEK 1 '!F25),ISBLANK('WEEK 1 '!F24),ISBLANK('WEEK 1 '!F23)),"",mround('WEEK 1 '!B32*0.78,5)) -> 80 | C31: =IF(OR(ISBLANK('WEEK 1 '!F25),ISBLANK('WEEK 1 '!F24),ISBLANK('WEEK 1 '!F23)),"","REP OUT") -> REP OUT | D31: =IF(OR(ISBLANK('WEEK 1 '!F25),ISBLANK('WEEK 1 '!F24),ISBLANK('WEEK 1 '!F23)),"","1-3 MIN") -> 1-3 MIN | H31: =IF(OR(ISBLANK('WEEK 1 '!M25),ISBLANK('WEEK 1 '!M24),ISBLANK('WEEK 1 '!M23)),"",IF((AND(H27="",H28="")),6,IF((AND(H27>1,H28="")),7,8))) | I31: =IF(OR(ISBLANK('WEEK 1 '!M25),ISBLANK('WEEK 1 '!M24),ISBLANK('WEEK 1 '!M23)),"",mround('WEEK 1 '!I32*0.78,5)) | J31: =IF(OR(ISBLANK('WEEK 1 '!M25),ISBLANK('WEEK 1 '!M24),ISBLANK('WEEK 1 '!M23)),"","REP OUT") | K31: =IF(OR(ISBLANK('WEEK 1 '!M25),ISBLANK('WEEK 1 '!M24),ISBLANK('WEEK 1 '!M23)),"","1-3 MIN") | O31: =IF('WEEK 1 '!T27<4,"",IF(OR(ISBLANK('WEEK 1 '!T25),ISBLANK('WEEK 1 '!T24),ISBLANK('WEEK 1 '!T23)),"",IF('WEEK 1 '!T27>3,6,5))) | P31: =IF('WEEK 1 '!T27<4,"",IF(OR(ISBLANK('WEEK 1 '!T25),ISBLANK('WEEK 1 '!T24),ISBLANK('WEEK 1 '!T23)),"",IF('WEEK 1 '!T27<6,mround('WEEK 1 '!P33*0.8,5),IF('WEEK 1 '!T27<10,mround('WEEK 1 '!P33*0.93,5),mround('WEEK 1 '!P33*0.7,5))))) | Q31: =IF('WEEK 1 '!T27<4,"",IF(OR(ISBLANK('WEEK 1 '!T25),ISBLANK('WEEK 1 '!T24),ISBLANK('WEEK 1 '!T23)),"","REP OUT")) | R31: =IF('WEEK 1 '!T27<4,"",IF(OR(ISBLANK('WEEK 1 '!T25),ISBLANK('WEEK 1 '!T24),ISBLANK('WEEK 1 '!T23)),"","1 MIN"))
A32: FINAL MAX | B32: =IF(OR(ISBLANK('WEEK 1 '!F25),ISBLANK('WEEK 1 '!F24),ISBLANK('WEEK 1 '!F23)),"",IF('WEEK 1 '!F28>=1,'WEEK 1 '!B28,IF('WEEK 1 '!F27>=1,'WEEK 1 '!B27,IF('WEEK 1 '!F25<1,'WEEK 1 '!B25-5,'WEEK 1 '!B25)))) -> 100 | H32: FINAL MAX | I32: =IF(OR(ISBLANK('WEEK 1 '!M25),ISBLANK('WEEK 1 '!M24),ISBLANK('WEEK 1 '!M23)),"",IF('WEEK 1 '!M28>=1,'WEEK 1 '!I28,IF('WEEK 1 '!M27>=1,'WEEK 1 '!I27,IF('WEEK 1 '!M25<1,'WEEK 1 '!I25-5,'WEEK 1 '!I25)))) | O32: =IF('WEEK 1 '!T27<4,"",IF(OR(ISBLANK('WEEK 1 '!T25),ISBLANK('WEEK 1 '!T24),ISBLANK('WEEK 1 '!T23)),"",IF('WEEK 1 '!T27>3,7,""))) | P32: =IF('WEEK 1 '!T27<4,"",IF(OR(ISBLANK('WEEK 1 '!T25),ISBLANK('WEEK 1 '!T24),ISBLANK('WEEK 1 '!T23)),"",IF('WEEK 1 '!T27<6,mround('WEEK 1 '!P33*0.65,5),IF('WEEK 1 '!T27<10,mround('WEEK 1 '!P33*0.7,5),mround('WEEK 1 '!P33*0.65,5))))) | Q32: =IF('WEEK 1 '!T27<4,"",IF(OR(ISBLANK('WEEK 1 '!T25),ISBLANK('WEEK 1 '!T24),ISBLANK('WEEK 1 '!T23)),"","REP OUT")) | R32: =IF('WEEK 1 '!T27<4,"",IF(OR(ISBLANK('WEEK 1 '!T25),ISBLANK('WEEK 1 '!T24),ISBLANK('WEEK 1 '!T23)),"","1 MIN"))
O33: FINAL MAX | P33: =IF(OR(ISBLANK('WEEK 1 '!T23),ISBLANK('WEEK 1 '!T24),ISBLANK('WEEK 1 '!T25)),"",IF('WEEK 1 '!T27>=4,'WEEK 1 '!P27,IF('WEEK 1 '!T25<=3,'WEEK 1 '!P25-5,'WEEK 1 '!P25))) -> 75
A34: =IF(B35<5,"SKIP TO NEXT WORKOUT",HYPERLINK("https://www.youtube.com/watch?v=mGv8D2DGyNQ","2.DB CHEST FLY")) -> 2.DB CHEST FLY | H34: =HYPERLINK("https://www.youtube.com/watch?v=THb0dhfIu1k","2. MACHINE CHEST FLY") -> 2. MACHINE CHEST FLY
A35: DBL INC MAX | B35: 30 | G35: ALTERNATE | H35: DBL INC MAX | I35: ='WEEK 1 '!B35 -> 30
A36: SET | B36: WEIGHT | C36: REPS | D36: REST | E36: PREVIOUS | F36: REP LOG | H36: SET | I36: WEIGHT | J36: REPS | K36: REST | L36: PREVIOUS | M36: REP LOG
A37: 1 | B37: =mround(B35*0.29,2.5) -> 7.5 | C37: 15 | D37: 1 - 2 MIN | H37: 1 | I37: =mround('WEEK 1 '!I35*2*0.75,10) -> 110 | J37: 15 | K37: 1 - 2 MIN
A38: 2 | B38: =mround(B35*0.29,2.5) -> 7.5 | C38: 15 | D38: 1 - 2 MIN | H38: 2 | I38: =mround('WEEK 1 '!I35*2*0.75,10) -> 110 | J38: 15 | K38: 1 - 2 MIN
A41: =HYPERLINK("https://www.youtube.com/watch?v=PnaDzYh2axA","3. LAT PULL DOWN") -> 3. LAT PULL DOWN
A42: CURRENT MAX | B42: 100
A43: SET | B43: WEIGHT | C43: REPS | D43: REST | E43: PREVIOUS | F43: REP LOG
A44: 1 | B44: =mround('WEEK 1 '!B42*0.35,5) -> 90 | C44: 6 | D44: 30s
A45: 2 | B45: =mround('WEEK 1 '!B42*0.65,5) -> 165 | C45: 3 | D45: 1-2 MIN
A46: 3 | B46: =mround('WEEK 1 '!B42*0.9,5) -> 230 | C46: 2 | D46: 1-2 MIN
A47: 4 | B47: ='WEEK 1 '!B42 -> 255 | C47: 3 | D47: 1-5 MIN
A48: =IF('WEEK 1 '!F47<3,"PROCEED TO DOWN SETS","NEW 4 REP MAX ATTEMPT") -> NEW 4 REP MAX ATTEMPT
A49: =if('WEEK 1 '!F47<=2,"",5) -> 5 | B49: =IF('WEEK 1 '!F47<=2,"",B47+5) -> 260 | C49: =if('WEEK 1 '!F47<=2,"",4) -> 4 | D49: =if('WEEK 1 '!F47<=2,"","1-5 MIN") -> 1-5 MIN
A50: =IF('WEEK 1 '!F49<4,"","6") -> 6 | B50: =IF('WEEK 1 '!F49<4,"",B49+5) -> 265 | C50: =IF('WEEK 1 '!F49<4,"","4") -> 4 | D50: =IF('WEEK 1 '!F49<4,"","1-5 MIN") -> 1-5 MIN
A51: =IF(OR(ISBLANK('WEEK 1 '!F47),ISBLANK('WEEK 1 '!F46),ISBLANK('WEEK 1 '!F45)),"FILL OUT REP LOG FOR DOWN SETS","DOWN SETS") -> DOWN SETS
A52: =IF(OR(ISBLANK('WEEK 1 '!F47),ISBLANK('WEEK 1 '!F46),ISBLANK('WEEK 1 '!F45)),"",IF((AND(A49="",A50="")),5,IF((AND(A49>1,A50="")),6,7))) -> 7 | B52: =MROUND('WEEK 1 '!B54*0.8,5) -> 210 | C52: REP OUT | D52: 1-3 MIN
A53: =IF(OR(ISBLANK('WEEK 1 '!F47),ISBLANK('WEEK 1 '!F46),ISBLANK('WEEK 1 '!F45)),"",IF((AND(A49="",A50="")),6,IF((AND(A49>1,A50="")),7,8))) -> 8 | B53: =mround('WEEK 1 '!B54*0.7,5) -> 180 | C53: REP OUT | D53: 1-3 MIN
...

Sheet Sheet75

Sheet WEEK 1 
A9: Week 1 | H9: QUICK TIPS
A10: ='Week 1 MASTER SHEET'!A10 -> PRESS TO RECORD BODY WEIGHT | H10: IF IT'S GREEN=NEEDS YOUR INPUT
H11: Click The Title of The workout to see an Instructional Video
A12: This Weeks Goals | G12: ='Week 1 MASTER SHEET'!H12
A13: This week we are going to jump you into a workout. As the weeks go on we will refine your workout more and it will become more targeted. Give it all you got and push to your limits everytime.
A14: SWIPE RIGHT FOR QUICK TIPS
A15: DAY 1 | H15: ALTERNATE WORKOUTS | O15: ='Week 1 MASTER SHEET'!O15 -> ALTERNATE WORKOUTS
A18: CHEST & BACK | H18: ='Week 1 MASTER SHEET'!H18 -> CHEST & BACK | O18: ='Week 1 MASTER SHEET'!O18 -> CHEST & BACK
A19: =HYPERLINK("https://www.youtube.com/watch?v=iLgUDezDMbU","1. BENCH PRESS") -> 1. BENCH PRESS | G19: ALTERNATE | H19: ='Week 1 MASTER SHEET'!H19 -> 1. MACHINE PRESS | O19: ='Week 1 MASTER SHEET'!O19 -> 1. DUMBBELL INCLINE PRESS
A20: CURRENT MAX | B20: 100 | H20: ='Week 1 MASTER SHEET'!H20 -> CURRENT MAX | I20: ='DETERMINING MAX WEEK'!S31 | O20: ='Week 1 MASTER SHEET'!O20 -> CURRENT MAX | P20: 75
A21: SET | B21: WEIGHT | C21: REPS | D21: REST | E21: PREVIOUS | F21: REP LOG | H21: ='Week 1 MASTER SHEET'!H21 -> SET | I21: ='Week 1 MASTER SHEET'!I21 -> WEIGHT | J21: ='Week 1 MASTER SHEET'!J21 -> REPS | K21: ='Week 1 MASTER SHEET'!K21 -> REST | L21: ='Week 1 MASTER SHEET'!L21 -> PREVIOUS | M21: REP LOG | O21: ='Week 1 MASTER SHEET'!O21 -> SET | P21: ='Week 1 MASTER SHEET'!P21 -> WEIGHT | Q21: ='Week 1 MASTER SHEET'!Q21 -> REPS | R21: ='Week 1 MASTER SHEET'!R21 -> REST | S21: ='Week 1 MASTER SHEET'!S21 -> PREVIOUS | T21: REP LOG
A22: ='Week 1 MASTER SHEET'!A22 -> 1 | B22: ='Week 1 MASTER SHEET'!B22 -> 45 | C22: ='Week 1 MASTER SHEET'!C22 -> 6 | D22: ='Week 1 MASTER SHEET'!D22 -> 30s | F22: 6 | H22: ='Week 1 MASTER SHEET'!H22 -> 1 | I22: ='Week 1 MASTER SHEET'!I22 -> 0 | J22: ='Week 1 MASTER SHEET'!J22 -> 6 | K22: ='Week 1 MASTER SHEET'!K22 -> 30s | L22: ='Week 1 MASTER SHEET'!L22 | O22: ='Week 1 MASTER SHEET'!O22 -> 1 | P22: ='Week 1 MASTER SHEET'!P22 -> 25 | Q22: ='Week 1 MASTER SHEET'!Q22 -> 6 | R22: ='Week 1 MASTER SHEET'!R22 -> 1 MIN | S22: ='Week 1 MASTER SHEET'!S22 | T22: 6
A23: ='Week 1 MASTER SHEET'!A23 -> 2 | B23: ='Week 1 MASTER SHEET'!B23 -> 80 | C23: ='Week 1 MASTER SHEET'!C23 -> 1 | D23: ='Week 1 MASTER SHEET'!D23 -> 1-2 MIN | E23: ='Week 1 MASTER SHEET'!E23 | F23: 1 | H23: ='Week 1 MASTER SHEET'!H23 -> 2 | I23: ='Week 1 MASTER SHEET'!I23 -> 0 | J23: ='Week 1 MASTER SHEET'!J23 -> 1 | K23: ='Week 1 MASTER SHEET'!K23 -> 1-2 MIN | L23: ='Week 1 MASTER SHEET'!L23 | O23: ='Week 1 MASTER SHEET'!O23 -> 2 | P23: ='Week 1 MASTER SHEET'!P23 -> 50 | Q23: ='Week 1 MASTER SHEET'!Q23 -> 1 | R23: ='Week 1 MASTER SHEET'!R23 -> 1 MIN | S23: ='Week 1 MASTER SHEET'!S23 | T23: 1
A24: ='Week 1 MASTER SHEET'!A24 -> 3 | B24: ='Week 1 MASTER SHEET'!B24 -> 90 | C24: ='Week 1 MASTER SHEET'!C24 -> 1 | D24: ='Week 1 MASTER SHEET'!D24 -> 1-2 MIN | E24: ='Week 1 MASTER SHEET'!E24 | F24: 1 | H24: ='Week 1 MASTER SHEET'!H24 -> 3 | I24: ='Week 1 MASTER SHEET'!I24 -> 0 | J24: ='Week 1 MASTER SHEET'!J24 -> 1 | K24: ='Week 1 MASTER SHEET'!K24 -> 1-2 MIN | L24: ='Week 1 MASTER SHEET'!L24 | O24: ='Week 1 MASTER SHEET'!O24 -> 3 | P24: ='Week 1 MASTER SHEET'!P24 -> 65 | Q24: ='Week 1 MASTER SHEET'!Q24 -> 1 | R24: ='Week 1 MASTER SHEET'!R24 -> 1 MIN | S24: ='Week 1 MASTER SHEET'!S24 | T24: 1
A25: ='Week 1 MASTER SHEET'!A25 -> 4 | B25: ='Week 1 MASTER SHEET'!B25 -> 100 | C25: ='Week 1 MASTER SHEET'!C25 -> 1 | D25: ='Week 1 MASTER SHEET'!D25 -> 1-5 MIN | E25: ='Week 1 MASTER SHEET'!E25 | F25: 1 | H25: ='Week 1 MASTER SHEET'!H25 -> 4 | I25: ='Week 1 MASTER SHEET'!I25 | J25: ='Week 1 MASTER SHEET'!J25 -> 1 | K25: ='Week 1 MASTER SHEET'!K25 -> 1-5 MIN | L25: ='Week 1 MASTER SHEET'!L25 | O25: ='Week 1 MASTER SHEET'!O25 -> 4 | P25: ='Week 1 MASTER SHEET'!P25 -> 75 | Q25: ='Week 1 MASTER SHEET'!Q25 -> REP OUT | R25: ='Week 1 MASTER SHEET'!R25 -> 1 MIN | S25: ='Week 1 MASTER SHEET'!S25 | T25: 6
A26: ='Week 1 MASTER SHEET'!A26 -> NEW 1 REP MAX ATTEMPT | H26: ='Week 1 MASTER SHEET'!H26 -> PROCEED TO DOWN SETS | O26: ='Week 1 MASTER SHEET'!O26 -> NEW 4 REP MAX ATTEMPT
A27: ='Week 1 MASTER SHEET'!A27 -> 5 | B27: ='Week 1 MASTER SHEET'!B27 -> 105 | C27: ='Week 1 MASTER SHEET'!C27 -> 1 | D27: ='Week 1 MASTER SHEET'!D27 -> 1-5 MIN | E27: ='Week 1 MASTER SHEET'!E27 | H27: ='Week 1 MASTER SHEET'!H27 | I27: ='Week 1 MASTER SHEET'!I27 | J27: ='Week 1 MASTER SHEET'!J27 | K27: ='Week 1 MASTER SHEET'!K27 | L27: ='Week 1 MASTER SHEET'!L27 | O27: ='Week 1 MASTER SHEET'!O27 -> 5 | P27: ='Week 1 MASTER SHEET'!P27 -> 80 | Q27: ='Week 1 MASTER SHEET'!Q27 -> REP OUT | R27: ='Week 1 MASTER SHEET'!R27 -> 1 MIN | S27: ='Week 1 MASTER SHEET'!S27 | T27: 3
A28: ='Week 1 MASTER SHEET'!A28 | B28: ='Week 1 MASTER SHEET'!B28 | C28: ='Week 1 MASTER SHEET'!C28 | D28: ='Week 1 MASTER SHEET'!D28 | E28: ='Week 1 MASTER SHEET'!E28 | H28: ='Week 1 MASTER SHEET'!H28 | I28: ='Week 1 MASTER SHEET'!I28 | J28: ='Week 1 MASTER SHEET'!J28 | K28: ='Week 1 MASTER SHEET'!K28 | O28: ='Week 1 MASTER SHEET'!O28 -> DOWN SETS
A29: ='Week 1 MASTER SHEET'!A29 -> DOWN SETS | H29: ='Week 1 MASTER SHEET'!H29 -> FILL OUT REP LOG FOR DOWN SETS | O29: ='Week 1 MASTER SHEET'!O29 -> 6 | P29: ='Week 1 MASTER SHEET'!P29 -> 70 | Q29: ='Week 1 MASTER SHEET'!Q29 -> REP OUT | R29: ='Week 1 MASTER SHEET'!R29 -> 1 MIN | S29: ='Week 1 MASTER SHEET'!S29 | T29: 6
A30: ='Week 1 MASTER SHEET'!A30 -> 6 | C30: ='Week 1 MASTER SHEET'!C30 -> REP OUT | D30: ='Week 1 MASTER SHEET'!D30 -> 1-3 MIN | E30: ='Week 1 MASTER SHEET'!E30 | H30: ='Week 1 MASTER SHEET'!H30 | I30: ='Week 1 MASTER SHEET'!I30 | J30: ='Week 1 MASTER SHEET'!J30 | K30: ='Week 1 MASTER SHEET'!K30 | L30: ='Week 1 MASTER SHEET'!L30 | O30: ='Week 1 MASTER SHEET'!O30 -> 7 | P30: ='Week 1 MASTER SHEET'!P30 -> 55 | Q30: ='Week 1 MASTER SHEET'!Q30 -> REP OUT | R30: ='Week 1 MASTER SHEET'!R30 -> 1 MIN | S30: ='Week 1 MASTER SHEET'!S30 | T30: 10
A31: ='Week 1 MASTER SHEET'!A31 -> 7 | B31: 185 | C31: ='Week 1 MASTER SHEET'!C31 -> REP OUT | D31: ='Week 1 MASTER SHEET'!D31 -> 1-3 MIN | E31: ='Week 1 MASTER SHEET'!E31 | H31: ='Week 1 MASTER SHEET'!H31 | I31: ='Week 1 MASTER SHEET'!I31 | J31: ='Week 1 MASTER SHEET'!J31 | K31: ='Week 1 MASTER SHEET'!K31 | L31: ='Week 1 MASTER SHEET'!L31 | O31: ='Week 1 MASTER SHEET'!O31 | P31: ='Week 1 MASTER SHEET'!P31 | Q31: ='Week 1 MASTER SHEET'!Q31 | R31: ='Week 1 MASTER SHEET'!R31 | S31: ='Week 1 MASTER SHEET'!S31
A32: ='Week 1 MASTER SHEET'!A32 -> FINAL MAX | B32: ='Week 1 MASTER SHEET'!B32 -> 100 | H32: ='Week 1 MASTER SHEET'!H32 -> FINAL MAX | I32: ='Week 1 MASTER SHEET'!I32 | O32: ='Week 1 MASTER SHEET'!O32 | P32: ='Week 1 MASTER SHEET'!P32 | Q32: ='Week 1 MASTER SHEET'!Q32 | R32: ='Week 1 MASTER SHEET'!R32 | S32: ='Week 1 MASTER SHEET'!S32
O33: ='Week 1 MASTER SHEET'!O33 -> FINAL MAX | P33: ='Week 1 MASTER SHEET'!P33 -> 75
A34: ='Week 1 MASTER SHEET'!A34 -> 2.DB CHEST FLY | G34: ALTERNATE | H34: ='Week 1 MASTER SHEET'!H34 -> 2. MACHINE CHEST FLY
A35: ='Week 1 MASTER SHEET'!A35 -> DBL INC MAX | B35: 30 | H35: ='Week 1 MASTER SHEET'!H35 -> DBL INC MAX | I35: 75
A36: ='Week 1 MASTER SHEET'!A36 -> SET | B36: ='Week 1 MASTER SHEET'!B36 -> WEIGHT | C36: ='Week 1 MASTER SHEET'!C36 -> REPS | D36: ='Week 1 MASTER SHEET'!D36 -> REST | E36: ='Week 1 MASTER SHEET'!E36 -> PREVIOUS | F36: REP LOG | H36: ='Week 1 MASTER SHEET'!H36 -> SET | I36: ='Week 1 MASTER SHEET'!I36 -> WEIGHT | J36: ='Week 1 MASTER SHEET'!J36 -> REPS | K36: ='Week 1 MASTER SHEET'!K36 -> REST | L36: ='Week 1 MASTER SHEET'!L36 -> PREVIOUS | M36: REP LOG
A37: ='Week 1 MASTER SHEET'!A37 -> 1 | B37: ='Week 1 MASTER SHEET'!B37 -> 7.5 | C37: ='Week 1 MASTER SHEET'!C37 -> 15 | D37: ='Week 1 MASTER SHEET'!D37 -> 1 - 2 MIN | E37: ='Week 1 MASTER SHEET'!E37 | F37: 15 | H37: ='Week 1 MASTER SHEET'!H37 -> 1 | I37: ='Week 1 MASTER SHEET'!I37 -> 110 | J37: ='Week 1 MASTER SHEET'!J37 -> 15 | K37: ='Week 1 MASTER SHEET'!K37 -> 1 - 2 MIN | L37: ='Week 1 MASTER SHEET'!L37
A38: ='Week 1 MASTER SHEET'!A38 -> 2 | B38: ='Week 1 MASTER SHEET'!B38 -> 7.5 | C38: ='Week 1 MASTER SHEET'!C38 -> 15 | D38: ='Week 1 MASTER SHEET'!D38 -> 1 - 2 MIN | E38: ='Week 1 MASTER SHEET'!E38 | F38: 15 | H38: ='Week 1 MASTER SHEET'!H38 -> 2 | I38: ='Week 1 MASTER SHEET'!I38 -> 110 | J38: ='Week 1 MASTER SHEET'!J38 -> 15 | K38: ='Week 1 MASTER SHEET'!K38 -> 1 - 2 MIN | L38: ='Week 1 MASTER SHEET'!L38
A41: ='Week 1 MASTER SHEET'!A41 -> 3. LAT PULL DOWN
A42: ='Week 1 MASTER SHEET'!A42 -> CURRENT MAX | B42: 255
A43: ='Week 1 MASTER SHEET'!A43 -> SET | B43: ='Week 1 MASTER SHEET'!B43 -> WEIGHT | C43: ='Week 1 MASTER SHEET'!C43 -> REPS | D43: ='Week 1 MASTER SHEET'!D43 -> REST | E43: ='Week 1 MASTER SHEET'!E43 -> PREVIOUS | F43: REP LOG
A44: ='Week 1 MASTER SHEET'!A44 -> 1 | B44: ='Week 1 MASTER SHEET'!B44 -> 90 | C44: ='Week 1 MASTER SHEET'!C44 -> 6 | D44: ='Week 1 MASTER SHEET'!D44 -> 30s | E44: ='Week 1 MASTER SHEET'!E44 | F44: 6
A45: ='Week 1 MASTER SHEET'!A45 -> 2 | B45: ='Week 1 MASTER SHEET'!B45 -> 165 | C45: ='Week 1 MASTER SHEET'!C45 -> 3 | D45: ='Week 1 MASTER SHEET'!D45 -> 1-2 MIN | E45: ='Week 1 MASTER SHEET'!E45 | F45: 3
A46: ='Week 1 MASTER SHEET'!A46 -> 3 | B46: ='Week 1 MASTER SHEET'!B46 -> 230 | C46: ='Week 1 MASTER SHEET'!C46 -> 2 | D46: ='Week 1 MASTER SHEET'!D46 -> 1-2 MIN | E46: ='Week 1 MASTER SHEET'!E46 | F46: 2
A47: ='Week 1 MASTER SHEET'!A47 -> 4 | B47: ='Week 1 MASTER SHEET'!B47 -> 255 | C47: ='Week 1 MASTER SHEET'!C47 -> 3 | D47: ='Week 1 MASTER SHEET'!D47 -> 1-5 MIN | E47: ='Week 1 MASTER SHEET'!E47 | F47: 3
A48: ='Week 1 MASTER SHEET'!A48 -> NEW 4 REP MAX ATTEMPT
A49: ='Week 1 MASTER SHEET'!A49 -> 5 | B49: ='Week 1 MASTER SHEET'!B49 -> 260 | C49: ='Week 1 MASTER SHEET'!C49 -> 4 | D49: ='Week 1 MASTER SHEET'!D49 -> 1-5 MIN | E49: ='Week 1 MASTER SHEET'!E49 | F49: 4
A50: ='Week 1 MASTER SHEET'!A50 -> 6 | B50: ='Week 1 MASTER SHEET'!B50 -> 265 | C50: ='Week 1 MASTER SHEET'!C50 -> 4 | D50: ='Week 1 MASTER SHEET'!D50 -> 1-5 MIN | E50: ='Week 1 MASTER SHEET'!E50 | F50: 3
A51: ='Week 1 MASTER SHEET'!A51 -> DOWN SETS
A52: ='Week 1 MASTER SHEET'!A52 -> 7 | B52: ='Week 1 MASTER SHEET'!B52 -> 210 | C52: ='Week 1 MASTER SHEET'!C52 -> REP OUT | D52: ='Week 1 MASTER SHEET'!D52 -> 1-3 MIN | E52: ='Week 1 MASTER SHEET'!E52 | F52: 6
...

Sheet WEEK 2
A9: ='Week 2 (MASTER SHEET)'!A9 -> Week 2 | H9: QUICK TIPS
A10: ='Week 2 (MASTER SHEET)'!A10 -> PRESS TO RECORD BODY WEIGHT | H10: IF IT'S GREEN=NEEDS YOUR INPUT
H11: Click The Title of The workout to see an Instructional Video
A12: This Weeks Goals
A13: ='Week 2 (MASTER SHEET)'!A13 -> This week we are going to continue to attemp new maxes in some areas as well as go for max repititions in others. Be sure to push your hardest and keep good form.
A14: SWIPE RIGHT FOR QUICK TIPS
A16: DAY 1 | H16: ='Week 2 (MASTER SHEET)'!H16 -> ALTERNATE WORKOUTS
A19: ='Week 2 (MASTER SHEET)'!A19 -> CHEST & BACK | H19: ='Week 2 (MASTER SHEET)'!H19 -> CHEST & BACK
A20: ='Week 2 (MASTER SHEET)'!A20 -> 1. DUMBBELL INCLINE PRESS | G20: ALTERNATE | H20: ='Week 2 (MASTER SHEET)'!H20 -> 1. MACHINE PRESS
A21: ='Week 2 (MASTER SHEET)'!A21 -> CURRENT MAX | B21: 75 | H21: ='Week 2 (MASTER SHEET)'!H21 -> CURRENT MAX | I21: ='Week 2 (MASTER SHEET)'!I21
A22: ='Week 2 (MASTER SHEET)'!A22 -> SET | B22: ='Week 2 (MASTER SHEET)'!B22 -> WEIGHT | C22: ='Week 2 (MASTER SHEET)'!C22 -> REPS | D22: ='Week 2 (MASTER SHEET)'!D22 -> REST | E22: ='Week 2 (MASTER SHEET)'!E22 -> PREVIOUS | F22: ='Week 2 (MASTER SHEET)'!F22 -> REP LOG | H22: ='Week 2 (MASTER SHEET)'!H22 -> SET | I22: ='Week 2 (MASTER SHEET)'!I22 -> WEIGHT | J22: ='Week 2 (MASTER SHEET)'!J22 -> REPS | K22: ='Week 2 (MASTER SHEET)'!K22 -> REST | L22: ='Week 2 (MASTER SHEET)'!L22 -> PREVIOUS | M22: ='Week 2 (MASTER SHEET)'!M22 -> REP LOG
A23: ='Week 2 (MASTER SHEET)'!A23 -> 1 | B23: ='Week 2 (MASTER SHEET)'!B23 -> 25 | C23: ='Week 2 (MASTER SHEET)'!C23 -> 6 | D23: ='Week 2 (MASTER SHEET)'!D23 -> 1 MIN | E23: ='Week 2 (MASTER SHEET)'!E23 -> 6 | F23: 6 | H23: ='Week 2 (MASTER SHEET)'!H23 -> 1 | I23: ='Week 2 (MASTER SHEET)'!I23 -> 0 | J23: ='Week 2 (MASTER SHEET)'!J23 -> 6 | K23: ='Week 2 (MASTER SHEET)'!K23 -> 1 MIN | L23: ='Week 2 (MASTER SHEET)'!L23
A24: ='Week 2 (MASTER SHEET)'!A24 -> 2 | B24: ='Week 2 (MASTER SHEET)'!B24 -> 50 | C24: ='Week 2 (MASTER SHEET)'!C24 -> 1 | D24: ='Week 2 (MASTER SHEET)'!D24 -> 1 MIN | E24: ='Week 2 (MASTER SHEET)'!E24 -> 1 | F24: 1 | H24: ='Week 2 (MASTER SHEET)'!H24 -> 2 | I24: ='Week 2 (MASTER SHEET)'!I24 -> 0 | J24: ='Week 2 (MASTER SHEET)'!J24 -> 1 | K24: ='Week 2 (MASTER SHEET)'!K24 -> 1 MIN | L24: ='Week 2 (MASTER SHEET)'!L24
A25: ='Week 2 (MASTER SHEET)'!A25 -> 3 | B25: ='Week 2 (MASTER SHEET)'!B25 -> 65 | C25: ='Week 2 (MASTER SHEET)'!C25 -> 1 | D25: ='Week 2 (MASTER SHEET)'!D25 -> 1 MIN | E25: ='Week 2 (MASTER SHEET)'!E25 -> 1 | F25: 1 | H25: ='Week 2 (MASTER SHEET)'!H25 -> 3 | I25: ='Week 2 (MASTER SHEET)'!I25 -> 0 | J25: ='Week 2 (MASTER SHEET)'!J25 -> 1 | K25: ='Week 2 (MASTER SHEET)'!K25 -> 1 MIN | L25: ='Week 2 (MASTER SHEET)'!L25
A26: ='Week 2 (MASTER SHEET)'!A26 -> 4 | B26: ='Week 2 (MASTER SHEET)'!B26 -> 75 | C26: ='Week 2 (MASTER SHEET)'!C26 -> REP OUT | D26: ='Week 2 (MASTER SHEET)'!D26 -> 1 MIN | E26: ='Week 2 (MASTER SHEET)'!E26 -> 6 | F26: 6 | H26: ='Week 2 (MASTER SHEET)'!H26 -> 4 | I26: ='Week 2 (MASTER SHEET)'!I26 -> 0 | J26: ='Week 2 (MASTER SHEET)'!J26 -> REP OUT | K26: ='Week 2 (MASTER SHEET)'!K26 -> 1 MIN | L26: ='Week 2 (MASTER SHEET)'!L26
A27: ='Week 2 (MASTER SHEET)'!A27 -> NEW 4 REP MAX ATTEMPT | H27: ='Week 2 (MASTER SHEET)'!H27 -> PROCEED TO DOWNSETS
A28: ='Week 2 (MASTER SHEET)'!A28 -> 5 | B28: ='Week 2 (MASTER SHEET)'!B28 -> 80 | C28: ='Week 2 (MASTER SHEET)'!C28 -> REP OUT | D28: ='Week 2 (MASTER SHEET)'!D28 -> 1 MIN | E28: ='Week 2 (MASTER SHEET)'!E28 -> 3 | F28: 2 | H28: ='Week 2 (MASTER SHEET)'!H28 | I28: ='Week 2 (MASTER SHEET)'!I28 | J28: ='Week 2 (MASTER SHEET)'!J28 | K28: ='Week 2 (MASTER SHEET)'!K28 | L28: ='Week 2 (MASTER SHEET)'!L28
A29: ='Week 2 (MASTER SHEET)'!A29 -> DOWN SETS | H29: ='Week 2 (MASTER SHEET)'!H29 -> FILL OUT REP LOG FIRST
A30: ='Week 2 (MASTER SHEET)'!A30 -> 6 | B30: ='Week 2 (MASTER SHEET)'!B30 -> 70 | C30: ='Week 2 (MASTER SHEET)'!C30 -> REP OUT | D30: ='Week 2 (MASTER SHEET)'!D30 -> 1 MIN | E30: ='Week 2 (MASTER SHEET)'!E30 -> 6 | H30: ='Week 2 (MASTER SHEET)'!H30 | I30: ='Week 2 (MASTER SHEET)'!I30 | J30: ='Week 2 (MASTER SHEET)'!J30 | K30: ='Week 2 (MASTER SHEET)'!K30 | L30: ='Week 2 (MASTER SHEET)'!L30
A31: ='Week 2 (MASTER SHEET)'!A31 -> 7 | B31: ='Week 2 (MASTER SHEET)'!B31 -> 55 | C31: ='Week 2 (MASTER SHEET)'!C31 -> REP OUT | D31: ='Week 2 (MASTER SHEET)'!D31 -> 1 MIN | E31: ='Week 2 (MASTER SHEET)'!E31 -> 10 | H31: ='Week 2 (MASTER SHEET)'!H31 | I31: ='Week 2 (MASTER SHEET)'!I31 | J31: ='Week 2 (MASTER SHEET)'!J31 | K31: ='Week 2 (MASTER SHEET)'!K31
A32: ='Week 2 (MASTER SHEET)'!A32 | B32: ='Week 2 (MASTER SHEET)'!B32 | C32: ='Week 2 (MASTER SHEET)'!C32 | D32: ='Week 2 (MASTER SHEET)'!D32 | E32: ='Week 2 (MASTER SHEET)'!E32 | H32: ='Week 2 (MASTER SHEET)'!H32 | I32: ='Week 2 (MASTER SHEET)'!I32 | J32: ='Week 2 (MASTER SHEET)'!J32 | K32: ='Week 2 (MASTER SHEET)'!K32
A33: ='Week 2 (MASTER SHEET)'!A33 | B33: ='Week 2 (MASTER SHEET)'!B33 | C33: ='Week 2 (MASTER SHEET)'!C33 | D33: ='Week 2 (MASTER SHEET)'!D33 | E33: ='Week 2 (MASTER SHEET)'!E33 | H33: ='Week 2 (MASTER SHEET)'!H33 | I33: ='Week 2 (MASTER SHEET)'!I33 | J33: ='Week 2 (MASTER SHEET)'!J33 | K33: ='Week 2 (MASTER SHEET)'!K33
A34: ='Week 2 (MASTER SHEET)'!A34 -> FINAL MAX | B34: ='Week 2 (MASTER SHEET)'!B34 -> 75 | H34: ='Week 2 (MASTER SHEET)'!H34 -> FINAL MAX | I34: ='Week 2 (MASTER SHEET)'!I34
A37: ='Week 2 (MASTER SHEET)'!A37 -> 2. DUMBBELL CHEST FLY | G37: ALTERNATE | H37: ='Week 2 (MASTER SHEET)'!H37 -> 2. MACHINE CHEST FLY
A38: ='Week 2 (MASTER SHEET)'!A38 -> DB INCLINE MAX | B38: ='Week 2 (MASTER SHEET)'!B38 -> 75 | H38: ='Week 2 (MASTER SHEET)'!H38 -> DB INCLINE MAX | I38: ='Week 2 (MASTER SHEET)'!I38 -> 75
A39: ='Week 2 (MASTER SHEET)'!A39 -> SET | B39: ='Week 2 (MASTER SHEET)'!B39 -> WEIGHT | C39: ='Week 2 (MASTER SHEET)'!C39 -> REPS | D39: ='Week 2 (MASTER SHEET)'!D39 -> REST | E39: ='Week 2 (MASTER SHEET)'!E39 -> PREVIOUS | F39: ='Week 2 (MASTER SHEET)'!F39 -> REP LOG | H39: ='Week 2 (MASTER SHEET)'!H39 -> SET | I39: ='Week 2 (MASTER SHEET)'!I39 -> WEIGHT | J39: ='Week 2 (MASTER SHEET)'!J39 -> REPS | K39: ='Week 2 (MASTER SHEET)'!K39 -> REST | L39: ='Week 2 (MASTER SHEET)'!L39 -> PREVIOUS | M39: ='Week 2 (MASTER SHEET)'!M39 -> REP LOG
A40: ='Week 2 (MASTER SHEET)'!A40 -> 1 | B40: ='Week 2 (MASTER SHEET)'!B40 -> 22.5 | C40: ='Week 2 (MASTER SHEET)'!C40 -> 15 | D40: ='Week 2 (MASTER SHEET)'!D40 -> 1 MIN | E40: ='Week 2 (MASTER SHEET)'!E40 | F40: 15 | H40: ='Week 2 (MASTER SHEET)'!H40 -> 1 | I40: ='Week 2 (MASTER SHEET)'!I40 -> 110 | J40: ='Week 2 (MASTER SHEET)'!J40 -> 15 | K40: ='Week 2 (MASTER SHEET)'!K40 -> 1 MIN | L40: ='Week 2 (MASTER SHEET)'!L40
A41: ='Week 2 (MASTER SHEET)'!A41 -> 2 | B41: ='Week 2 (MASTER SHEET)'!B41 -> 22.5 | C41: ='Week 2 (MASTER SHEET)'!C41 -> 15 | D41: ='Week 2 (MASTER SHEET)'!D41 -> 1 MIN | E41: ='Week 2 (MASTER SHEET)'!E41 | F41: 15 | H41: ='Week 2 (MASTER SHEET)'!H41 -> 2 | I41: ='Week 2 (MASTER SHEET)'!I41 -> 110 | J41: ='Week 2 (MASTER SHEET)'!J41 -> 15 | K41: ='Week 2 (MASTER SHEET)'!K41 -> 1 MIN | L41: ='Week 2 (MASTER SHEET)'!L41
A44: ='Week 2 (MASTER SHEET)'!A44 -> 3. MACHINE LOW ROW
A45: ='Week 2 (MASTER SHEET)'!A45 -> CURRENT MAX | B45: ='Week 2 (MASTER SHEET)'!B45 -> 205
A46: ='Week 2 (MASTER SHEET)'!A46 -> SET | B46: ='Week 2 (MASTER SHEET)'!B46 -> WEIGHT | C46: ='Week 2 (MASTER SHEET)'!C46 -> REPS | D46: ='Week 2 (MASTER SHEET)'!D46 -> REST | E46: ='Week 2 (MASTER SHEET)'!E46 -> PREVIOUS | F46: ='Week 2 (MASTER SHEET)'!F46 -> REP LOG
A47: ='Week 2 (MASTER SHEET)'!A47 -> 1 | B47: ='Week 2 (MASTER SHEET)'!B47 -> 70 | C47: ='Week 2 (MASTER SHEET)'!C47 -> 6 | D47: ='Week 2 (MASTER SHEET)'!D47 -> 30s | E47: ='Week 2 (MASTER SHEET)'!E47
A48: ='Week 2 (MASTER SHEET)'!A48 -> 2 | B48: ='Week 2 (MASTER SHEET)'!B48 -> 135 | C48: ='Week 2 (MASTER SHEET)'!C48 -> 3 | D48: ='Week 2 (MASTER SHEET)'!D48 -> 1-2 MIN | E48: ='Week 2 (MASTER SHEET)'!E48
A49: ='Week 2 (MASTER SHEET)'!A49 -> 3 | B49: ='Week 2 (MASTER SHEET)'!B49 -> 185 | C49: ='Week 2 (MASTER SHEET)'!C49 -> 2 | D49: ='Week 2 (MASTER SHEET)'!D49 -> 1-2 MIN | E49: ='Week 2 (MASTER SHEET)'!E49
A50: ='Week 2 (MASTER SHEET)'!A50 -> 4 | B50: ='Week 2 (MASTER SHEET)'!B50 -> 205 | C50: ='Week 2 (MASTER SHEET)'!C50 -> 3 | D50: ='Week 2 (MASTER SHEET)'!D50 -> 1-5 MIN
A51: ='Week 2 (MASTER SHEET)'!A51 -> PROCEED TO DOWN SETS
A52: ='Week 2 (MASTER SHEET)'!A52 | B52: ='Week 2 (MASTER SHEET)'!B52 | C52: ='Week 2 (MASTER SHEET)'!C52 | D52: ='Week 2 (MASTER SHEET)'!D52
A53: ='Week 2 (MASTER SHEET)'!A53 | B53: ='Week 2 (MASTER SHEET)'!B53 | C53: ='Week 2 (MASTER SHEET)'!C53 | D53: ='Week 2 (MASTER SHEET)'!D53 | E53: ='Week 2 (MASTER SHEET)'!E53
A54: ='Week 2 (MASTER SHEET)'!A54 -> DOWN SETS
A55: ='Week 2 (MASTER SHEET)'!A55 | B55: ='Week 2 (MASTER SHEET)'!B55 -> 0 | C55: ='Week 2 (MASTER SHEET)'!C55 -> REP OUT | D55: ='Week 2 (MASTER SHEET)'!D55 -> 1-3 MIN | E55: ='Week 2 (MASTER SHEET)'!E55
...

Sheet Week 2 (MASTER SHEET)
A9: Week 2
A10: ='Week 1 MASTER SHEET'!A10 -> PRESS TO RECORD BODY WEIGHT
A12: This Weeks Goals
A13: This week we are going to continue to attemp new maxes in some areas as well as go for max repititions in others. Be sure to push your hardest and keep good form.
A16: DAY 1 | H16: ALTERNATE WORKOUTS
A19: CHEST & BACK | H19: CHEST & BACK
A20: =HYPERLINK("https://youtu.be/ujVN-A0Z-ic","1. DUMBBELL INCLINE PRESS") -> 1. DUMBBELL INCLINE PRESS | H20: =HYPERLINK("https://youtu.be/75e_H9Vq_Lw","1. MACHINE PRESS") -> 1. MACHINE PRESS
A21: CURRENT MAX | B21: 20 | H21: CURRENT MAX | I21: ='WEEK 1 '!I32
A22: SET | B22: WEIGHT | C22: REPS | D22: REST | E22: PREVIOUS | F22: REP LOG | H22: SET | I22: WEIGHT | J22: REPS | K22: REST | L22: PREVIOUS | M22: REP LOG
A23: 1 | B23: =mround('WEEK 2'!B21*0.35,5) -> 25 | C23: 6 | D23: 1 MIN | E23: =IF('WEEK 1 '!P22='WEEK 2'!B23,'WEEK 1 '!T22,"") -> 6 | H23: 1 | I23: =mround('WEEK 2'!I21*0.35,5) -> 0 | J23: 6 | K23: 1 MIN | L23: =IF('WEEK 1 '!I22='WEEK 2'!I23,'WEEK 1 '!M22,"")
A24: 2 | B24: =mround('WEEK 2'!B21*0.65,5) -> 50 | C24: 1 | D24: 1 MIN | E24: =IF('WEEK 1 '!P23='WEEK 2'!B24,'WEEK 1 '!T23,"") -> 1 | H24: 2 | I24: =mround('WEEK 2'!I21*0.65,5) -> 0 | J24: 1 | K24: 1 MIN | L24: =IF('WEEK 1 '!I23='WEEK 2'!I24,'WEEK 1 '!M23,"")
A25: 3 | B25: =mround('WEEK 2'!B21*0.85,5) -> 65 | C25: 1 | D25: 1 MIN | E25: =IF('WEEK 1 '!P24='WEEK 2'!B25,'WEEK 1 '!T24,"") -> 1 | H25: 3 | I25: =mround('WEEK 2'!I21*0.85,5) -> 0 | J25: 1 | K25: 1 MIN | L25: =IF('WEEK 1 '!I24='WEEK 2'!I25,'WEEK 1 '!M24,"")
A26: 4 | B26: =mround('WEEK 2'!B21*1,5) -> 75 | C26: REP OUT | D26: 1 MIN | E26: =IF('WEEK 1 '!P25='WEEK 2'!B26,'WEEK 1 '!T25,"") -> 6 | H26: 4 | I26: =mround('WEEK 2'!I21*1,5) -> 0 | J26: REP OUT | K26: 1 MIN | L26: =IF('WEEK 1 '!I25='WEEK 2'!I26,'WEEK 1 '!M25,"")
A27: =IF(OR(ISBLANK('WEEK 2'!F26),ISBLANK('WEEK 2'!F25),ISBLANK('WEEK 2'!F24)),"PROCEED TO DOWNSETS",if('WEEK 2'!F26>=6,"NEW 4 REP MAX ATTEMPT","PROCEED TO DOWN SETS")) -> NEW 4 REP MAX ATTEMPT | G27: ALTERNATE | H27: =IF(OR(ISBLANK('WEEK 2'!M26),ISBLANK('WEEK 2'!M25),ISBLANK('WEEK 2'!M24)),"PROCEED TO DOWNSETS",if('WEEK 2'!M26>=6,"NEW 4 REP MAX ATTEMPT","PROCEED TO DOWN SETS")) -> PROCEED TO DOWNSETS
A28: =IF(OR(ISBLANK('WEEK 2'!F26),ISBLANK('WEEK 2'!F25),ISBLANK('WEEK 2'!F24)),"",IF('WEEK 2'!F26>=6,5,"")) -> 5 | B28: =IF(OR(ISBLANK('WEEK 2'!F26),ISBLANK('WEEK 2'!F25),ISBLANK('WEEK 2'!F24)),"",IF('WEEK 2'!F26>=6,'WEEK 2'!B21+5,"")) -> 80 | C28: =IF(OR(ISBLANK('WEEK 2'!F26),ISBLANK('WEEK 2'!F25),ISBLANK('WEEK 2'!F24)),"",IF('WEEK 2'!F26>=6,"REP OUT","")) -> REP OUT | D28: =IF(OR(ISBLANK('WEEK 2'!F26),ISBLANK('WEEK 2'!F25),ISBLANK('WEEK 2'!F24)),"",IF('WEEK 2'!F26>5,"1 MIN","")) -> 1 MIN | E28: =IF('WEEK 1 '!P27='WEEK 2'!B28,'WEEK 1 '!T27,"") -> 3 | H28: =IF(OR(ISBLANK('WEEK 2'!M26),ISBLANK('WEEK 2'!M25),ISBLANK('WEEK 2'!M24)),"",IF('WEEK 2'!M26>=6,5,"")) | I28: =IF(OR(ISBLANK('WEEK 2'!M26),ISBLANK('WEEK 2'!M25),ISBLANK('WEEK 2'!M24)),"",IF('WEEK 2'!M26>=6,'WEEK 2'!I21+5,"")) | J28: =IF(OR(ISBLANK('WEEK 2'!M26),ISBLANK('WEEK 2'!M25),ISBLANK('WEEK 2'!M24)),"",IF('WEEK 2'!M26>=6,"REP OUT","")) | K28: =IF(OR(ISBLANK('WEEK 2'!M26),ISBLANK('WEEK 2'!M25),ISBLANK('WEEK 2'!M24)),"",IF('WEEK 2'!M26>5,"1 MIN","")) | L28: =IF('WEEK 1 '!I27='WEEK 2'!I28,'WEEK 1 '!M27,"")
A29: =IF(OR(ISBLANK('WEEK 2'!F26),ISBLANK('WEEK 2'!F25),ISBLANK('WEEK 2'!F24)),"FILL OUT REP LOG FIRST","DOWN SETS") -> DOWN SETS | H29: =IF(OR(ISBLANK('WEEK 2'!M26),ISBLANK('WEEK 2'!M25),ISBLANK('WEEK 2'!M24)),"FILL OUT REP LOG FIRST","DOWN SETS") -> FILL OUT REP LOG FIRST
A30: =IF('WEEK 2'!F28>=4,"",IF(OR(ISBLANK('WEEK 2'!F26),ISBLANK('WEEK 2'!F25),ISBLANK('WEEK 2'!F24)),"",IF('WEEK 2'!F26>5,6,5))) -> 6 | B30: =IF('WEEK 2'!F28>=4,"",IF(OR(ISBLANK('WEEK 2'!F26),ISBLANK('WEEK 2'!F25),ISBLANK('WEEK 2'!F24)),"",IF('WEEK 2'!F26<6,mround('WEEK 2'!B21*0.8,5),IF('WEEK 2'!F26<10,mround('WEEK 2'!B21*0.93,5),mround('WEEK 2'!B21*0.7,5))))) -> 70 | C30: =IF('WEEK 2'!F28>=4,"",IF(OR(ISBLANK('WEEK 2'!F26),ISBLANK('WEEK 2'!F25),ISBLANK('WEEK 2'!F24)),"","REP OUT")) -> REP OUT | D30: =IF('WEEK 2'!F28>=4,"",IF(OR(ISBLANK('WEEK 2'!F26),ISBLANK('WEEK 2'!F25),ISBLANK('WEEK 2'!F24)),"","1 MIN")) -> 1 MIN | E30: =IF('WEEK 1 '!P29='WEEK 2'!B30,'WEEK 1 '!T29,"") -> 6 | H30: =IF('WEEK 2'!M28>=4,"",IF(OR(ISBLANK('WEEK 2'!M26),ISBLANK('WEEK 2'!M25),ISBLANK('WEEK 2'!M24)),"",IF('WEEK 2'!M26>5,6,5))) | I30: =IF('WEEK 2'!M28>=4,"",IF(OR(ISBLANK('WEEK 2'!M26),ISBLANK('WEEK 2'!M25),ISBLANK('WEEK 2'!M24)),"",IF('WEEK 2'!M26<6,mround('WEEK 2'!I21*0.8,5),IF('WEEK 2'!M26<10,mround('WEEK 2'!I21*0.93,5),mround('WEEK 2'!I21*0.7,5))))) | J30: =IF('WEEK 2'!M28>=4,"",IF(OR(ISBLANK('WEEK 2'!M26),ISBLANK('WEEK 2'!M25),ISBLANK('WEEK 2'!M24)),"","REP OUT")) | K30: =IF('WEEK 2'!M28>=4,"",IF(OR(ISBLANK('WEEK 2'!M26),ISBLANK('WEEK 2'!M25),ISBLANK('WEEK 2'!M24)),"","1 MIN")) | L30: =IF('WEEK 1 '!I29='WEEK 2'!I30,'WEEK 1 '!M29,"")
A31: =IF('WEEK 2'!F28>=4,"",IF(OR(ISBLANK('WEEK 2'!F26),ISBLANK('WEEK 2'!F25),ISBLANK('WEEK 2'!F24)),"",IF('WEEK 2'!F26>5,7,6))) -> 7 | B31: =IF('WEEK 2'!F28>=4,"",IF(OR(ISBLANK('WEEK 2'!F26),ISBLANK('WEEK 2'!F25),ISBLANK('WEEK 2'!F24)),"",IF('WEEK 2'!F26<6,mround('WEEK 2'!B21*0.65,5),IF('WEEK 2'!F26<10,mround('WEEK 2'!B21*0.7,5),mround('WEEK 2'!B21*0.65,5))))) -> 55 | C31: =IF('WEEK 2'!F28>=4,"",IF(OR(ISBLANK('WEEK 2'!F26),ISBLANK('WEEK 2'!F25),ISBLANK('WEEK 2'!F24)),"","REP OUT")) -> REP OUT | D31: =IF('WEEK 2'!F28>=4,"",IF(OR(ISBLANK('WEEK 2'!F26),ISBLANK('WEEK 2'!F25),ISBLANK('WEEK 2'!F24)),"","1 MIN")) -> 1 MIN | E31: =IF('WEEK 1 '!P30='WEEK 2'!B31,'WEEK 1 '!T30,"") -> 10 | H31: =IF('WEEK 2'!M28>=4,"",IF(OR(ISBLANK('WEEK 2'!M26),ISBLANK('WEEK 2'!M25),ISBLANK('WEEK 2'!M24)),"",IF('WEEK 2'!M26>5,7,6))) | I31: =IF('WEEK 2'!M28>=4,"",IF(OR(ISBLANK('WEEK 2'!M26),ISBLANK('WEEK 2'!M25),ISBLANK('WEEK 2'!M24)),"",IF('WEEK 2'!M26<6,mround('WEEK 2'!I21*0.65,5),IF('WEEK 2'!M26<10,mround('WEEK 2'!I21*0.7,5),mround('WEEK 2'!I21*0.65,5))))) | J31: =IF('WEEK 2'!M28>=4,"",IF(OR(ISBLANK('WEEK 2'!M26),ISBLANK('WEEK 2'!M25),ISBLANK('WEEK 2'!M24)),"","REP OUT")) | K31: =IF('WEEK 2'!M28>=4,"",IF(OR(ISBLANK('WEEK 2'!M26),ISBLANK('WEEK 2'!M25),ISBLANK('WEEK 2'!M24)),"","1 MIN")) | L31: =IF('WEEK 1 '!I30='WEEK 2'!I31,'WEEK 1 '!M30,"")
